Workbook

Sheet Tabelau Fraction
K1: TABLEAU CARACTERISATIONS OM de la CAD | AF1: SYSTÈME DE MANAGEMENT INTEGRE
L5: Fraction > 200mm | R5: Fraction > 70mm | AE5: Fraction < 70mm | AM5: Fraction <20mm
A6: Collectivités | B6: Circuit | C6: Date de Réception | D6: Heure | E6: N° de Pesée | F6: Plaque Immatriculation | G6: Poids Réceptionné | H6: Opérateur | I6: Date de l'échantillonage | J6: Nombre de Trieurs | K6: Details refus | L6: Gros Inerte | M6: Films Plastiques | N6: Plastiques Rigides | O6: Bois | P6: Grosses fractions métaliques | Q6: EMR | R6: Inertes | S6: Verre | T6: Petits Films | U6: Autres palstiques rigides | V6: Bois | W6: Fibreux | X6: Textiles | Y6: Fraction Métaliques | Z6: Déchets alimentaires | AA6: Produits alimentaires Non Consommés | AB6: Déchets de Jardins | AC6: Textiles Sanitaire | AD6: Refus | AE6: Fractions métaliques | AF6: Déchets alimentaires | AG6: Déchets de Jardins | AH6: Textiles Sanitaires | AI6: Verre | AJ6: Inertes | AK6: Fibreux | AL6: Plastiques | AM6: Fines Inferieurs à 0,20 | AN6: TOTAL
A7: Les Arcs | B7: Ext | C7: 43608 | D7: 09h06 | E7: 293009 | F7: CP730KZ | G7: 4.52 | H7: Claudine/Manon | I7: 43612 | J7: 2 | K7: Asticots, aspiratuer, nourritures, ENV | L7: ='Les Arcs sur Argens'!F19 -> 0 | M7: ='Les Arcs sur Argens'!F20 -> 0.015745148 | N7: ='Les Arcs sur Argens'!F21 -> 0.011900403 | O7: ='Les Arcs sur Argens'!F22 -> 0.0035701208 | P7: ='Les Arcs sur Argens'!F23 -> 0.0035701208 | Q7: ='Les Arcs sur Argens'!F24 -> 0.044123032 | R7: ='Les Arcs sur Argens'!F26 -> 0.0050347858 | S7: ='Les Arcs sur Argens'!F27 -> 0.046503112 | T7: ='Les Arcs sur Argens'!F28 -> 0.060692054 | U7: ='Les Arcs sur Argens'!F29 -> 0.047143903 | V7: ='Les Arcs sur Argens'!F30 -> 0.0027462468 | W7: ='Les Arcs sur Argens'!F31 -> 0.1182717 | X7: ='Les Arcs sur Argens'!F32 -> 0.0997803 | Y7: ='Les Arcs sur Argens'!F33 -> 0.019498352 | Z7: ='Les Arcs sur Argens'!F34 -> 0.097491761 | AA7: ='Les Arcs sur Argens'!F35 -> 0.0054924936 | AB7: ='Les Arcs sur Argens'!F36 -> 0.12303186 | AC7: ='Les Arcs sur Argens'!F37 -> 0.047418528 | AD7: ='Les Arcs sur Argens'!F38 -> 0.16395093 | AE7: ='Les Arcs sur Argens'!F40 -> 0.0088795313 | AF7: ='Les Arcs sur Argens'!F41 -> 0.0053094105 | AG7: ='Les Arcs sur Argens'!F42 -> 0.0011900403 | AH7: ='Les Arcs sur Argens'!F43 -> 0.0043939949 | AI7: ='Les Arcs sur Argens'!F44 -> 0.0030208715 | AJ7: ='Les Arcs sur Argens'!F45 -> 0.001464665 | AK7: ='Les Arcs sur Argens'!F46 -> 0.0047601611 | AL7: ='Les Arcs sur Argens'!F47 -> 0.0023800806 | AM7: ='Les Arcs sur Argens'!F49 -> 0.052636397
L8: =L7+M7+N7+O7+P7+Q7 -> 0.078908825 | R8: =R7+S7+T7+U7+V7+W7+X7+Y7+Z7+AA7+AB7++AC7+AD7 -> 0.83705602 | AE8: =AE7+AF7+AG7+AH7+AI7+AJ7+AK7+AL7 -> 0.031398755 | AM8: =AM7 -> 0.052636397 | AN8: =AM8+AE8+R8+L8 -> 1
A9: Draguignan | B9: Bleu A1 | C9: 43609 | D9: 09h13 | E9: 293151 | F9: BV129RS | G9: 6.62 | H9: Claudine/Manon | I9: 43612 | J9: 2 | K9: Asticots, petits morceau de verre, tuyau, cartouches | L9: ='Draguignan Bleu A1'!F19 -> 0 | M9: ='Draguignan Bleu A1'!F20 -> 0.0043067481 | N9: ='Draguignan Bleu A1'!F21 -> 0.0020457054 | O9: ='Draguignan Bleu A1'!F22 -> 0.0046835886 | P9: ='Draguignan Bleu A1'!F23 -> 0.0024763802 | Q9: ='Draguignan Bleu A1'!F24 -> 0.085542785 | R9: ='Draguignan Bleu A1'!F26 -> 0.0040375764 | S9: ='Draguignan Bleu A1'!F27 -> 0.033215795 | T9: ='Draguignan Bleu A1'!F28 -> 0.046459046 | U9: ='Draguignan Bleu A1'!F29 -> 0.056526069 | V9: ='Draguignan Bleu A1'!F30 -> 0.0017226993 | W9: ='Draguignan Bleu A1'!F31 -> 0.20166348 | X9: ='Draguignan Bleu A1'!F32 -> 0.020510888 | Y9: ='Draguignan Bleu A1'!F33 -> 0.019165029 | Z9: ='Draguignan Bleu A1'!F34 -> 0.12909478 | AA9: ='Draguignan Bleu A1'!F35 -> 0.0026378832 | AB9: ='Draguignan Bleu A1'!F36 -> 0.059110118 | AC9: ='Draguignan Bleu A1'!F37 -> 0.071895777 | AD9: ='Draguignan Bleu A1'!F38 -> 0.15908051 | AE9: ='Draguignan Bleu A1'!F40 -> 0.00069984657 | AF9: ='Draguignan Bleu A1'!F41 -> 0.0039299077 | AG9: ='Draguignan Bleu A1'!F42 -> 0.0032300611 | AH9: ='Draguignan Bleu A1'!F43 -> 0.0020995397 | AI9: ='Draguignan Bleu A1'!F44 -> 0.0061371161 | AJ9: ='Draguignan Bleu A1'!F45 -> 0 | AK9: ='Draguignan Bleu A1'!F46 -> 0.0033915642 | AL9: ='Draguignan Bleu A1'!F47 -> 0.0025840489 | AM9: ='Draguignan Bleu A1'!F49 -> 0.073753062
L10: =L9+M9+N9+O9+P9+Q9 -> 0.099055207 | R10: =R9+S9+T9+U9+V9+W9+X9+Y9+Z9+AA9+AB9+AC9+AD9 -> 0.80511965 | AE10: =AE9+AF9+AG9+AH9+AI9+AJ9+AK9+AL9 -> 0.022072084 | AM10: =AM9 -> 0.073753062 | AN10: =AM10+AE10+R10+L10 -> 1
A11: Tran en Provence | B11: Ext | C11: 43609 | D11: 09h41 | E11: 293157 | F11: DX172JM | G11: 5 | H11: Claudine/Manon | I11: 43613 | J11: 2 | K11: Litières, chaussures, DEE, siège ne mousse, lit enfant.. | L11: ='Trans en Provence Ext'!F19 -> 0 | M11: ='Trans en Provence Ext'!F20 -> 0.0016155089 | N11: ='Trans en Provence Ext'!F21 -> 0.004073892 | O11: ='Trans en Provence Ext'!F22 -> 0.0025286226 | P11: ='Trans en Provence Ext'!F23 -> 0.012853832 | Q11: ='Trans en Provence Ext'!F24 -> 0.016646765 | R11: ='Trans en Provence Ext'!F26 -> 0.0027393412 | S11: ='Trans en Provence Ext'!F27 -> 0.031397064 | T11: ='Trans en Provence Ext'!F28 -> 0.046919997 | U11: ='Trans en Provence Ext'!F29 -> 0.05963335 | V11: ='Trans en Provence Ext'!F30 -> 0.010535928 | W11: ='Trans en Provence Ext'!F31 -> 0.15213879 | X11: ='Trans en Provence Ext'!F32 -> 0.0067429936 | Y11: ='Trans en Provence Ext'!F33 -> 0.021282574 | Z11: ='Trans en Provence Ext'!F34 -> 0.060546463 | AA11: ='Trans en Provence Ext'!F35 -> 0.0047762871 | AB11: ='Trans en Provence Ext'!F36 -> 0.16000562 | AC11: ='Trans en Provence Ext'!F37 -> 0.038069818 | AD11: ='Trans en Provence Ext'!F38 -> 0.24260729 | AE11: ='Trans en Provence Ext'!F40 -> 0.0023881436 | AF11: ='Trans en Provence Ext'!F41 -> 0.0041441315 | AG11: ='Trans en Provence Ext'!F42 -> 0.00063215565 | AH11: ='Trans en Provence Ext'!F43 -> 0.0051977242 | AI11: ='Trans en Provence Ext'!F44 -> 0.0058298799 | AJ11: ='Trans en Provence Ext'!F45 -> 0.0031607783 | AK11: ='Trans en Provence Ext'!F46 -> 0.0037929339 | AL11: ='Trans en Provence Ext'!F47 -> 0.0034417363 | AM11: ='Trans en Provence Ext'!F49 -> 0.096298377
L12: =L11+M11+N11+O11+P11+Q11 -> 0.03771862 | R12: =R11+S11+T11+U11+V11+W11+X11+Y11+Z11+AA11+AB11+AC11+AD11 -> 0.83739552 | AE12: =AE11+AF11+AG11+AH11+AI11+AJ11+AK11+AL11 -> 0.028587483 | AM12: =AM11 -> 0.096298377 | AN12: =AM12+AE12+R12+L12 -> 1
A13: Draguignan | B13: Vert/Rouge | C13: 43609 | D13: 10h36 | E13: 293175 | F13: CK397RT | G13: 9.36 | H13: Claudine/Manon | I13: 43613 | J13: 2 | K13: Litières, cables electriques, DEE, peluches | L13: ='Draguignan Vert-Rouge'!F19 -> 0 | M13: ='Draguignan Vert-Rouge'!F20 -> 0 | N13: ='Draguignan Vert-Rouge'!F21 -> 0 | O13: ='Draguignan Vert-Rouge'!F22 -> 0.0075773977 | P13: ='Draguignan Vert-Rouge'!F23 -> 0.0062784152 | Q13: ='Draguignan Vert-Rouge'!F24 -> 0.02294869 | R13: ='Draguignan Vert-Rouge'!F26 -> 0.0023093022 | S13: ='Draguignan Vert-Rouge'!F27 -> 0.04272209 | T13: ='Draguignan Vert-Rouge'!F28 -> 0.038969474 | U13: ='Draguignan Vert-Rouge'!F29 -> 0.058670708 | V13: ='Draguignan Vert-Rouge'!F30 -> 0.0050515985 | W13: ='Draguignan Vert-Rouge'!F31 -> 0.14288807 | X13: ='Draguignan Vert-Rouge'!F32 -> 0.011907339 | Y13: ='Draguignan Vert-Rouge'!F33 -> 0.019556903 | Z13: ='Draguignan Vert-Rouge'!F34 -> 0.185538 | AA13: ='Draguignan Vert-Rouge'!F35 -> 0.010031031 | AB13: ='Draguignan Vert-Rouge'!F36 -> 0.012773328 | AC13: ='Draguignan Vert-Rouge'!F37 -> 0.10687739 | AD13: ='Draguignan Vert-Rouge'!F38 -> 0.2589305 | AE13: ='Draguignan Vert-Rouge'!F40 -> 0.00064949123 | AF13: ='Draguignan Vert-Rouge'!F41 -> 0.0041134445 | AG13: ='Draguignan Vert-Rouge'!F42 -> 0.00036082846 | AH13: ='Draguignan Vert-Rouge'!F43 -> 0.0022371365 | AI13: ='Draguignan Vert-Rouge'!F44 -> 0.00064949123 | AJ13: ='Draguignan Vert-Rouge'!F45 -> 0 | AK13: ='Draguignan Vert-Rouge'!F46 -> 0.0010103197 | AL13: ='Draguignan Vert-Rouge'!F47 -> 0.0010824854 | AM13: ='Draguignan Vert-Rouge'!F49 -> 0.056866566
L14: =L13+M13+N13+O13+P13+Q13 -> 0.036804503 | R14: =R13+S13+T13+U13+V13+W13+X13+Y13+Z13+AA13+AB13+AC13+AD13 -> 0.89622573 | AE14: =AE13+AF13+AG13+AH13+AI13+AJ13+AK13+AL13 -> 0.010103197 | AM14: =AM13 -> 0.056866566 | AN14: =AM14+AE14+R14+L14 -> 1
A15: Salernes | B15: Ext | C15: 43610 | D15: 09h05 | E15: 293262 | F15: BV745RS | G15: 5.5 | H15: Claudine/Manon | I15: 43614 | J15: 2 | K15: DEE, blocs pour glacière, seringues, textiles | L15: ='Salernes Ext'!F19 -> 0.00059798394 | M15: ='Salernes Ext'!F20 -> 0.0079446438 | N15: ='Salernes Ext'!F21 -> 0.0025627883 | O15: ='Salernes Ext'!F22 -> 0.0038441825 | P15: ='Salernes Ext'!F23 -> 0 | Q15: ='Salernes Ext'!F24 -> 0.026225867 | R15: ='Salernes Ext'!F26 -> 0 | S15: ='Salernes Ext'!F27 -> 0.059456689 | T15: ='Salernes Ext'!F28 -> 0.031864001 | U15: ='Salernes Ext'!F29 -> 0.058858705 | V15: ='Salernes Ext'!F30 -> 0.0029044934 | W15: ='Salernes Ext'!F31 -> 0.097727661 | X15: ='Salernes Ext'!F32 -> 0.024431915 | Y15: ='Salernes Ext'!F33 -> 0.024602768 | Z15: ='Salernes Ext'!F34 -> 0.090295575 | AA15: ='Salernes Ext'!F35 -> 0.0021356569 | AB15: ='Salernes Ext'!F36 -> 0.18264138 | AC15: ='Salernes Ext'!F37 -> 0.068597301 | AD15: ='Salernes Ext'!F38 -> 0.25790193 | AE15: ='Salernes Ext'!F40 -> 0.00051255766 | AF15: ='Salernes Ext'!F41 -> 0.0029899197 | AG15: ='Salernes Ext'!F42 -> 0.022637963 | AH15: ='Salernes Ext'!F43 -> 0.0021356569 | AI15: ='Salernes Ext'!F44 -> 0.0011959679 | AJ15: ='Salernes Ext'!F45 -> 0.0013668204 | AK15: ='Salernes Ext'!F46 -> 0.0011959679 | AL15: ='Salernes Ext'!F47 -> 0.0016230993 | AM15: ='Salernes Ext'!F49 -> 0.023748505
L16: =L15+M15+N15+O15+P15+Q15 -> 0.041175466 | R16: =R15+S15+T15+U15+V15+W15+X15+Y15+Z15+AA15+AB15+AC15+AD15 -> 0.90141808 | AE16: =AE15+AF15+AG15+AH15+AI15+AJ15+AK15+AL15 -> 0.033657953 | AM16: =+AM15 -> 0.023748505 | AN16: =AM16+AE16+R16+L16 -> 1
A17: Lorgues | B17: Ext | C17: 43612 | D17: 09h39 | E17: 293311 | F17: CH714TJ | G17: 6.02 | H17: Claudine/Manon | I17: 43614 | J17: 2 | K17: Sacs pleins de gravillons, excrement d'annimaux… | L17: =Lorgues!F19 -> 0 | M17: =Lorgues!F20 -> 0.0011152701 | N17: =Lorgues!F21 -> 0 | O17: =Lorgues!F22 -> 0.0042519674 | P17: =Lorgues!F23 -> 0.041474108 | Q17: =Lorgues!F24 -> 0.040219429 | R17: =Lorgues!F26 -> 0.0059248726 | S17: =Lorgues!F27 -> 0.03736155 | T17: =Lorgues!F28 -> 0.029833476 | U17: =Lorgues!F29 -> 0.062385423 | V17: =Lorgues!F30 -> 0.0063430989 | W17: =Lorgues!F31 -> 0.088385159 | X17: =Lorgues!F32 -> 0.057645525 | Y17: =Lorgues!F33 -> 0.022375107 | Z17: =Lorgues!F34 -> 0.079379352 | AA17: =Lorgues!F35 -> 0 | AB17: =Lorgues!F36 -> 0.082251173 | AC17: =Lorgues!F37 -> 0.089326168 | AD17: =Lorgues!F38 -> 0.23441584 | AE17: =Lorgues!F40 -> 0.0014637921 | AF17: =Lorgues!F41 -> 0.0039034455 | AG17: =Lorgues!F42 -> 0.0045307849 | AH17: =Lorgues!F43 -> 0.0026487666 | AI17: =Lorgues!F44 -> 0.002369949 | AJ17: =Lorgues!F45 -> 0 | AK17: =Lorgues!F46 -> 0.0031366973 | AL17: =Lorgues!F47 -> 0.0019517227 | AM17: =Lorgues!F49 -> 0.09730732
L18: =L17+M17+N17+O17+P17+Q17 -> 0.087060775 | R18: =R17+S17+T17+U17+V17+W17+X17+Y17+Z17+AA17+AB17+AC17+AD17 -> 0.79562675 | AE18: =AE17+AF17+AG17+AH17+AI17+AJ17+AK17+AL17 -> 0.020005158 | AM18: =AM17 -> 0.09730732 | AN18: =AM18+AE18+L18+R18 -> 1
A19: Flayosc | B19: Ext | C19: 43613 | D19: 11h01 | E19: 293459 | F19: BZ349ZV | G19: 2.76 | H19: Claudine/Manon | I19: 43615 | J19: 2 | K19: Sacs avec litières, chaussures… | L19: =Flayosc!F19 -> 0 | M19: =Flayosc!F20 -> 0 | N19: =Flayosc!F21 -> 0.0055999341 | O19: =Flayosc!F22 -> 0.017046858 | P19: =Flayosc!F23 -> 0.0041175986 | Q19: =Flayosc!F24 -> 0.021823273 | R19: =Flayosc!F26 -> 0.0034587828 | S19: =Flayosc!F27 -> 0.095528288 | T19: =Flayosc!F28 -> 0.019270362 | U19: =Flayosc!F29 -> 0.061599275 | V19: =Flayosc!F30 -> 0.0020587993 | W19: =Flayosc!F31 -> 0.10137528 | X19: =Flayosc!F32 -> 0.018117434 | Y19: =Flayosc!F33 -> 0.01877625 | Z19: =Flayosc!F34 -> 0.17845672 | AA19: =Flayosc!F35 -> 0.02964671 | AB19: =Flayosc!F36 -> 0.067199209 | AC19: =Flayosc!F37 -> 0.056822861 | AD19: =Flayosc!F38 -> 0.1503747 | AE19: =Flayosc!F40 -> 0.00049411183 | AF19: =Flayosc!F41 -> 0.0055175821 | AG19: =Flayosc!F42 -> 0.00049411183 | AH19: =Flayosc!F43 -> 0.0026352631 | AI19: =Flayosc!F44 -> 0.0013999835 | AJ19: =Flayosc!F45 -> 0.0010705756 | AK19: =Flayosc!F46 -> 0.0014823355 | AL19: =Flayosc!F47 -> 0.0016470394 | AM19: =Flayosc!F49 -> 0.13398666
L20: =L19+M19+N19+O19+P19+Q19 -> 0.048587664 | R20: =R19+S19+T19+U19+V19+W19+X19+Y19+Z19+AA19+AB19+AC19+AD19 -> 0.80268467 | AE20: =AE19+AF19+AG19+AH19+AI19+AJ19+AK19+AL19 -> 0.014741003 | AM20: =AM19 -> 0.13398666 | AN20: =AM20+AE20+R20+L20 -> 1
A21: Draguignan | B21: Rouge A1 | C21: 43614 | D21: 11h22 | E21: 293613 | F21: AR760CV | G21: 2.52 | H21: Claudine/Manon | I21: 43615 | J21: 2 | K21: DEE, tuyaux, sacs gabats… | L21: ='Draguignan Rouge A1'!F19 -> 0 | M21: ='Draguignan Rouge A1'!F20 -> 0.011689205 | N21: ='Draguignan Rouge A1'!F21 -> 0 | O21: ='Draguignan Rouge A1'!F22 -> 0.018412407 | P21: ='Draguignan Rouge A1'!F23 -> 0 | Q21: ='Draguignan Rouge A1'!F24 -> 0.036137214 | R21: ='Draguignan Rouge A1'!F26 -> 0.0070288028 | S21: ='Draguignan Rouge A1'!F27 -> 0.021468409 | T21: ='Draguignan Rouge A1'!F28 -> 0.039346016 | U21: ='Draguignan Rouge A1'!F29 -> 0.04912522 | V21: ='Draguignan Rouge A1'!F30 -> 0.0060356024 | W21: ='Draguignan Rouge A1'!F31 -> 0.077393231 | X21: ='Draguignan Rouge A1'!F32 -> 0.081289633 | Y21: ='Draguignan Rouge A1'!F33 -> 0.041943617 | Z21: ='Draguignan Rouge A1'!F34 -> 0.19902208 | AA21: ='Draguignan Rouge A1'!F35 -> 0.012224005 | AB21: ='Draguignan Rouge A1'!F36 -> 0.055390022 | AC21: ='Draguignan Rouge A1'!F37 -> 0.057834823 | AD21: ='Draguignan Rouge A1'!F38 -> 0.19795248 | AE21: ='Draguignan Rouge A1'!F40 -> 0.0010696004 | AF21: ='Draguignan Rouge A1'!F41 -> 0.0029032012 | AG21: ='Draguignan Rouge A1'!F42 -> 0.00061120024 | AH21: ='Draguignan Rouge A1'!F43 -> 0.0010696004 | AI21: ='Draguignan Rouge A1'!F44 -> 0.00030560012 | AJ21: ='Draguignan Rouge A1'!F45 -> 0 | AK21: ='Draguignan Rouge A1'!F46 -> 0.00053480021 | AL21: ='Draguignan Rouge A1'!F47 -> 0.00038200015 | AM21: ='Draguignan Rouge A1'!F49 -> 0.080831232
L22: =L21+M21+N21+O21+P21+Q21 -> 0.066238826 | R22: =R21+S21+T21+U21+V21+W21+X21+Y21+Z21+AA21+AB21+AC21+AD21 -> 0.84605394 | AE22: =AE21+AF21+AG21+AH21+AI21+AJ21+AK21+AL21 -> 0.0068760028 | AM22: =AM21 -> 0.080831232 | AN22: =AM22+AE22+R22+L22 -> 1
A23: Vidauban | B23: Ext | C23: 43615 | D23: 10h35 | E23: 293688 | F23: BV745RS | G23: 7.4 | H23: Claudine/Manon | I23: 43616 | J23: 2 | K23: 3 big bag, sacs de litières, sacs à mains, chaussures.. | L23: =Vidauban!F19 -> 0 | M23: =Vidauban!F20 -> 0 | N23: =Vidauban!F21 -> 0 | O23: =Vidauban!F22 -> 0 | P23: =Vidauban!F23 -> 0 | Q23: =Vidauban!F24 -> 0.066893636 | R23: =Vidauban!F26 -> 0 | S23: =Vidauban!F27 -> 0.06636986 | T23: =Vidauban!F28 -> 0.037861499 | U23: =Vidauban!F29 -> 0.05417337 | V23: =Vidauban!F30 -> 0.0047139811 | W23: =Vidauban!F31 -> 0.14733061 | X23: =Vidauban!F32 -> 0.012121666 | Y23: =Vidauban!F33 -> 0.024916757 | Z23: =Vidauban!F34 -> 0.21422425 | AA23: =Vidauban!F35 -> 0.0087545363 | AB23: =Vidauban!F36 -> 0.067641887 | AC23: =Vidauban!F37 -> 0.031202065 | AD23: =Vidauban!F38 -> 0.17946799 | AE23: =Vidauban!F40 -> 0.00089790116 | AF23: =Vidauban!F41 -> 0.006210483 | AG23: =Vidauban!F42 -> 0.010176213 | AH23: =Vidauban!F43 -> 0.0040405552 | AI23: =Vidauban!F44 -> 0.0010475513 | AJ23: =Vidauban!F45 -> 0 | AK23: =Vidauban!F46 -> 0.0021699278 | AL23: =Vidauban!F47 -> 0.0020202776 | AM23: =Vidauban!F49 -> 0.057764974
L24: =L23+M23+N23+O23+P23+Q23 -> 0.066893636 | R24: =R23+S23+T23+U23+V23+W23+X23+Y23+Z23+AA23+AB23+AC23+AD23 -> 0.84877848 | AE24: =AE23+AF23+AG23+AH23+AI23+AJ23+AK23+AL23 -> 0.026562909 | AM24: =AM23 -> 0.057764974 | AN24: =AM24+AE24+R24+L24 -> 1
A25: TOTAL en % | L25: =(L7+L9+L11+L13+L15+L17+L19+L21+L23+#REF!)/10 -> #REF! | M25: =(M7+M9+M11+M13+M15+M17+M19+M21+M23+#REF!)/10 -> #REF! | N25: =(N7+N9+N11+N13+N15+N17+N19+N21+N23+#REF!)/10 -> #REF! | O25: =(O7+O9+O11+O13+O15+O17+O19+O21+O23+#REF!)/10 -> #REF! | P25: =(P7+P9+P11+P13+P15+P17+P19+P21+P23+#REF!)/10 -> #REF! | Q25: =(Q7+Q9+Q11+Q13+Q15+Q17+Q19+Q21+Q23+#REF!)/10 -> #REF! | R25: =(R7+R9+R11+R13+R15+R17+R19+R21+R23+#REF!)/10 -> #REF! | S25: =(S7+S9+S11+S13+S15+S17+S19+S21+S23+#REF!)/10 -> #REF! | ... AM25: =(AM7+AM9+AM11+AM13+AM15+AM17+AM19+AM21+AM23+#REF!)/10 -> #REF! | AN25: =SUM(L25:AM25) -> #REF!

Sheet Tableau Synthèse
G1: TABLEAU DE SYNTHESE DES CARACTERISATION OM de la CAD | O1: SYSTÈME DE MANAGEMENT INTEGRE
A9: Collectivités | B9: Circuit | C9: EMR | D9: Inertes | E9: Verre | F9: Films | G9: Plastiques rigides | H9: Bois | I9: Fibreux | J9: Textile | K9: Fraction Métalique | L9: Déchets alimentaires | M9: Produits alimentaires Non Consommés | N9: Déchets de Jardins | O9: Textiles Sanitaire | P9: Refus | Q9: Fines Inferieurs à 0,20 | R9: TOTAL
A10: Les Arcs sur Argens | B10: Ext | C10: ='Tabelau Fraction'!Q7 -> 0.044123032 | D10: ='Tabelau Fraction'!AJ7+'Tabelau Fraction'!R7+'Tabelau Fraction'!L7 -> 0.0064994508 | E10: ='Tabelau Fraction'!S7+'Tabelau Fraction'!AI7 -> 0.049523984 | F10: ='Tabelau Fraction'!M7+'Tabelau Fraction'!T7 -> 0.076437202 | G10: ='Tabelau Fraction'!N7+'Tabelau Fraction'!U7+'Tabelau Fraction'!AL7 -> 0.061424387 | H10: ='Tabelau Fraction'!O7+'Tabelau Fraction'!V7 -> 0.0063163676 | I10: ='Tabelau Fraction'!W7+'Tabelau Fraction'!AK7 -> 0.12303186 | J10: ='Tabelau Fraction'!X7 -> 0.0997803 | K10: ='Tabelau Fraction'!P7+'Tabelau Fraction'!Y7+'Tabelau Fraction'!AE7 -> 0.031948004 | L10: ='Tabelau Fraction'!Z7+'Tabelau Fraction'!AF7 -> 0.10280117 | M10: ='Tabelau Fraction'!AA7 -> 0.0054924936 | N10: ='Tabelau Fraction'!AB7+'Tabelau Fraction'!AG7 -> 0.1242219 | O10: ='Tabelau Fraction'!AC7+'Tabelau Fraction'!AH7 -> 0.051812523 | P10: ='Tabelau Fraction'!AD7 -> 0.16395093 | Q10: ='Tabelau Fraction'!AM7 -> 0.052636397 | R10: =Q10+P10+O10+N10+M10+L10+K10+J10+I10+H10+G10+F10+E10+D10+C10 -> 1
A11: Draguignan | B11: Bleu A1 | C11: ='Tabelau Fraction'!Q9 -> 0.085542785 | D11: ='Tabelau Fraction'!AJ9+'Tabelau Fraction'!R9+'Tabelau Fraction'!L9 -> 0.0040375764 | E11: ='Tabelau Fraction'!S9+'Tabelau Fraction'!AI9 -> 0.039352911 | F11: ='Tabelau Fraction'!M9+'Tabelau Fraction'!T9 -> 0.050765794 | G11: ='Tabelau Fraction'!N9+'Tabelau Fraction'!U9+'Tabelau Fraction'!AL9 -> 0.061155824 | H11: ='Tabelau Fraction'!O9+'Tabelau Fraction'!V9 -> 0.0064062879 | I11: ='Tabelau Fraction'!W9+'Tabelau Fraction'!AK9 -> 0.20505505 | J11: ='Tabelau Fraction'!X9 -> 0.020510888 | K11: ='Tabelau Fraction'!P9+'Tabelau Fraction'!Y9+'Tabelau Fraction'!AE9 -> 0.022341256 | L11: ='Tabelau Fraction'!Z9+'Tabelau Fraction'!AF9 -> 0.13302468 | M11: ='Tabelau Fraction'!AA9 -> 0.0026378832 | N11: ='Tabelau Fraction'!AB9+'Tabelau Fraction'!AG9 -> 0.062340179 | O11: ='Tabelau Fraction'!AC9+'Tabelau Fraction'!AH9 -> 0.073995316 | P11: ='Tabelau Fraction'!AD9 -> 0.15908051 | Q11: ='Tabelau Fraction'!AM9 -> 0.073753062 | R11: =Q11+P11+O11+N11+M11+L11+K11+J11+I11+H11+G11+F11+E11+D11+C11 -> 1
A12: Trans en Provence | B12: Ext | C12: ='Tabelau Fraction'!Q11 -> 0.016646765 | D12: ='Tabelau Fraction'!AJ11+'Tabelau Fraction'!R11+'Tabelau Fraction'!L11 -> 0.0059001194 | E12: ='Tabelau Fraction'!S11+'Tabelau Fraction'!AI11 -> 0.037226944 | F12: ='Tabelau Fraction'!M11+'Tabelau Fraction'!T11 -> 0.048535506 | G12: ='Tabelau Fraction'!N11+'Tabelau Fraction'!U11+'Tabelau Fraction'!AL11 -> 0.067148978 | H12: ='Tabelau Fraction'!O11+'Tabelau Fraction'!V11 -> 0.01306455 | I12: ='Tabelau Fraction'!W11+'Tabelau Fraction'!AK11 -> 0.15593173 | J12: ='Tabelau Fraction'!X11 -> 0.0067429936 | K12: ='Tabelau Fraction'!P11+'Tabelau Fraction'!Y11+'Tabelau Fraction'!AE11 -> 0.036524549 | L12: ='Tabelau Fraction'!Z11+'Tabelau Fraction'!AF11 -> 0.064690595 | M12: ='Tabelau Fraction'!AA11 -> 0.0047762871 | N12: ='Tabelau Fraction'!AB11+'Tabelau Fraction'!AG11 -> 0.16063777 | O12: ='Tabelau Fraction'!AC11+'Tabelau Fraction'!AH11 -> 0.043267542 | P12: ='Tabelau Fraction'!AD11 -> 0.24260729 | Q12: ='Tabelau Fraction'!AM11 -> 0.096298377 | R12: =Q12+P12+O12+N12+M12+L12+K12+J12+I12+H12+G12+F12+E12+D12+C12 -> 1
A13: Draguignan | B13: Vert/Rouge | C13: ='Tabelau Fraction'!Q13 -> 0.02294869 | D13: ='Tabelau Fraction'!AJ13+'Tabelau Fraction'!R13+'Tabelau Fraction'!L13 -> 0.0023093022 | E13: ='Tabelau Fraction'!S13+'Tabelau Fraction'!AI13 -> 0.043371581 | F13: ='Tabelau Fraction'!M13+'Tabelau Fraction'!T13 -> 0.038969474 | G13: ='Tabelau Fraction'!N13+'Tabelau Fraction'!U13+'Tabelau Fraction'!AL13 -> 0.059753193 | H13: ='Tabelau Fraction'!O13+'Tabelau Fraction'!V13 -> 0.012628996 | I13: ='Tabelau Fraction'!W13+'Tabelau Fraction'!AK13 -> 0.14389839 | J13: ='Tabelau Fraction'!X13 -> 0.011907339 | K13: ='Tabelau Fraction'!P13+'Tabelau Fraction'!Y13+'Tabelau Fraction'!AE13 -> 0.026484809 | L13: ='Tabelau Fraction'!Z13+'Tabelau Fraction'!AF13 -> 0.18965144 | M13: ='Tabelau Fraction'!AA13 -> 0.010031031 | N13: ='Tabelau Fraction'!AB13+'Tabelau Fraction'!AG13 -> 0.013134156 | O13: ='Tabelau Fraction'!AC13+'Tabelau Fraction'!AH13 -> 0.10911453 | P13: ='Tabelau Fraction'!AD13 -> 0.2589305 | Q13: ='Tabelau Fraction'!AM13 -> 0.056866566 | R13: =Q13+P13+O13+N13+M13+L13+K13+J13+I13+H13+G13+F13+E13+D13+C13 -> 1
A14: Salernes | B14: Ext | C14: ='Tabelau Fraction'!Q15 -> 0.026225867 | D14: ='Tabelau Fraction'!AJ15+'Tabelau Fraction'!R15+'Tabelau Fraction'!L15 -> 0.0019648044 | E14: ='Tabelau Fraction'!S15+'Tabelau Fraction'!AI15 -> 0.060652657 | F14: ='Tabelau Fraction'!M15+'Tabelau Fraction'!T15 -> 0.039808645 | G14: ='Tabelau Fraction'!N15+'Tabelau Fraction'!U15+'Tabelau Fraction'!AL15 -> 0.063044593 | H14: ='Tabelau Fraction'!O15+'Tabelau Fraction'!V15 -> 0.0067486759 | I14: ='Tabelau Fraction'!W15+'Tabelau Fraction'!AK15 -> 0.098923629 | J14: ='Tabelau Fraction'!X15 -> 0.024431915 | K14: ='Tabelau Fraction'!P15+'Tabelau Fraction'!Y15+'Tabelau Fraction'!AE15 -> 0.025115325 | L14: ='Tabelau Fraction'!Z15+'Tabelau Fraction'!AF15 -> 0.093285495 | M14: ='Tabelau Fraction'!AA15 -> 0.0021356569 | N14: ='Tabelau Fraction'!AB15+'Tabelau Fraction'!AG15 -> 0.20527934 | O14: ='Tabelau Fraction'!AC15+'Tabelau Fraction'!AH15 -> 0.070732957 | P14: ='Tabelau Fraction'!AD15 -> 0.25790193 | Q14: ='Tabelau Fraction'!AM15 -> 0.023748505 | R14: =Q14+P14+O14+N14+M14+L14+K14+J14+I14+H14+G14+F14+E14+D14+C14 -> 1
A15: Flayosc | B15: Ext | C15: ='Tabelau Fraction'!Q17 -> 0.040219429 | D15: ='Tabelau Fraction'!AJ17+'Tabelau Fraction'!R17+'Tabelau Fraction'!L17 -> 0.0059248726 | E15: ='Tabelau Fraction'!S17+'Tabelau Fraction'!AI17 -> 0.039731499 | F15: ='Tabelau Fraction'!M17+'Tabelau Fraction'!T17 -> 0.030948746 | G15: ='Tabelau Fraction'!N17+'Tabelau Fraction'!U17+'Tabelau Fraction'!AL17 -> 0.064337146 | H15: ='Tabelau Fraction'!O17+'Tabelau Fraction'!V17 -> 0.010595066 | I15: ='Tabelau Fraction'!W17+'Tabelau Fraction'!AK17 -> 0.091521856 | J15: ='Tabelau Fraction'!X17 -> 0.057645525 | K15: ='Tabelau Fraction'!P17+'Tabelau Fraction'!Y17+'Tabelau Fraction'!AE17 -> 0.065313008 | L15: ='Tabelau Fraction'!Z17+'Tabelau Fraction'!AF17 -> 0.083282798 | M15: ='Tabelau Fraction'!AA17 -> 0 | N15: ='Tabelau Fraction'!AB17+'Tabelau Fraction'!AG17 -> 0.086781958 | O15: ='Tabelau Fraction'!AC17+'Tabelau Fraction'!AH17 -> 0.091974934 | P15: ='Tabelau Fraction'!AD17 -> 0.23441584 | Q15: ='Tabelau Fraction'!AM17 -> 0.09730732 | R15: =Q15+P15+O15+N15+M15+L15+K15+J15+I15+H15+G15+F15+E15+D15+C15 -> 1
A16: Draguignan | B16: Rouge A1 | C16: ='Tabelau Fraction'!Q19 -> 0.021823273 | D16: ='Tabelau Fraction'!AJ19+'Tabelau Fraction'!R19+'Tabelau Fraction'!L19 -> 0.0045293585 | E16: ='Tabelau Fraction'!S19+'Tabelau Fraction'!AI19 -> 0.096928271 | F16: ='Tabelau Fraction'!M19+'Tabelau Fraction'!T19 -> 0.019270362 | G16: ='Tabelau Fraction'!N19+'Tabelau Fraction'!U19+'Tabelau Fraction'!AL19 -> 0.068846249 | H16: ='Tabelau Fraction'!O19+'Tabelau Fraction'!V19 -> 0.019105658 | I16: ='Tabelau Fraction'!W19+'Tabelau Fraction'!AK19 -> 0.10285761 | J16: ='Tabelau Fraction'!X19 -> 0.018117434 | K16: ='Tabelau Fraction'!P19+'Tabelau Fraction'!Y19+'Tabelau Fraction'!AE19 -> 0.02338796 | L16: ='Tabelau Fraction'!Z19+'Tabelau Fraction'!AF19 -> 0.18397431 | M16: ='Tabelau Fraction'!AA19 -> 0.02964671 | N16: ='Tabelau Fraction'!AB19+'Tabelau Fraction'!AG19 -> 0.067693321 | O16: ='Tabelau Fraction'!AC19+'Tabelau Fraction'!AH19 -> 0.059458124 | P16: ='Tabelau Fraction'!AD19 -> 0.1503747 | Q16: ='Tabelau Fraction'!AM19 -> 0.13398666 | R16: =Q16+P16+O16+N16+M16+L16+K16+J16+I16+H16+G16+F16+E16+D16+C16 -> 1
A17: Vidauban | B17: Ext | C17: ='Tabelau Fraction'!Q21 -> 0.036137214 | D17: ='Tabelau Fraction'!AJ21+'Tabelau Fraction'!R21+'Tabelau Fraction'!L21 -> 0.0070288028 | E17: ='Tabelau Fraction'!S21+'Tabelau Fraction'!AI21 -> 0.021774009 | F17: ='Tabelau Fraction'!M21+'Tabelau Fraction'!T21 -> 0.05103522 | G17: ='Tabelau Fraction'!N21+'Tabelau Fraction'!U21+'Tabelau Fraction'!AL21 -> 0.04950722 | H17: ='Tabelau Fraction'!O21+'Tabelau Fraction'!V21 -> 0.02444801 | I17: ='Tabelau Fraction'!W21+'Tabelau Fraction'!AK21 -> 0.077928031 | J17: ='Tabelau Fraction'!X21 -> 0.081289633 | K17: ='Tabelau Fraction'!P21+'Tabelau Fraction'!Y21+'Tabelau Fraction'!AE21 -> 0.043013217 | L17: ='Tabelau Fraction'!Z21+'Tabelau Fraction'!AF21 -> 0.20192528 | M17: ='Tabelau Fraction'!AA21 -> 0.012224005 | N17: ='Tabelau Fraction'!AB21+'Tabelau Fraction'!AG21 -> 0.056001222 | O17: ='Tabelau Fraction'!AC21+'Tabelau Fraction'!AH21 -> 0.058904424 | P17: ='Tabelau Fraction'!AD21 -> 0.19795248 | Q17: ='Tabelau Fraction'!AM21 -> 0.080831232 | R17: =Q17+P17+O17+N17+M17+L17+K17+J17+I17+H17+G17+F17+E17+D17+C17 -> 1
A18: TOTAL CAD | C18: =SUM(C10:C17)/SUM($C$10:$Q$17) -> 0.036708382 | D18: =SUM(D10:D17)/SUM($C$10:$Q$17) -> 0.0047742859 | E18: =SUM(E10:E17)/SUM($C$10:$Q$17) -> 0.048570232 | F18: =SUM(F10:F17)/SUM($C$10:$Q$17) -> 0.044471369 | G18: =SUM(G10:G17)/SUM($C$10:$Q$17) -> 0.061902199 | H18: =SUM(H10:H17)/SUM($C$10:$Q$17) -> 0.012414201 | I18: =SUM(I10:I17)/SUM($C$10:$Q$17) -> 0.12489352 | J18: =SUM(J10:J17)/SUM($C$10:$Q$17) -> 0.040053254 | ... Q18: =SUM(Q10:Q17)/SUM($C$10:$Q$17) -> 0.076928515 | R18: =SUM(C18:Q18) -> 1

Sheet TRAME CAD
B1: x | C1: Rapport de Prelevement OM CAD | F1: Système de Management
B6: INFORMATIONS GENERALES
B7: Colectivité | D7: CAD
B8: Type de flux | D8: OM
B9: Heure
B10: Tournée
B11: Date réception et Poids receptionné
B13: TRI DU PRELEVEMENT
B14: Opérateur/Nbre Trieurs
B15: Date et Heure
B17: RESULTAT
B18: Produits | D18: Poids | F18: Pourcentage
B19: Fractions >200mm | C19: Gros Inertes (Cailloux) | F19: =+D19/D51 -> #DIV/0!
C20: Films plastiques | F20: =+D20/D51 -> #DIV/0!
C21: Plastiques rigides | F21: =+D21/D51 -> #DIV/0!
C22: Bois | F22: =+D22/D51 -> #DIV/0!
C23: Grosse fractions métalliques | F23: =+D23/D51 -> #DIV/0!
C24: EMR | F24: =+D24/D51 -> #DIV/0!
B26: Fractions > 70mm | C26: Inertes | F26: =+D26/D51 -> #DIV/0!
C27: Verre | F27: =+D27/D51 -> #DIV/0!
C28: Petits films | F28: =D28/D51 -> #DIV/0!
C29: Autres plastiques rigides | F29: =D29/D51 -> #DIV/0!
C30: Bois | F30: =D30/D51 -> #DIV/0!
C31: Fibreux | F31: =D31/D51 -> #DIV/0!
C32: Textiles | F32: =D32/D51 -> #DIV/0!
C33: Fractions métaliques | F33: =D33/D51 -> #DIV/0!
C34: Dechets Alimentaires | F34: =D34/D51 -> #DIV/0!
C35: Produits alimentaires non consommés | F35: =D35/D51 -> #DIV/0!
C36: Déchets de jardin | F36: =D36/D51 -> #DIV/0!
C37: Textiles Sanitaires | F37: =D37/D51 -> #DIV/0!
C38: Refus | F38: =D38/D51 -> #DIV/0!
B40: Fractions < 70mm | C40: Fractions métallique (Ferreux, non ferreux) | F40: =+D40/D51 -> #DIV/0!
C41: Dechets Alimentaires | F41: =+D41/D51 -> #DIV/0!
C42: Déchets de jardin | F42: =+D42/D51 -> #DIV/0!
C43: Textiles Sanitaires | F43: =+D43/D51 -> #DIV/0!
C44: Verre | F44: =+D44/D51 -> #DIV/0!
C45: Inertes | F45: =+D45/D51 -> #DIV/0!
C46: Fibreux | F46: =+D46/D51 -> #DIV/0!
C47: Plastiques | F47: =+D47/D51 -> #DIV/0!
B49: Fractions < 20mm | C49: Fines Inferieur à 0,20 | F49: =+D49/D51 -> #DIV/0!
...

Sheet Les Arcs sur Argens
B1: x | C1: Rapport de Prelevement OM CAD | F1: Système de Management
B6: INFORMATIONS GENERALES
B7: Colectivité | D7: CAD
B8: Type de flux | D8: OM
B9: Heure | D9: 09h06
B10: Tournée | D10: Les Arcs sur Argens ext
B11: Date réception et Poids receptionné | D11: 43608 | F11: 4.52
B13: TRI DU PRELEVEMENT
B14: Opérateur/Nbre Trieurs | D14: Claudine | F14: Manon
B15: Date et Heure | D15: 43612 | F15: 05h30
B17: RESULTAT
B18: Produits | D18: Poids | F18: Pourcentage
B19: Fractions >200mm | C19: Gros Inertes (Cailloux) | D19: 0 | F19: =+D19/D51 -> 0
C20: Films plastiques | D20: =3.24+0.2 -> 3.44 | F20: =+D20/D51 -> 0.015745148
C21: Plastiques rigides | D21: 2.6 | F21: =+D21/D51 -> 0.011900403
C22: Bois | D22: 0.78 | F22: =+D22/D51 -> 0.0035701208
C23: Grosse fractions métalliques | D23: 0.78 | F23: =+D23/D51 -> 0.0035701208
C24: EMR | D24: =6.98+2.66 -> 9.64 | F24: =+D24/D51 -> 0.044123032
B26: Fractions > 70mm | C26: Inertes | D26: 1.1 | F26: =+D26/D51 -> 0.0050347858
C27: Verre | D27: =6.4+3.76 -> 10.16 | F27: =+D27/D51 -> 0.046503112
C28: Petits films | D28: =4.16+9.1 -> 13.26 | F28: =D28/D51 -> 0.060692054
C29: Autres plastiques rigides | D29: =4.86+5.44 -> 10.3 | F29: =D29/D51 -> 0.047143903
C30: Bois | D30: 0.6 | F30: =D30/D51 -> 0.0027462468
C31: Fibreux | D31: =7.4+5.06+7.94+5.44 -> 25.84 | F31: =D31/D51 -> 0.1182717
C32: Textiles | D32: =16.54+5.26 -> 21.8 | F32: =D32/D51 -> 0.0997803
C33: Fractions métaliques | D33: =1.08+3.18 -> 4.26 | F33: =D33/D51 -> 0.019498352
C34: Dechets Alimentaires | D34: =7.86+5.3+8.14 -> 21.3 | F34: =D34/D51 -> 0.097491761
C35: Produits alimentaires non consommés | D35: 1.2 | F35: =D35/D51 -> 0.0054924936
C36: Déchets de jardin | D36: =19.9+6.98 -> 26.88 | F36: =D36/D51 -> 0.12303186
C37: Textiles Sanitaires | D37: =7.02+3.34 -> 10.36 | F37: =D37/D51 -> 0.047418528
C38: Refus | D38: =11.54+5.2+6.9+12.18 -> 35.82 | F38: =D38/D51 -> 0.16395093
B40: Fractions < 70mm | C40: Fractions métallique (Ferreux, non ferreux) | D40: 1.94 | F40: =+D40/D51 -> 0.0088795313
C41: Dechets Alimentaires | D41: 1.16 | F41: =+D41/D51 -> 0.0053094105
C42: Déchets de jardin | D42: 0.26 | F42: =+D42/D51 -> 0.0011900403
C43: Textiles Sanitaires | D43: 0.96 | F43: =+D43/D51 -> 0.0043939949
C44: Verre | D44: 0.66 | F44: =+D44/D51 -> 0.0030208715
C45: Inertes | D45: 0.32 | F45: =+D45/D51 -> 0.001464665
C46: Fibreux | D46: 1.04 | F46: =+D46/D51 -> 0.0047601611
C47: Plastiques | D47: 0.52 | F47: =+D47/D51 -> 0.0023800806
B49: Fractions < 20mm | C49: Fines Inferieur à 0,20 | D49: 11.5 | F49: =+D49/D51 -> 0.052636397
...

Sheet Draguignan  Bleu A1
B1: x | C1: Rapport de Prelevement OM CAD | F1: Système de Management
B6: INFORMATIONS GENERALES
B7: Colectivité | D7: CAD
B8: Type de flux | D8: OM
B9: Heure | D9: 09h13
B10: Tournée | D10: Draguignan Bleu A1
B11: Date réception et Poids receptionné | D11: 43609 | F11: 6.62
B13: TRI DU PRELEVEMENT
B14: Opérateur/Nbre Trieurs | D14: Claudine | F14: Manon
B15: Date et Heure | D15: 43612 | F15: 09h30
B17: RESULTAT
B18: Produits | D18: Poids | F18: Pourcentage
B19: Fractions >200mm | C19: Gros Inertes (Cailloux) | D19: 0 | F19: =+D19/D51 -> 0
C20: Films plastiques | D20: 1.6 | F20: =+D20/D51 -> 0.0043067481
C21: Plastiques rigides | D21: 0.76 | F21: =+D21/D51 -> 0.0020457054
C22: Bois | D22: 1.74 | F22: =+D22/D51 -> 0.0046835886
C23: Grosse fractions métalliques | D23: 0.92 | F23: =+D23/D51 -> 0.0024763802
C24: EMR | D24: =11.36+13.76+6.66 -> 31.78 | F24: =+D24/D51 -> 0.085542785
B26: Fractions > 70mm | C26: Inertes | D26: 1.5 | F26: =+D26/D51 -> 0.0040375764
C27: Verre | D27: =2.94+2.96+6.44 -> 12.34 | F27: =+D27/D51 -> 0.033215795
C28: Petits films | D28: =11.22+6.04 -> 17.26 | F28: =D28/D51 -> 0.046459046
C29: Autres plastiques rigides | D29: =6.88+7.18+6.94 -> 21 | F29: =D29/D51 -> 0.056526069
C30: Bois | D30: 0.64 | F30: =D30/D51 -> 0.0017226993
C31: Fibreux | D31: =13.5+18.2+16.1+7.74+8.4+10.98 -> 74.92 | F31: =D31/D51 -> 0.20166348
C32: Textiles | D32: 7.62 | F32: =D32/D51 -> 0.020510888
C33: Fractions métaliques | D33: 7.12 | F33: =D33/D51 -> 0.019165029
C34: Dechets Alimentaires | D34: =12.1+13.38+11.28+11.2 -> 47.96 | F34: =D34/D51 -> 0.12909478
C35: Produits alimentaires non consommés | D35: 0.98 | F35: =D35/D51 -> 0.0026378832
C36: Déchets de jardin | D36: =15.36+6.6 -> 21.96 | F36: =D36/D51 -> 0.059110118
C37: Textiles Sanitaires | D37: =12.74+9.48+4.49 -> 26.71 | F37: =D37/D51 -> 0.071895777
C38: Refus | D38: =12.52+10.64+7.04+9.58+12.08+7.24 -> 59.1 | F38: =D38/D51 -> 0.15908051
B40: Fractions < 70mm | C40: Fractions métallique (Ferreux, non ferreux) | D40: 0.26 | F40: =+D40/D51 -> 0.00069984657
C41: Dechets Alimentaires | D41: 1.46 | F41: =+D41/D51 -> 0.0039299077
C42: Déchets de jardin | D42: 1.2 | F42: =+D42/D51 -> 0.0032300611
C43: Textiles Sanitaires | D43: 0.78 | F43: =+D43/D51 -> 0.0020995397
C44: Verre | D44: 2.28 | F44: =+D44/D51 -> 0.0061371161
C45: Inertes | D45: 0 | F45: =+D45/D51 -> 0
C46: Fibreux | D46: 1.26 | F46: =+D46/D51 -> 0.0033915642
C47: Plastiques | D47: 0.96 | F47: =+D47/D51 -> 0.0025840489
B49: Fractions < 20mm | C49: Fines Inferieur à 0,20 | D49: 27.4 | F49: =+D49/D51 -> 0.073753062
...

Sheet Trans en Provence Ext
B1: x | C1: Rapport de Prelevement OM CAD | F1: Système de Management
B6: INFORMATIONS GENERALES
B7: Colectivité | D7: CAD
B8: Type de flux | D8: OM
B9: Heure | D9: 09h41
B10: Tournée | D10: Trans en Provence Ext
B11: Date réception et Poids receptionné | D11: 43609 | F11: 5
B13: TRI DU PRELEVEMENT
B14: Opérateur/Nbre Trieurs | D14: Claudine | F14: Manon
B15: Date et Heure | D15: 43613 | F15: 08h20
B17: RESULTAT
B18: Produits | D18: Poids | F18: Pourcentage
B19: Fractions >200mm | C19: Gros Inertes (Cailloux) | D19: 0 | F19: =+D19/D51 -> 0
C20: Films plastiques | D20: 0.46 | F20: =+D20/D51 -> 0.0016155089
C21: Plastiques rigides | D21: 1.16 | F21: =+D21/D51 -> 0.004073892
C22: Bois | D22: 0.72 | F22: =+D22/D51 -> 0.0025286226
C23: Grosse fractions métalliques | D23: 3.66 | F23: =+D23/D51 -> 0.012853832
C24: EMR | D24: 4.74 | F24: =+D24/D51 -> 0.016646765
B26: Fractions > 70mm | C26: Inertes | D26: 0.78 | F26: =+D26/D51 -> 0.0027393412
C27: Verre | D27: =6.3+2.64 -> 8.94 | F27: =+D27/D51 -> 0.031397064
C28: Petits films | D28: =4.88+4.18+4.3 -> 13.36 | F28: =D28/D51 -> 0.046919997
C29: Autres plastiques rigides | D29: =6.62+2.26+8.1 -> 16.98 | F29: =D29/D51 -> 0.05963335
C30: Bois | D30: 3 | F30: =D30/D51 -> 0.010535928
C31: Fibreux | D31: =7.54+10.4+14.78+10.6 -> 43.32 | F31: =D31/D51 -> 0.15213879
C32: Textiles | D32: 1.92 | F32: =D32/D51 -> 0.0067429936
C33: Fractions métaliques | D33: 6.06 | F33: =D33/D51 -> 0.021282574
C34: Dechets Alimentaires | D34: =7.1+7.18+2.96 -> 17.24 | F34: =D34/D51 -> 0.060546463
C35: Produits alimentaires non consommés | D35: 1.36 | F35: =D35/D51 -> 0.0047762871
C36: Déchets de jardin | D36: =17.6+13.82+14.14 -> 45.56 | F36: =D36/D51 -> 0.16000562
C37: Textiles Sanitaires | D37: =5.62+5.22 -> 10.84 | F37: =D37/D51 -> 0.038069818
C38: Refus | D38: =12.02+14.56+16.88+13.64+11.98 -> 69.08 | F38: =D38/D51 -> 0.24260729
B40: Fractions < 70mm | C40: Fractions métallique (Ferreux, non ferreux) | D40: 0.68 | F40: =+D40/D51 -> 0.0023881436
C41: Dechets Alimentaires | D41: 1.18 | F41: =+D41/D51 -> 0.0041441315
C42: Déchets de jardin | D42: 0.18 | F42: =+D42/D51 -> 0.00063215565
C43: Textiles Sanitaires | D43: 1.48 | F43: =+D43/D51 -> 0.0051977242
C44: Verre | D44: 1.66 | F44: =+D44/D51 -> 0.0058298799
C45: Inertes | D45: 0.9 | F45: =+D45/D51 -> 0.0031607783
C46: Fibreux | D46: 1.08 | F46: =+D46/D51 -> 0.0037929339
C47: Plastiques | D47: 0.98 | F47: =+D47/D51 -> 0.0034417363
B49: Fractions < 20mm | C49: Fines Inferieur à 0,20 | D49: =10.44+16.98 -> 27.42 | F49: =+D49/D51 -> 0.096298377
...

Sheet Draguignan Vert-Rouge
B1: x | C1: Rapport de Prelevement OM CAD | F1: Système de Management
B6: INFORMATIONS GENERALES
B7: Colectivité | D7: CAD
B8: Type de flux | D8: OM
B9: Heure | D9: 10h36
B10: Tournée | D10: Draguignan Vert/Rouge
B11: Date réception et Poids receptionné | D11: 43609 | F11: 9.36
B13: TRI DU PRELEVEMENT
B14: Opérateur/Nbre Trieurs | D14: Claudine | F14: Manon
B15: Date et Heure | D15: 43613 | F15: 5h30
B17: RESULTAT
B18: Produits | D18: Poids | F18: Pourcentage
B19: Fractions >200mm | C19: Gros Inertes (Cailloux) | D19: 0 | F19: =+D19/D51 -> 0
C20: Films plastiques | D20: 0 | F20: =+D20/D51 -> 0
C21: Plastiques rigides | D21: 0 | F21: =+D21/D51 -> 0
C22: Bois | D22: 2.1 | F22: =+D22/D51 -> 0.0075773977
C23: Grosse fractions métalliques | D23: 1.74 | F23: =+D23/D51 -> 0.0062784152
C24: EMR | D24: 6.36 | F24: =+D24/D51 -> 0.02294869
B26: Fractions > 70mm | C26: Inertes | D26: 0.64 | F26: =+D26/D51 -> 0.0023093022
C27: Verre | D27: =7.36+4.48 -> 11.84 | F27: =+D27/D51 -> 0.04272209
C28: Petits films | D28: =5.94+4.86 -> 10.8 | F28: =D28/D51 -> 0.038969474
C29: Autres plastiques rigides | D29: =6.18+6.12+3.96 -> 16.26 | F29: =D29/D51 -> 0.058670708
C30: Bois | D30: 1.4 | F30: =D30/D51 -> 0.0050515985
C31: Fibreux | D31: =8.9+10.74+12.4+7.56 -> 39.6 | F31: =D31/D51 -> 0.14288807
C32: Textiles | D32: 3.3 | F32: =D32/D51 -> 0.011907339
C33: Fractions métaliques | D33: 5.42 | F33: =D33/D51 -> 0.019556903
C34: Dechets Alimentaires | D34: =13.44+4.44+10.7+11.26+11.58 -> 51.42 | F34: =D34/D51 -> 0.185538
C35: Produits alimentaires non consommés | D35: 2.78 | F35: =D35/D51 -> 0.010031031
C36: Déchets de jardin | D36: 3.54 | F36: =D36/D51 -> 0.012773328
C37: Textiles Sanitaires | D37: =7+7.72+6.5+8.4 -> 29.62 | F37: =D37/D51 -> 0.10687739
C38: Refus | D38: =15.04+21.6+10.2+14.98+9.94 -> 71.76 | F38: =D38/D51 -> 0.2589305
B40: Fractions < 70mm | C40: Fractions métallique (Ferreux, non ferreux) | D40: 0.18 | F40: =+D40/D51 -> 0.00064949123
C41: Dechets Alimentaires | D41: 1.14 | F41: =+D41/D51 -> 0.0041134445
C42: Déchets de jardin | D42: 0.1 | F42: =+D42/D51 -> 0.00036082846
C43: Textiles Sanitaires | D43: 0.62 | F43: =+D43/D51 -> 0.0022371365
C44: Verre | D44: 0.18 | F44: =+D44/D51 -> 0.00064949123
C45: Inertes | D45: 0 | F45: =+D45/D51 -> 0
C46: Fibreux | D46: 0.28 | F46: =+D46/D51 -> 0.0010103197
C47: Plastiques | D47: 0.3 | F47: =+D47/D51 -> 0.0010824854
B49: Fractions < 20mm | C49: Fines Inferieur à 0,20 | D49: 15.76 | F49: =+D49/D51 -> 0.056866566
...

Sheet Salernes Ext
B1: x | C1: Rapport de Prelevement OM CAD | F1: Système de Management
B6: INFORMATIONS GENERALES
B7: Colectivité | D7: CAD
B8: Type de flux | D8: OM
B9: Heure | D9: 09h05
B10: Tournée | D10: Salernes Ext
B11: Date réception et Poids receptionné | D11: 43610 | F11: 5.5
B13: TRI DU PRELEVEMENT
B14: Opérateur/Nbre Trieurs | D14: Claudine | F14: Manon
B15: Date et Heure | D15: 43614 | F15: 5h30
B17: RESULTAT
B18: Produits | D18: Poids | F18: Pourcentage
B19: Fractions >200mm | C19: Gros Inertes (Cailloux) | D19: 0.14 | F19: =+D19/D51 -> 0.00059798394
C20: Films plastiques | D20: 1.86 | F20: =+D20/D51 -> 0.0079446438
C21: Plastiques rigides | D21: 0.6 | F21: =+D21/D51 -> 0.0025627883
C22: Bois | D22: 0.9 | F22: =+D22/D51 -> 0.0038441825
C23: Grosse fractions métalliques | D23: 0 | F23: =+D23/D51 -> 0
C24: EMR | D24: =5.7+0.44 -> 6.14 | F24: =+D24/D51 -> 0.026225867
B26: Fractions > 70mm | C26: Inertes | D26: 0 | F26: =+D26/D51 -> 0
C27: Verre | D27: =9.02+4.9 -> 13.92 | F27: =+D27/D51 -> 0.059456689
C28: Petits films | D28: =2.52+3.44+1.5 -> 7.46 | F28: =D28/D51 -> 0.031864001
C29: Autres plastiques rigides | D29: =6.86+4.12+2.8 -> 13.78 | F29: =D29/D51 -> 0.058858705
C30: Bois | D30: 0.68 | F30: =D30/D51 -> 0.0029044934
C31: Fibreux | D31: =7.56+6.18+5.24+3.9 -> 22.88 | F31: =D31/D51 -> 0.097727661
C32: Textiles | D32: 5.72 | F32: =D32/D51 -> 0.024431915
C33: Fractions métaliques | D33: 5.76 | F33: =D33/D51 -> 0.024602768
C34: Dechets Alimentaires | D34: =12.26+8.88 -> 21.14 | F34: =D34/D51 -> 0.090295575
C35: Produits alimentaires non consommés | D35: 0.5 | F35: =D35/D51 -> 0.0021356569
C36: Déchets de jardin | D36: =15.14+14.36+13.26 -> 42.76 | F36: =D36/D51 -> 0.18264138
C37: Textiles Sanitaires | D37: =10.04+6.02 -> 16.06 | F37: =D37/D51 -> 0.068597301
C38: Refus | D38: =16.64+6.4+9.36+9.08+8.66+10.24 -> 60.38 | F38: =D38/D51 -> 0.25790193
B40: Fractions < 70mm | C40: Fractions métallique (Ferreux, non ferreux) | D40: 0.12 | F40: =+D40/D51 -> 0.00051255766
C41: Dechets Alimentaires | D41: 0.7 | F41: =+D41/D51 -> 0.0029899197
C42: Déchets de jardin | D42: =2.74+2.56 -> 5.3 | F42: =+D42/D51 -> 0.022637963
C43: Textiles Sanitaires | D43: 0.5 | F43: =+D43/D51 -> 0.0021356569
C44: Verre | D44: 0.28 | F44: =+D44/D51 -> 0.0011959679
C45: Inertes | D45: 0.32 | F45: =+D45/D51 -> 0.0013668204
C46: Fibreux | D46: 0.28 | F46: =+D46/D51 -> 0.0011959679
C47: Plastiques | D47: 0.38 | F47: =+D47/D51 -> 0.0016230993
B49: Fractions < 20mm | C49: Fines Inferieur à 0,20 | D49: 5.56 | F49: =+D49/D51 -> 0.023748505
...

Sheet Lorgues
B1: x | C1: Rapport de Prelevement OM CAD | F1: Système de Management
B6: INFORMATIONS GENERALES
B7: Colectivité | D7: CAD
B8: Type de flux | D8: OM
B9: Heure | D9: 09h39
B10: Tournée | D10: Lorgues Ext
B11: Date réception et Poids receptionné | D11: 43612 | F11: 6.02
B13: TRI DU PRELEVEMENT
B14: Opérateur/Nbre Trieurs | D14: Claudine | F14: Manon
B15: Date et Heure | D15: 43614 | F15: 08h20
B17: RESULTAT
B18: Produits | D18: Poids | F18: Pourcentage
B19: Fractions >200mm | C19: Gros Inertes (Cailloux) | D19: 0 | F19: =+D19/D51 -> 0
C20: Films plastiques | D20: 0.32 | F20: =+D20/D51 -> 0.0011152701
C21: Plastiques rigides | D21: 0 | F21: =+D21/D51 -> 0
C22: Bois | D22: 1.22 | F22: =+D22/D51 -> 0.0042519674
C23: Grosse fractions métalliques | D23: 11.9 | F23: =+D23/D51 -> 0.041474108
C24: EMR | D24: 11.54 | F24: =+D24/D51 -> 0.040219429
B26: Fractions > 70mm | C26: Inertes | D26: 1.7 | F26: =+D26/D51 -> 0.0059248726
C27: Verre | D27: =4.2+6.52 -> 10.72 | F27: =+D27/D51 -> 0.03736155
C28: Petits films | D28: =6.88+1.68 -> 8.56 | F28: =D28/D51 -> 0.029833476
C29: Autres plastiques rigides | D29: =5.48+8.12+4.3 -> 17.9 | F29: =D29/D51 -> 0.062385423
C30: Bois | D30: 1.82 | F30: =D30/D51 -> 0.0063430989
C31: Fibreux | D31: =6.7+6.2+12.46 -> 25.36 | F31: =D31/D51 -> 0.088385159
C32: Textiles | D32: =12.56+3.98 -> 16.54 | F32: =D32/D51 -> 0.057645525
C33: Fractions métaliques | D33: 6.42 | F33: =D33/D51 -> 0.022375107
C34: Dechets Alimentaires | D34: =5.8+8.86+8.116 -> 22.776 | F34: =D34/D51 -> 0.079379352
C35: Produits alimentaires non consommés | D35: 0 | F35: =D35/D51 -> 0
C36: Déchets de jardin | D36: =17.38+6.22 -> 23.6 | F36: =D36/D51 -> 0.082251173
C37: Textiles Sanitaires | D37: =15.35+10.28 -> 25.63 | F37: =D37/D51 -> 0.089326168
C38: Refus | D38: =14.9+5.58+16.76+11.68+10.3+3.74+4.3 -> 67.26 | F38: =D38/D51 -> 0.23441584
B40: Fractions < 70mm | C40: Fractions métallique (Ferreux, non ferreux) | D40: 0.42 | F40: =+D40/D51 -> 0.0014637921
C41: Dechets Alimentaires | D41: 1.12 | F41: =+D41/D51 -> 0.0039034455
C42: Déchets de jardin | D42: 1.3 | F42: =+D42/D51 -> 0.0045307849
C43: Textiles Sanitaires | D43: 0.76 | F43: =+D43/D51 -> 0.0026487666
C44: Verre | D44: 0.68 | F44: =+D44/D51 -> 0.002369949
C45: Inertes | D45: 0 | F45: =+D45/D51 -> 0
C46: Fibreux | D46: 0.9 | F46: =+D46/D51 -> 0.0031366973
C47: Plastiques | D47: 0.56 | F47: =+D47/D51 -> 0.0019517227
B49: Fractions < 20mm | C49: Fines Inferieur à 0,20 | D49: =11.6+16.32 -> 27.92 | F49: =+D49/D51 -> 0.09730732
...

Sheet Flayosc
B1: x | C1: Rapport de Prelevement OM CAD | F1: Système de Management
B6: INFORMATIONS GENERALES
B7: Colectivité | D7: CAD
B8: Type de flux | D8: OM
B9: Heure | D9: 11h17
B10: Tournée | D10: Flayosc
B11: Date réception et Poids receptionné | D11: 43613 | F11: 2.76
B13: TRI DU PRELEVEMENT
B14: Opérateur/Nbre Trieurs | D14: =F14 -> Manon | F14: Manon
B15: Date et Heure | D15: 43615 | F15: 5h30
B17: RESULTAT
B18: Produits | D18: Poids | F18: Pourcentage
B19: Fractions >200mm | C19: Gros Inertes (Cailloux) | D19: 0 | F19: =+D19/D51 -> 0
C20: Films plastiques | D20: 0 | F20: =+D20/D51 -> 0
C21: Plastiques rigides | D21: 1.36 | F21: =+D21/D51 -> 0.0055999341
C22: Bois | D22: 4.14 | F22: =+D22/D51 -> 0.017046858
C23: Grosse fractions métalliques | D23: 1 | F23: =+D23/D51 -> 0.0041175986
C24: EMR | D24: 5.3 | F24: =+D24/D51 -> 0.021823273
B26: Fractions > 70mm | C26: Inertes | D26: 0.84 | F26: =+D26/D51 -> 0.0034587828
C27: Verre | D27: =8.32+9.38+2.4+3.1 -> 23.2 | F27: =+D27/D51 -> 0.095528288
C28: Petits films | D28: =3.46+1.22 -> 4.68 | F28: =D28/D51 -> 0.019270362
C29: Autres plastiques rigides | D29: =4.42+4.5+2.78+3.26 -> 14.96 | F29: =D29/D51 -> 0.061599275
C30: Bois | D30: 0.5 | F30: =D30/D51 -> 0.0020587993
C31: Fibreux | D31: =6.12+9.42+4.76+4.32 -> 24.62 | F31: =D31/D51 -> 0.10137528
C32: Textiles | D32: 4.4 | F32: =D32/D51 -> 0.018117434
C33: Fractions métaliques | D33: 4.56 | F33: =D33/D51 -> 0.01877625
C34: Dechets Alimentaires | D34: =11.34+8.22+5.32+10.5+7.96 -> 43.34 | F34: =D34/D51 -> 0.17845672
C35: Produits alimentaires non consommés | D35: =3.8+3.4 -> 7.2 | F35: =D35/D51 -> 0.02964671
C36: Déchets de jardin | D36: =12.1+4.22 -> 16.32 | F36: =D36/D51 -> 0.067199209
C37: Textiles Sanitaires | D37: =6.5+3.96+3.34 -> 13.8 | F37: =D37/D51 -> 0.056822861
C38: Refus | D38: =11.6+5.12+5.1+4.6+10.1 -> 36.52 | F38: =D38/D51 -> 0.1503747
B40: Fractions < 70mm | C40: Fractions métallique (Ferreux, non ferreux) | D40: 0.12 | F40: =+D40/D51 -> 0.00049411183
C41: Dechets Alimentaires | D41: 1.34 | F41: =+D41/D51 -> 0.0055175821
C42: Déchets de jardin | D42: 0.12 | F42: =+D42/D51 -> 0.00049411183
C43: Textiles Sanitaires | D43: 0.64 | F43: =+D43/D51 -> 0.0026352631
C44: Verre | D44: 0.34 | F44: =+D44/D51 -> 0.0013999835
C45: Inertes | D45: 0.26 | F45: =+D45/D51 -> 0.0010705756
C46: Fibreux | D46: 0.36 | F46: =+D46/D51 -> 0.0014823355
C47: Plastiques | D47: 0.4 | F47: =+D47/D51 -> 0.0016470394
B49: Fractions < 20mm | C49: Fines Inferieur à 0,20 | D49: 32.54 | F49: =+D49/D51 -> 0.13398666
...

Sheet Draguignan Rouge A1
B1: x | C1: Rapport de Prelevement OM CAD | F1: Système de Management
B6: INFORMATIONS GENERALES
B7: Colectivité | D7: CAD
B8: Type de flux | D8: OM
B9: Heure | D9: 11h36
B10: Tournée | D10: Draguignan Rouge A1
B11: Date réception et Poids receptionné | D11: 43614 | F11: 2.52
B13: TRI DU PRELEVEMENT
B14: Opérateur/Nbre Trieurs | D14: Claudine | F14: Manon
B15: Date et Heure | D15: 43615 | F15: 10h00
B17: RESULTAT
B18: Produits | D18: Poids | F18: Pourcentage
B19: Fractions >200mm | C19: Gros Inertes (Cailloux) | D19: 0 | F19: =+D19/D51 -> 0
C20: Films plastiques | D20: 3.06 | F20: =+D20/D51 -> 0.011689205
C21: Plastiques rigides | D21: 0 | F21: =+D21/D51 -> 0
C22: Bois | D22: =2.12+2.7 -> 4.82 | F22: =+D22/D51 -> 0.018412407
C23: Grosse fractions métalliques | D23: 0 | F23: =+D23/D51 -> 0
C24: EMR | D24: =2.72+6.74 -> 9.46 | F24: =+D24/D51 -> 0.036137214
B26: Fractions > 70mm | C26: Inertes | D26: =1.22+0.62 -> 1.84 | F26: =+D26/D51 -> 0.0070288028
C27: Verre | D27: =3.7+1.92 -> 5.62 | F27: =+D27/D51 -> 0.021468409
C28: Petits films | D28: =3.24+1.68+5.38 -> 10.3 | F28: =D28/D51 -> 0.039346016
C29: Autres plastiques rigides | D29: =4.38+2.82+0.8+4.86 -> 12.86 | F29: =D29/D51 -> 0.04912522
C30: Bois | D30: =0.8+0.78 -> 1.58 | F30: =D30/D51 -> 0.0060356024
C31: Fibreux | D31: =7.34+5.3+3.78+3.84 -> 20.26 | F31: =D31/D51 -> 0.077393231
C32: Textiles | D32: =17.62+2.42+1.24 -> 21.28 | F32: =D32/D51 -> 0.081289633
C33: Fractions métaliques | D33: =4.5+6.48 -> 10.98 | F33: =D33/D51 -> 0.041943617
C34: Dechets Alimentaires | D34: =6.2+10.84+5.08+7.02+2.48+6.24+14.24 -> 52.1 | F34: =D34/D51 -> 0.19902208
C35: Produits alimentaires non consommés | D35: =1.42+1.78 -> 3.2 | F35: =D35/D51 -> 0.012224005
C36: Déchets de jardin | D36: =12.38+0.66+1.46 -> 14.5 | F36: =D36/D51 -> 0.055390022
C37: Textiles Sanitaires | D37: =7.22+6.88+1.04 -> 15.14 | F37: =D37/D51 -> 0.057834823
C38: Refus | D38: =19.52+11.1+11.14+7.02+3.04 -> 51.82 | F38: =D38/D51 -> 0.19795248
B40: Fractions < 70mm | C40: Fractions métallique (Ferreux, non ferreux) | D40: 0.28 | F40: =+D40/D51 -> 0.0010696004
C41: Dechets Alimentaires | D41: 0.76 | F41: =+D41/D51 -> 0.0029032012
C42: Déchets de jardin | D42: 0.16 | F42: =+D42/D51 -> 0.00061120024
C43: Textiles Sanitaires | D43: 0.28 | F43: =+D43/D51 -> 0.0010696004
C44: Verre | D44: 0.08 | F44: =+D44/D51 -> 0.00030560012
C45: Inertes | D45: 0 | F45: =+D45/D51 -> 0
C46: Fibreux | D46: 0.14 | F46: =+D46/D51 -> 0.00053480021
C47: Plastiques | D47: 0.1 | F47: =+D47/D51 -> 0.00038200015
B49: Fractions < 20mm | C49: Fines Inferieur à 0,20 | D49: =11.72+9.44 -> 21.16 | F49: =+D49/D51 -> 0.080831232
...

Sheet Vidauban
B1: x | C1: Rapport de Prelevement OM CAD | F1: Système de Management
B6: INFORMATIONS GENERALES
B7: Colectivité | D7: CAD
B8: Type de flux | D8: OM
B9: Heure | D9: 10h35
B10: Tournée | D10: Vidauban Ext
B11: Date réception et Poids receptionné | D11: 43615 | F11: 7.4
B13: TRI DU PRELEVEMENT
B14: Opérateur/Nbre Trieurs | D14: Claudine | F14: Manon
B15: Date et Heure | D15: 43616 | F15: 06h00
B17: RESULTAT
B18: Produits | D18: Poids | F18: Pourcentage
B19: Fractions >200mm | C19: Gros Inertes (Cailloux) | D19: 0 | F19: =+D19/D51 -> 0
C20: Films plastiques | D20: 0 | F20: =+D20/D51 -> 0
C21: Plastiques rigides | D21: 0 | F21: =+D21/D51 -> 0
C22: Bois | D22: 0 | F22: =+D22/D51 -> 0
C23: Grosse fractions métalliques | D23: 0 | F23: =+D23/D51 -> 0
C24: EMR | D24: =6.9+4.72+6.26 -> 17.88 | F24: =+D24/D51 -> 0.066893636
B26: Fractions > 70mm | C26: Inertes | D26: 0 | F26: =+D26/D51 -> 0
C27: Verre | D27: =6.12+6.68+3.84+1.1 -> 17.74 | F27: =+D27/D51 -> 0.06636986
C28: Petits films | D28: =1.9+6.22+2 -> 10.12 | F28: =D28/D51 -> 0.037861499
C29: Autres plastiques rigides | D29: =3.74+4.78+5.1+0.86 -> 14.48 | F29: =D29/D51 -> 0.05417337
C30: Bois | D30: 1.26 | F30: =D30/D51 -> 0.0047139811
C31: Fibreux | D31: =7.28+3.54+7.92+7.06+6.88+6.7 -> 39.38 | F31: =D31/D51 -> 0.14733061
C32: Textiles | D32: 3.24 | F32: =D32/D51 -> 0.012121666
C33: Fractions métaliques | D33: 6.66 | F33: =D33/D51 -> 0.024916757
C34: Dechets Alimentaires | D34: =9.66+12.02+14.54+12.08+8.96 -> 57.26 | F34: =D34/D51 -> 0.21422425
C35: Produits alimentaires non consommés | D35: 2.34 | F35: =D35/D51 -> 0.0087545363
C36: Déchets de jardin | D36: =15.78+2.3 -> 18.08 | F36: =D36/D51 -> 0.067641887
C37: Textiles Sanitaires | D37: =3.98+4.36 -> 8.34 | F37: =D37/D51 -> 0.031202065
C38: Refus | D38: =3.62+3.38+5.7+5.75+4.6+7.16+12+5.76 -> 47.97 | F38: =D38/D51 -> 0.17946799
B40: Fractions < 70mm | C40: Fractions métallique (Ferreux, non ferreux) | D40: 0.24 | F40: =+D40/D51 -> 0.00089790116
C41: Dechets Alimentaires | D41: 1.66 | F41: =+D41/D51 -> 0.006210483
C42: Déchets de jardin | D42: 2.72 | F42: =+D42/D51 -> 0.010176213
C43: Textiles Sanitaires | D43: 1.08 | F43: =+D43/D51 -> 0.0040405552
C44: Verre | D44: 0.28 | F44: =+D44/D51 -> 0.0010475513
C45: Inertes | D45: 0 | F45: =+D45/D51 -> 0
C46: Fibreux | D46: 0.58 | F46: =+D46/D51 -> 0.0021699278
C47: Plastiques | D47: 0.54 | F47: =+D47/D51 -> 0.0020202776
B49: Fractions < 20mm | C49: Fines Inferieur à 0,20 | D49: 15.44 | F49: =+D49/D51 -> 0.057764974
...
