Workbook

Sheet 0-Revisions
A1: URBAN RIG — MODELE FINANCIER V7
A2: Revision du V6. Etablie le 21 septembre 2026. Char en deux hypotheses, PCI du char, modele de cadence.
A4: # | B4: Poste | C4: V3 | D4: V4 | E4: Statut | F4: Justification
A5: BLOC V5 — CORRECTIONS DU 19/09/2026
B6: Flux de tresorerie | C6: EBITDA - impot, sans les interets | D6: EBITDA + impot + interets | E6: CORRIGE | F6: DEUX ERREURS DU V4. Un : la ligne d'impot est negative et etait soustraite, donc l'impot s'AJOUTAIT a la tresorerie. Deux : les interets payes a la banque n'etaient pas deduits du flux libre. Le moteur Python avait la seconde erreur. Effet : flux libre et TRI des fonds propres fortement surestimes dans le V4.
B7: Bilan matiere | C7: 1 565 T/an non comptees | D7: Ecart nul, controle ajoute | E7: CORRIGE | F7: Trois fuites du V4 : fraction non classee de 2,5% (1 132 T/an), fer et aluminium ayant echappe au pre-tri (289 T/an), chlore du PVC (144 T/an). Les deux premieres vont en elimination, le chlore dans le concentrat. Lignes de controle K1 a K4 ajoutees a l'onglet 2-Production.
B8: Recuperation des metaux dans le char | C8: Autres metaux seulement | D8: Fer, aluminium et autres | E8: REINTRODUIT | F8: Le V3 recuperait dans le char 80% du fer et de l'aluminium ayant echappe au pre-tri. Le V4 l'avait perdu.
B9: Besoin en fonds de roulement | C9: Absent | D9: 5% du chiffre d'affaires | E9: REINTRODUIT | F9: Reprise du V3 F8. Variation annuelle en tresorerie, recuperation en annee 15.
B10: VAN et TRI | C10: Absents | D10: VAN au CMPC de 10%, TRI projet, TRI fonds propres | E10: REINTRODUIT | F10: Reprise du V3 F7.
B11: Prix de l'huile | C11: Craqueur 641 ou combustible 350 | D11: Trois fractions, trois scenarios : 480 / 641 / 895 | E11: REINTRODUIT | F11: Reprise du V3 section H. Le 350 EUR/T du V4 n'avait pas de source ; le scenario bas documente est a 480.
B12: Emprunt | C12: Amortissement lineaire du capital | D12: Annuites constantes, mensualites | E12: CORRIGE | F12: Reprise du V3 : 120 mensualites, pratique bancaire francaise.
B13: Humidite | C13: 8%, sans reserve | D13: 8%, avec avertissement | E13: PRECISE | F13: Le V3 precisait que les OMR sont a 25-35% et que 8% suppose une charge presechee. Avertissement retabli.
B14: Gate fees par type de dechet | C14: Moyenne unique a 110 | D14: Six categories + mode de calcul | E14: REINTRODUIT | F14: Reprise du V3 section G. Mode 1 : moyenne saisie (110, valeur par defaut). Mode 2 : melange par type (melange CDG : 119 EUR/T).
A15: BLOC A — ERREURS DE STRUCTURE
B16: Multiplicateur d'unites | C16: N'agit que sur les gate fees | D16: Agit sur tout le modele | E16: CORRIGE | F16: Dans le V3, la cellule A4 de 1-Waste Input multiplie le tonnage utilise pour les gate fees, mais l'huile, le char, les metaux, le verre, les credits carbone et la quasi-totalite de l'OPEX sont calcules a partir de la production journaliere d'UNE unite. Mettre 2 donnait un resultat faux.
B17: Recettes huile, char, metaux, verre | C17: Non multipliees par N | D17: Multipliees par N | E17: CORRIGE | F17: Consequence directe du point precedent.
B18: OPEX electricite, fioul, residus | C18: Non multiplies par N | D18: Multiplies par N | E18: CORRIGE
B19: Personnel de tri | C19: 4 + 3 ETP fixes | D19: 7 ETP par unite | E19: CORRIGE | F19: Le trommel du V3 est dimensionne a 6 T/h, soit 144 T/jour, c'est-a-dire le debit d'une seule machine. Deux machines exigent deux lignes de tri.
B20: Lignes de pre-tri et post-tri (CAPEX) | C20: Montant fixe | D20: x N | E20: CORRIGE | F20: Meme raison.
A21: BLOC B — ENERGIE
B22: PCI du gaz de procede — plastique | C22: 5,54 MJ/kg | D22: 37,3 MJ/kg | E22: CORRIGE | F22: Calcule a partir du rapport de chromatographie B2002600 du 05/12/2020. L'echantillon contient 65,8% de N2 et 12,3% de O2, soit 78,1% de diluant. Sur les 19,7% de gaz reel (H2 12,7%, CH4 3,2%, C2-C3 1,5%, CO 0,6%, CO2 1,7%), le PCI ressort a 37,3 MJ/kg, soit 18,8 MJ/Nm3. Le 5,54 MJ/kg du rapport d'essai est le PCI de l'echantillon DILUE, applique par erreur a la masse de gaz non dilue du bilan matiere.
B23: PCI du gaz de procede — organique | C23: 0,5 MJ/kg | D23: 11,0 MJ/kg | E23: CORRIGE | F23: Neves et al., Chalmers : PCI du gaz de pyrolyse de biomasse d'environ 11 MJ/kg a 600 degres C. Le 0,5 MJ/kg du V3 n'a aucune source. Valeur hors depot, a confirmer par un essai sur charge organique.
B24: Fioul de chauffe | C24: 7 494 L/jour, 989 297 EUR/an | D24: 0 L/jour en regime normal | E24: CORRIGE | F24: Avec les PCI corriges, le gaz de procede couvre 130% du besoin thermique a 30% de plastique. La separation etagee (150 / 300 / 450 degres C) permet d'ajuster la coupure C5 et donc l'arbitrage huile contre gaz. Le bruleur, le separateur et la filtration sont deja installes.
B25: Provision de fioul de secours | C25: Absente | D25: 5% du besoin theorique | E25: AJOUTE | F25: Demarrages, arrets, variations de charge, flamme pilote. Cellule modifiable.
B26: Besoin thermique | C26: 2 714 MJ/T | D26: 2 714 MJ/T | E26: INCHANGE | F26: Recoupement independant : le bruleur est donne a 833 kcal/s dans UR2000-JP, soit 3,49 MW et 301 190 MJ/jour, a comparer aux 338 802 MJ/jour du modele. Coherent a 11% pres.
B27: Rendement du bruleur | C27: Implicite 100% | D27: 85% | E27: AJOUTE | F27: Aucun bruleur ne transfere 100% de l'energie du combustible au procede.
A28: BLOC C — CAPEX
B29: Batiment | C29: 5,0 MEUR fixe | D29: Surface x 1 075 EUR/m2 | E29: CORRIGE | F29: Plans d'implantation UR2000-JP. Une machine : 4 650 m2 batis (usine 3 000, dechets 640, produits 810, bureaux 200). Cinq machines : 21 770 m2 (usine S 14 230, dechets RC 3 450, CSR RC 3 450, bureaux RC 640). La surface par machine ne baisse que de 6%.
B30: Emprise fonciere | C30: Absente | D30: Ligne indicative | E30: AJOUTE | F30: UR2000-JP : 5 265 m2 pour une machine, 28 900 m2 (170 x 170 m) pour cinq. A ne pas confondre avec la surface batie.
B31: Ingenierie, ICPE, MOE | C31: Fixe | D31: +20% par machine ajoutee | E31: CORRIGE | F31: Dossier ICPE et etude d'impact plus lourds.
A32: BLOC D — EXPLOITATION
B33: Electricite | C33: 4 800 kWh/jour | D33: 3 000 kWh/jour | E33: CORRIGE | F33: Quatre valeurs existent dans le depot : 20 kW en continu (fiche UR2000-JP), 600 kW (annexe 9), 4 800 kWh/jour soit 200 kW (V3), et 15 a 20 kWh/T mesures sur site (donnees Ichimura). 3 000 kWh/jour, soit 21,4 kWh/T, se cale sur la seule valeur mesuree. A trancher par un releve d'un mois.
B34: Prix de l'electricite | C34: 0,15 EUR/kWh | D34: 0,15 EUR/kWh | E34: INCHANGE
B35: Prix du fioul | C35: 0,40 EUR/L | D35: 0,95 EUR/L | E35: CORRIGE | F35: Prix GNR livre en France 2026 : 0,90 a 1,10 EUR/L HT. Sans effet materiel puisque la consommation tombe a la provision de secours.
B36: Assurance | C36: 0,5% du CAPEX | D36: 0,5% du CAPEX | E36: INCHANGE
B37: Provision et divers | C37: 2% du CAPEX | D37: 2% du CAPEX | E37: INCHANGE
B38: Maintenance | C38: 4% de l'equipement | D38: 4% de l'equipement | E38: INCHANGE | F38: Reserve : 5 a 8% est plus courant sur un procede haute temperature en atmosphere chloree. Cellule modifiable.
B39: Batiment | C39: 5,0 MEUR forfaitaires | D39: Surfaces x prix de marche par type | E39: CORRIGE | F39: Le 1 075 EUR/m2 de la premiere version du V4 etait un calcul inverse : 5 000 000 EUR du V3 divises par 4 650 m2 de plan. Ce n'etait pas une reference de marche. Remplace par quatre lignes aux prix du marche francais 2026 : usine de traitement 900 EUR/m2 (atelier de production, fourchette 500 a 1 000), stockage 500 EUR/m2 (hangar, fourchette 350 a 450 en charpente metallique), bureaux 1 300 EUR/m2. Le VRD, les fondations renforcees et les raccordements sortent en ligne distincte.
B40: VRD, fondations, raccordements | C40: Inclus dans le forfait | D40: 1,30 MEUR + 0,40 MEUR par unite | E40: AJOUTE | F40: UR2000-JP impose une dalle supportant 5 tonnes au m2. Poste distinct du batiment.
B41: Maintenance | C41: 4% de l'equipement des l'annee 1 | D41: 1% jusqu'en annee 4, montee lineaire a 4% en annee 10, puis 4% | E41: CORRIGE | F41: Equipement neuf sous garantie constructeur les premieres annees. Sur quinze ans le cumul passe de 60% a 40,5% du prix de l'equipement. Reserve a garder en tete : une revision majeure de refractaire tombe generalement entre l'annee 5 et l'annee 7 et n'est pas capturee par un pourcentage lisse.
...

Sheet 1-Inputs
A1: ENTREES DU MODELE
A2: Bleu = saisie. Orange = valeur corrigee par rapport au V3. Jaune = hypothese structurante non verifiee.
A4: Ref | B4: Parametre | C4: Valeur | D4: Unite | E4: Source / commentaire
A5: A — CAPACITE
A6: A1 | B6: Capacite nominale volumetrique par unite | C6: 200 | D6: m3/j | E6: URC-2000. Capacite volumetrique : 16 lots x 3 godets x 4,17 m3
A7: A2 | B7: Masse volumique des dechets | C7: 0.7 | D7: T/m3 | E7: V3 A2
A8: A3 | B8: Nombre d'unites URC-2000 | C8: 1 | D8: unites | E8: MODIFIABLE. Tout le modele suit desormais ce nombre
A9: A4 | B9: Jours d'exploitation par an | C9: 330 | D9: j/an | E9: V3 A5. 35 jours de maintenance
A11: B — COMPOSITION DU DECHET
A12: B1 | B12: Plastique | C12: 0.3 | D12: % | E12: V3 B1. La fiche constructeur UR2000-JP calcule son cas de reference a 10% de resine
A13: B2 | B13: Organique et cellulose | C13: 0.47 | D13: % | E13: V3 B2
A14: B3 | B14: Metaux | C14: 0.05 | D14: % | E14: V3 B3
A15: B4 | B15: Verre | C15: 0.055 | D15: % | E15: V3 B4
A16: B5 | B16: Inertes mineraux | C16: 0.02 | D16: % | E16: V3 B5
A17: B6 | B17: Humidite | C17: 0.08 | D17: % | E17: ATTENTION : les OMR brutes sont a 25-35% d'humidite. 8% suppose une charge presechee ou un gisement sec (emballages, dechets aeroportuaires). L'annexe 2 fait son controle thermique a ~20%
A18: B7 | B18: Autres | C18: 0.025 | D18: % | E18: V3 B7
A19: B8 | B19: Taux de refus a l'entree | C19: 0.02 | D19: % | E19: V3 D7
A20: B9 | B20: Part ferreuse des metaux | C20: 0.8 | D20: % | E20: V3 B2.1
A21: B10 | B21: Part aluminium des metaux | C21: 0.15 | D21: % | E21: V3 B2.2
A23: C — RENDEMENTS
A24: C1 | B24: Rendement huile sur plastique | C24: 0.69315 | D24: % | E24: V3 E1, moyenne ponderee du mix polymere
A25: C2 | B25: Rendement gaz sur plastique | C25: 0.193 | D25: % | E25: V3 E2
A26: C3 | B26: Rendement residu solide sur plastique | C26: 0.10325 | D26: % | E26: V3 E3
A27: C4 | B27: Rendement char sur organique | C27: 0.69 | D27: % | E27: V3 D1. NON VERIFIE. Litterature : 25 a 30% a 600 degres C. Lie au gaz par le bilan matiere
A28: C5 | B28: Masse volumique de l'huile | C28: 0.85 | D28: kg/L | E28: V3 D2
A30: D — ENERGIE (BLOC CORRIGE)
A31: D1 | B31: PCI du gaz issu du plastique | C31: 37.3 | D31: MJ/kg | E31: CORRIGE. Calcule sur le rapport GC B2002600 apres retrait du diluant (78,1% de N2 et O2). Etait 5,54
A32: D2 | B32: PCI du gaz issu de l'organique | C32: 11 | D32: MJ/kg | E32: CORRIGE. Neves et al., Chalmers, gaz de pyrolyse de biomasse a 600 degres C. Etait 0,5. Valeur hors depot, a mesurer
A33: D3 | B33: Besoin thermique | C33: 2714 | D33: MJ/T | E33: V3 D6. Recoupe par le bruleur de 833 kcal/s soit 3,49 MW
A34: D4 | B34: Rendement du bruleur | C34: 0.85 | D34: % | E34: AJOUTE
A35: D5 | B35: Provision de fioul de secours | C35: 0.05 | D35: % du besoin | E35: AJOUTE. Demarrages, arrets, flamme pilote
A36: D6 | B36: PCI du fioul | C36: 38 | D36: MJ/L | E36: V3
A37: D7 | B37: PCI du char organique | C37: ='1-Inputs'!$C$169 -> 25 | D37: MJ/kg | E37: V7. Lie a K1a. Etait 15 MJ/kg (V3 D4), incoherent avec les annexes (~25)
A39: E — TRI
A40: E1 | B40: Recuperation ferreux au pre-tri | C40: 0.9 | D40: % | E40: V3 P1
A41: E2 | B41: Recuperation aluminium au pre-tri | C41: 0.75 | D41: % | E41: V3 P2
A42: E3 | B42: Recuperation verre au pre-tri | C42: 0.7 | D42: % | E42: V3 P3
A43: E4 | B43: Retrait des inertes au pre-tri | C43: 0.5 | D43: % | E43: V3 P6
A44: E5 | B44: Criblage du char au post-tri | C44: 0.85 | D44: % | E44: V3 Q1
A45: E6 | B45: Metaux recuperes du char | C45: 0.8 | D45: % | E45: V3 Q2
...

Sheet 2-Production
A1: BILAN MATIERE ET ENERGIE
A2: Colonne C : une unite. Colonne D : toutes unites. Base journaliere sauf indication.
A4: Ref | B4: Grandeur | C4: Par unite | D4: Total | E4: Unite | F4: Commentaire
A5: T1 — ENTREE
A6: T1.1 | B6: Debit massique nominal | C6: ='1-Inputs'!$C$204 -> 140 | D6: =C6*'1-Inputs'!$C$8 -> 140 | E6: T/j | F6: V7. Voir onglet 1-Inputs, bloc L. Mode 1 : 200 m3/j x masse volumique
A7: T1.2 | B7: Tonnage annuel | C7: =C6*'1-Inputs'!$C$9 -> 46200 | D7: =C7*'1-Inputs'!$C$8 -> 46200 | E7: T/an
A8: T1.3 | B8: Entree brute | C8: =C6*1000 -> 140000 | D8: =C8*'1-Inputs'!$C$8 -> 140000 | E8: kg/j
A9: T1.4 | B9: Refus a l'entree | C9: =C8*'1-Inputs'!$C$19 -> 2800 | D9: =C9*'1-Inputs'!$C$8 -> 2800 | E9: kg/j
A10: T1.5 | B10: Entree nette traitee | C10: =C8-C9 -> 137200 | D10: =C10*'1-Inputs'!$C$8 -> 137200 | E10: kg/j
A12: T2 — COMPOSITION
A13: T2.1 | B13: Plastique | C13: =C10*'1-Inputs'!$C$12*(1-'1-Inputs'!$C$188*'1-Inputs'!$C$184) -> 41160 | D13: =C13*'1-Inputs'!$C$8 -> 41160 | E13: kg/j | F13: V6. Net des recyclables extraits au pre-tri si l option K11 est active
A14: T2.2 | B14: Organique et cellulose | C14: =C10*'1-Inputs'!$C$13*(1-'1-Inputs'!$C$188*'1-Inputs'!$C$186) -> 64484 | D14: =C14*'1-Inputs'!$C$8 -> 64484 | E14: kg/j
A15: T2.3 | B15: Metaux | C15: =C10*'1-Inputs'!$C$14 -> 6860 | D15: =C15*'1-Inputs'!$C$8 -> 6860 | E15: kg/j
A16: T2.4 | B16: Verre | C16: =C10*'1-Inputs'!$C$15 -> 7546 | D16: =C16*'1-Inputs'!$C$8 -> 7546 | E16: kg/j
A17: T2.5 | B17: Inertes | C17: =C10*'1-Inputs'!$C$16 -> 2744 | D17: =C17*'1-Inputs'!$C$8 -> 2744 | E17: kg/j
A18: T2.6 | B18: Autres, non classes | C18: =C10*'1-Inputs'!$C$18 -> 3430 | D18: =C18*'1-Inputs'!$C$8 -> 3430 | E18: kg/j
A20: T3 — SORTIES DU REACTEUR
A21: T3.1 | B21: Huile | C21: =C13*'1-Inputs'!$C$24 -> 28530.054 | D21: =C21*'1-Inputs'!$C$8 -> 28530.054 | E21: kg/j
A22: T3.2 | B22: Huile | C22: =C21/'1-Inputs'!$C$28 -> 33564.769 | D22: =C22*'1-Inputs'!$C$8 -> 33564.769 | E22: L/j
A23: T3.3 | B23: Gaz de procede issu du plastique | C23: =C13*'1-Inputs'!$C$25 -> 7943.88 | D23: =C23*'1-Inputs'!$C$8 -> 7943.88 | E23: kg/j
A24: T3.4 | B24: Residu solide du plastique | C24: =C13*'1-Inputs'!$C$26 -> 4249.77 | D24: =C24*'1-Inputs'!$C$8 -> 4249.77 | E24: kg/j
A25: T3.5 | B25: Char organique | C25: =C14*'1-Inputs'!$C$27 -> 44493.96 | D25: =C25*'1-Inputs'!$C$8 -> 44493.96 | E25: kg/j
A26: T3.5b | B26: Chlore du PVC capte dans l'eau (HCl) | C26: =C13*(1-'1-Inputs'!$C$24-'1-Inputs'!$C$25-'1-Inputs'!$C$26) -> 436.296 | D26: =C26*'1-Inputs'!$C$8 -> 436.296 | E26: kg/j | F26: V5. Complement a 100% des rendements plastique : 2% de PVC x 53% de chlore. Part dans l'eau, neutralise, finit dans le concentrat
A27: T3.6 | B27: Gaz de procede issu de l'organique | C27: =C14-C25 -> 19990.04 | D27: =C27*'1-Inputs'!$C$8 -> 19990.04 | E27: kg/j | F27: Par difference. Plus le rendement char est eleve, moins il reste de gaz
A29: T4 — BILAN ENERGIE (BLOC CORRIGE)
A30: T4.1 | B30: Energie du gaz issu du plastique | C30: =C23*'1-Inputs'!$C$31 -> 296306.72 | D30: =C30*'1-Inputs'!$C$8 -> 296306.72 | E30: MJ/j | F30: PCI corrige a 37,3 MJ/kg
A31: T4.2 | B31: Energie du gaz issu de l'organique | C31: =C27*'1-Inputs'!$C$32 -> 219890.44 | D31: =C31*'1-Inputs'!$C$8 -> 219890.44 | E31: MJ/j | F31: PCI corrige a 11,0 MJ/kg
A32: T4.3 | B32: Energie totale du gaz de procede | C32: =C30+C31 -> 516197.16 | D32: =C32*'1-Inputs'!$C$8 -> 516197.16 | E32: MJ/j
A33: T4.4 | B33: Chaleur utile delivree par le bruleur | C33: =C32*'1-Inputs'!$C$34 -> 438767.59 | D33: =C33*'1-Inputs'!$C$8 -> 438767.59 | E33: MJ/j | F33: Rendement bruleur 85%
A34: T4.5 | B34: Besoin thermique | C34: =C6*'1-Inputs'!$C$33 -> 379960 | D34: =C34*'1-Inputs'!$C$8 -> 379960 | E34: MJ/j | F34: Recoupement : bruleur de 833 kcal/s soit 301 190 MJ/j
A35: T4.6 | B35: Taux de couverture par le gaz | C35: =C33/C34 -> 1.1547731 | D35: =C35*'1-Inputs'!$C$8 -> 1.1547731 | E35: % | F35: Superieur a 100% : autonomie energetique
A36: T4.7 | B36: Deficit thermique eventuel | C36: =MAX(0,C34-C33) -> 0 | D36: =C36*'1-Inputs'!$C$8 -> 0 | E36: MJ/j
A37: T4.8 | B37: Fioul de secours | C37: =(C36+'1-Inputs'!$C$35*C34)/'1-Inputs'!$C$36/'1-Inputs'!$C$34 -> 588.17337 | D37: =C37*'1-Inputs'!$C$8 -> 588.17337 | E37: L/j | F37: Deficit eventuel plus la provision de securite de 5%
A38: T4.9 | B38: Excedent de gaz non utilise | C38: =MAX(0,C33-C34) -> 58807.589 | D38: =C38*'1-Inputs'!$C$8 -> 58807.589 | E38: MJ/j | F38: Valorisable en vapeur ou en electricite. Non valorise dans ce modele
A39: T4.10 | B39: Teneur en plastique a l'equilibre energetique | E39: % | F39: Non calcule dans ce fichier
A41: T5 — SORTIES COMMERCIALISABLES
A42: T5.1 | B42: Huile vendue | C42: =C21*'1-Inputs'!$C$9/1000+C10*'1-Inputs'!$C$17*'1-Inputs'!$C$9/1000*'1-Inputs'!$C$122*'1-Inputs'!$C$123*'1-Inputs'!$C$124 -> 9414.9178 | D42: =C42*'1-Inputs'!$C$8 -> 9414.9178 | E42: T/an | F42: Production du reacteur plus l'huile issue du recyclage de la phase organique decantee (lignes T5.8c a T5.8e)
A43: T5.2 | B43: Char commercialisable | C43: =(C25+C24)*'1-Inputs'!$C$180*'1-Inputs'!$C$9/1000 -> 13672.616 | D43: =C43*'1-Inputs'!$C$8 -> 13672.616 | E43: T/an | F43: Char organique plus residu plastique, apres criblage a 85%
A44: T5.3 | B44: Ferreux recuperes | C44: =C15*'1-Inputs'!$C$20*('1-Inputs'!$C$177+(1-'1-Inputs'!$C$177)*'1-Inputs'!$C$181)*'1-Inputs'!$C$9/1000 -> 1774.8192 | D44: =C44*'1-Inputs'!$C$8 -> 1774.8192 | E44: T/an | F44: V5. Pre-tri, puis recuperation dans le char de ce qui a echappe au pre-tri (reprise du V3)
A45: T5.4 | B45: Aluminium recupere | C45: =C15*'1-Inputs'!$C$21*('1-Inputs'!$C$178+(1-'1-Inputs'!$C$178)*'1-Inputs'!$C$181)*'1-Inputs'!$C$9/1000 -> 322.5915 | D45: =C45*'1-Inputs'!$C$8 -> 322.5915 | E45: T/an | F45: V5. Idem
...

Sheet 3-CAPEX
A1: INVESTISSEMENT
A4: Ref | B4: Poste | C4: Montant (EUR) | D4: % total | E4: Commentaire
A5: EQUIPEMENT
A6: 1 | B6: Machine URC-2000 | C6: ='1-Inputs'!$C$128*'1-Inputs'!$C$8 -> 50000000 | D6: =C6/$C$31 -> 0.78052131 | E6: x N
A7: 2 | B7: Installation et mise en service | C7: ='1-Inputs'!$C$129*'1-Inputs'!$C$8 -> 200000 | D7: =C7/$C$31 -> 0.0031220852 | E7: x N
A8: 3 | B8: Fret | C8: ='1-Inputs'!$C$130*'1-Inputs'!$C$8 -> 400000 | D8: =C8/$C$31 -> 0.0062441705 | E8: x N
A9: 4 | B9: Formation | C9: ='1-Inputs'!$C$131*'1-Inputs'!$C$8 -> 300000 | D9: =C9/$C$31 -> 0.0046831279 | E9: x N
A10: 5 | B10: Accessoires et pieces | C10: ='1-Inputs'!$C$132*'1-Inputs'!$C$8 -> 2000000 | D10: =C10/$C$31 -> 0.031220852 | E10: x N
A11: 6 | B11: Ligne de pre-tri | C11: ='1-Inputs'!$C$148*'1-Inputs'!$C$8*'1-Inputs'!$C$173 -> 1080000 | D11: =C11/$C$31 -> 0.01685926 | E11: x N x interrupteur pre-tri (K2)
A12: 7 | B12: Ligne de post-tri | C12: ='1-Inputs'!$C$149*'1-Inputs'!$C$8*'1-Inputs'!$C$174 -> 430000 | D12: =C12/$C$31 -> 0.0067124833 | E12: x N x interrupteur post-tri (K3)
A13: 8 | B13: ATEX et depoussierage | C13: ='1-Inputs'!$C$150*'1-Inputs'!$C$8 -> 650000 | D13: =C13/$C$31 -> 0.010146777 | E13: x N. Un systeme par reacteur
A14: 8b | B14: Cuve de neutralisation et de decantation | C14: =250000*'1-Inputs'!$C$8 -> 250000 | D14: =C14/$C$31 -> 0.0039026066 | E14: Equipement de procede, donc soumis a maintenance. Lit de pellets de calcaire puis decantation. Ordre de grandeur, a chiffrer sur devis
B15: Sous-total equipement | C15: =SUM(C5:C14) -> 55310000 | D15: =C15/$C$31 -> 0.86341267
A17: GENIE CIVIL ET ETUDES
A18: 9a | B18: Usine de traitement — surface | C18: =MAX(2600,'1-Inputs'!$C$133+'1-Inputs'!$C$134*('1-Inputs'!$C$8-1))*'1-Inputs'!$C$8 -> 3000 | E18: Plans UR2000-JP : 3 000 m2 a N=1, 14 230 m2 a N=5
A19: 9b | B19: Usine de traitement | C19: =C18*'1-Inputs'!$C$135 -> 2700000 | D19: =C19/$C$31 -> 0.042148151 | E19: 900 EUR/m2
A20: 9c | B20: Stockage dechets — surface | C20: =('1-Inputs'!$C$136+'1-Inputs'!$C$137*('1-Inputs'!$C$8-1))*'1-Inputs'!$C$8 -> 640 | E20: 640 m2 a N=1, 3 450 m2 a N=5
A21: 9d | B21: Stockage dechets | C21: =C20*'1-Inputs'!$C$138 -> 320000 | D21: =C21/$C$31 -> 0.0049953364 | E21: 500 EUR/m2
A22: 9e | B22: Stockage produits — surface | C22: =MAX(600,'1-Inputs'!$C$139+'1-Inputs'!$C$140*('1-Inputs'!$C$8-1))*'1-Inputs'!$C$8 -> 810 | E22: 810 m2 a N=1, 3 450 m2 a N=5
A23: 9f | B23: Stockage produits | C23: =C22*'1-Inputs'!$C$141 -> 405000 | D23: =C23/$C$31 -> 0.0063222226 | E23: 500 EUR/m2
A24: 9g | B24: Bureaux et locaux — surface | C24: =MAX(64,'1-Inputs'!$C$142+'1-Inputs'!$C$143*('1-Inputs'!$C$8-1))*'1-Inputs'!$C$8 -> 200 | E24: 200 m2 a N=1, 640 m2 a N=5
A25: 9h | B25: Bureaux et locaux | C25: =C24*'1-Inputs'!$C$144 -> 260000 | D25: =C25/$C$31 -> 0.0040587108 | E25: 1 300 EUR/m2
A26: 9i | B26: Surface batie totale | C26: =C18+C20+C22+C24 -> 4650 | E26: Recoupement plans : 4 650 m2 a N=1, 21 770 m2 a N=5
A27: 10 | B27: VRD, fondations, raccordements | C27: ='1-Inputs'!$C$145+'1-Inputs'!$C$146*('1-Inputs'!$C$8-1) -> 1300000 | D27: =C27/$C$31 -> 0.020293554 | E27: AJOUTE. N'etait pas distingue du batiment dans le V3
A28: 10b | B28: Sous-total genie civil | C28: =C19+C21+C23+C25+C27 -> 4985000 | D28: =C28/$C$31 -> 0.077817975 | E28: A comparer aux 5,0 MEUR forfaitaires du V3
A29: 11 | B29: Ingenierie, ICPE, MOE | C29: ='1-Inputs'!$C$151*(1+'1-Inputs'!$C$152*('1-Inputs'!$C$8-1)) -> 750000 | D29: =C29/$C$31 -> 0.01170782
A30: 12 | B30: Aleas | C30: ='1-Inputs'!$C$153*(C15+C28) -> 3014750 | D30: =C30/$C$31 -> 0.047061532 | E30: 5% de l'equipement et du genie civil
B31: TOTAL CAPEX | C31: =C15+C28+C29+C30 -> 64059750 | D31: =C31/$C$31 -> 1
B33: Emprise fonciere indicative | C33: =C26*1.28 -> 5952 | E33: Ratio emprise sur surface batie tire des plans : 28 900 / 21 770 a N=5, 5 265 / 4 650 a N=1
B34: CAPEX par tonne annuelle | C34: =C31/'2-Production'!D7 -> 1386.5747
B35: Dette | C35: =C31*'1-Inputs'!$C$156 -> 44841825
B36: Fonds propres | C36: =C31-C35 -> 19217925
B37: Amortissement annuel | C37: =C31/'1-Inputs'!$C$160 -> 4270650

Sheet 4-PL
A1: COMPTE DE RESULTAT ET TRESORERIE — 15 ANS
A2: Toutes les lignes suivent le nombre d'unites saisi a l'onglet 1-Inputs.
C4: Annee 1 | D4: Annee 2 | E4: Annee 3 | F4: Annee 4 | G4: Annee 5 | H4: Annee 6 | I4: Annee 7 | J4: Annee 8 | K4: Annee 9 | L4: Annee 10 | M4: Annee 11 | N4: Annee 12 | O4: Annee 13 | P4: Annee 14 | Q4: Annee 15
B5: Taux de charge | C5: =IF(1=1,'1-Inputs'!$C$162,IF(1=2,'1-Inputs'!$C$163,1)) -> 0.7 | D5: =IF(2=1,'1-Inputs'!$C$162,IF(2=2,'1-Inputs'!$C$163,1)) -> 0.85 | E5: =IF(3=1,'1-Inputs'!$C$162,IF(3=2,'1-Inputs'!$C$163,1)) -> 1 | F5: =IF(4=1,'1-Inputs'!$C$162,IF(4=2,'1-Inputs'!$C$163,1)) -> 1 | G5: =IF(5=1,'1-Inputs'!$C$162,IF(5=2,'1-Inputs'!$C$163,1)) -> 1 | H5: =IF(6=1,'1-Inputs'!$C$162,IF(6=2,'1-Inputs'!$C$163,1)) -> 1 | I5: =IF(7=1,'1-Inputs'!$C$162,IF(7=2,'1-Inputs'!$C$163,1)) -> 1 | J5: =IF(8=1,'1-Inputs'!$C$162,IF(8=2,'1-Inputs'!$C$163,1)) -> 1 | K5: =IF(9=1,'1-Inputs'!$C$162,IF(9=2,'1-Inputs'!$C$163,1)) -> 1 | L5: =IF(10=1,'1-Inputs'!$C$162,IF(10=2,'1-Inputs'!$C$163,1)) -> 1 | M5: =IF(11=1,'1-Inputs'!$C$162,IF(11=2,'1-Inputs'!$C$163,1)) -> 1 | N5: =IF(12=1,'1-Inputs'!$C$162,IF(12=2,'1-Inputs'!$C$163,1)) -> 1 | O5: =IF(13=1,'1-Inputs'!$C$162,IF(13=2,'1-Inputs'!$C$163,1)) -> 1 | P5: =IF(14=1,'1-Inputs'!$C$162,IF(14=2,'1-Inputs'!$C$163,1)) -> 1 | Q5: =IF(15=1,'1-Inputs'!$C$162,IF(15=2,'1-Inputs'!$C$163,1)) -> 1
B6: Tonnage traite (T) | C6: ='2-Production'!D7*C5 -> 32340 | D6: ='2-Production'!D7*D5 -> 39270 | E6: ='2-Production'!D7*E5 -> 46200 | F6: ='2-Production'!D7*F5 -> 46200 | G6: ='2-Production'!D7*G5 -> 46200 | H6: ='2-Production'!D7*H5 -> 46200 | I6: ='2-Production'!D7*I5 -> 46200 | J6: ='2-Production'!D7*J5 -> 46200 | K6: ='2-Production'!D7*K5 -> 46200 | L6: ='2-Production'!D7*L5 -> 46200 | M6: ='2-Production'!D7*M5 -> 46200 | N6: ='2-Production'!D7*N5 -> 46200 | O6: ='2-Production'!D7*O5 -> 46200 | P6: ='2-Production'!D7*P5 -> 46200 | Q6: ='2-Production'!D7*Q5 -> 46200
A8: RECETTES
B9: Gate fees | C9: =C6*'1-Inputs'!$C$65*(1+'1-Inputs'!$C$161)^0 -> 3557400 | D9: =D6*'1-Inputs'!$C$65*(1+'1-Inputs'!$C$161)^1 -> 4406094 | E9: =E6*'1-Inputs'!$C$65*(1+'1-Inputs'!$C$161)^2 -> 5287312.8 | F9: =F6*'1-Inputs'!$C$65*(1+'1-Inputs'!$C$161)^3 -> 5393059.1 | G9: =G6*'1-Inputs'!$C$65*(1+'1-Inputs'!$C$161)^4 -> 5500920.2 | H9: =H6*'1-Inputs'!$C$65*(1+'1-Inputs'!$C$161)^5 -> 5610938.6 | I9: =I6*'1-Inputs'!$C$65*(1+'1-Inputs'!$C$161)^6 -> 5723157.4 | J9: =J6*'1-Inputs'!$C$65*(1+'1-Inputs'!$C$161)^7 -> 5837620.6 | K9: =K6*'1-Inputs'!$C$65*(1+'1-Inputs'!$C$161)^8 -> 5954373 | L9: =L6*'1-Inputs'!$C$65*(1+'1-Inputs'!$C$161)^9 -> 6073460.4 | M9: =M6*'1-Inputs'!$C$65*(1+'1-Inputs'!$C$161)^10 -> 6194929.6 | N9: =N6*'1-Inputs'!$C$65*(1+'1-Inputs'!$C$161)^11 -> 6318828.2 | O9: =O6*'1-Inputs'!$C$65*(1+'1-Inputs'!$C$161)^12 -> 6445204.8 | P9: =P6*'1-Inputs'!$C$65*(1+'1-Inputs'!$C$161)^13 -> 6574108.9 | Q9: =Q6*'1-Inputs'!$C$65*(1+'1-Inputs'!$C$161)^14 -> 6705591.1
B10: Huile | C10: ='2-Production'!D42*C5*'1-Inputs'!$C$79*(1+'1-Inputs'!$C$161)^0 -> 4224473.6 | D10: ='2-Production'!D42*D5*'1-Inputs'!$C$79*(1+'1-Inputs'!$C$161)^1 -> 5232312.3 | E10: ='2-Production'!D42*E5*'1-Inputs'!$C$79*(1+'1-Inputs'!$C$161)^2 -> 6278774.8 | F10: ='2-Production'!D42*F5*'1-Inputs'!$C$79*(1+'1-Inputs'!$C$161)^3 -> 6404350.3 | G10: ='2-Production'!D42*G5*'1-Inputs'!$C$79*(1+'1-Inputs'!$C$161)^4 -> 6532437.3 | H10: ='2-Production'!D42*H5*'1-Inputs'!$C$79*(1+'1-Inputs'!$C$161)^5 -> 6663086 | I10: ='2-Production'!D42*I5*'1-Inputs'!$C$79*(1+'1-Inputs'!$C$161)^6 -> 6796347.8 | J10: ='2-Production'!D42*J5*'1-Inputs'!$C$79*(1+'1-Inputs'!$C$161)^7 -> 6932274.7 | K10: ='2-Production'!D42*K5*'1-Inputs'!$C$79*(1+'1-Inputs'!$C$161)^8 -> 7070920.2 | L10: ='2-Production'!D42*L5*'1-Inputs'!$C$79*(1+'1-Inputs'!$C$161)^9 -> 7212338.6 | M10: ='2-Production'!D42*M5*'1-Inputs'!$C$79*(1+'1-Inputs'!$C$161)^10 -> 7356585.4 | N10: ='2-Production'!D42*N5*'1-Inputs'!$C$79*(1+'1-Inputs'!$C$161)^11 -> 7503717.1 | O10: ='2-Production'!D42*O5*'1-Inputs'!$C$79*(1+'1-Inputs'!$C$161)^12 -> 7653791.4 | P10: ='2-Production'!D42*P5*'1-Inputs'!$C$79*(1+'1-Inputs'!$C$161)^13 -> 7806867.3 | Q10: ='2-Production'!D42*Q5*'1-Inputs'!$C$79*(1+'1-Inputs'!$C$161)^14 -> 7963004.6
B11: Char | C11: ='2-Production'!D43*C5*'1-Inputs'!$C$80*(1+'1-Inputs'!$C$161)^0 -> 957083.14 | D11: ='2-Production'!D43*D5*'1-Inputs'!$C$80*(1+'1-Inputs'!$C$161)^1 -> 1185415.8 | E11: ='2-Production'!D43*E5*'1-Inputs'!$C$80*(1+'1-Inputs'!$C$161)^2 -> 1422499 | F11: ='2-Production'!D43*F5*'1-Inputs'!$C$80*(1+'1-Inputs'!$C$161)^3 -> 1450949 | G11: ='2-Production'!D43*G5*'1-Inputs'!$C$80*(1+'1-Inputs'!$C$161)^4 -> 1479968 | H11: ='2-Production'!D43*H5*'1-Inputs'!$C$80*(1+'1-Inputs'!$C$161)^5 -> 1509567.3 | I11: ='2-Production'!D43*I5*'1-Inputs'!$C$80*(1+'1-Inputs'!$C$161)^6 -> 1539758.7 | J11: ='2-Production'!D43*J5*'1-Inputs'!$C$80*(1+'1-Inputs'!$C$161)^7 -> 1570553.8 | K11: ='2-Production'!D43*K5*'1-Inputs'!$C$80*(1+'1-Inputs'!$C$161)^8 -> 1601964.9 | L11: ='2-Production'!D43*L5*'1-Inputs'!$C$80*(1+'1-Inputs'!$C$161)^9 -> 1634004.2 | M11: ='2-Production'!D43*M5*'1-Inputs'!$C$80*(1+'1-Inputs'!$C$161)^10 -> 1666684.3 | N11: ='2-Production'!D43*N5*'1-Inputs'!$C$80*(1+'1-Inputs'!$C$161)^11 -> 1700018 | O11: ='2-Production'!D43*O5*'1-Inputs'!$C$80*(1+'1-Inputs'!$C$161)^12 -> 1734018.3 | P11: ='2-Production'!D43*P5*'1-Inputs'!$C$80*(1+'1-Inputs'!$C$161)^13 -> 1768698.7 | Q11: ='2-Production'!D43*Q5*'1-Inputs'!$C$80*(1+'1-Inputs'!$C$161)^14 -> 1804072.7
B12: Metaux | C12: =('2-Production'!D44*'1-Inputs'!$C$81+'2-Production'!D45*'1-Inputs'!$C$82+'2-Production'!D46*'1-Inputs'!$C$83)*C5*(1+'1-Inputs'!$C$161)^0 -> 658426.23 | D12: =('2-Production'!D44*'1-Inputs'!$C$81+'2-Production'!D45*'1-Inputs'!$C$82+'2-Production'!D46*'1-Inputs'!$C$83)*D5*(1+'1-Inputs'!$C$161)^1 -> 815507.92 | E12: =('2-Production'!D44*'1-Inputs'!$C$81+'2-Production'!D45*'1-Inputs'!$C$82+'2-Production'!D46*'1-Inputs'!$C$83)*E5*(1+'1-Inputs'!$C$161)^2 -> 978609.5 | F12: =('2-Production'!D44*'1-Inputs'!$C$81+'2-Production'!D45*'1-Inputs'!$C$82+'2-Production'!D46*'1-Inputs'!$C$83)*F5*(1+'1-Inputs'!$C$161)^3 -> 998181.69 | G12: =('2-Production'!D44*'1-Inputs'!$C$81+'2-Production'!D45*'1-Inputs'!$C$82+'2-Production'!D46*'1-Inputs'!$C$83)*G5*(1+'1-Inputs'!$C$161)^4 -> 1018145.3 | H12: =('2-Production'!D44*'1-Inputs'!$C$81+'2-Production'!D45*'1-Inputs'!$C$82+'2-Production'!D46*'1-Inputs'!$C$83)*H5*(1+'1-Inputs'!$C$161)^5 -> 1038508.2 | I12: =('2-Production'!D44*'1-Inputs'!$C$81+'2-Production'!D45*'1-Inputs'!$C$82+'2-Production'!D46*'1-Inputs'!$C$83)*I5*(1+'1-Inputs'!$C$161)^6 -> 1059278.4 | J12: =('2-Production'!D44*'1-Inputs'!$C$81+'2-Production'!D45*'1-Inputs'!$C$82+'2-Production'!D46*'1-Inputs'!$C$83)*J5*(1+'1-Inputs'!$C$161)^7 -> 1080464 | K12: =('2-Production'!D44*'1-Inputs'!$C$81+'2-Production'!D45*'1-Inputs'!$C$82+'2-Production'!D46*'1-Inputs'!$C$83)*K5*(1+'1-Inputs'!$C$161)^8 -> 1102073.2 | L12: =('2-Production'!D44*'1-Inputs'!$C$81+'2-Production'!D45*'1-Inputs'!$C$82+'2-Production'!D46*'1-Inputs'!$C$83)*L5*(1+'1-Inputs'!$C$161)^9 -> 1124114.7 | M12: =('2-Production'!D44*'1-Inputs'!$C$81+'2-Production'!D45*'1-Inputs'!$C$82+'2-Production'!D46*'1-Inputs'!$C$83)*M5*(1+'1-Inputs'!$C$161)^10 -> 1146597 | N12: =('2-Production'!D44*'1-Inputs'!$C$81+'2-Production'!D45*'1-Inputs'!$C$82+'2-Production'!D46*'1-Inputs'!$C$83)*N5*(1+'1-Inputs'!$C$161)^11 -> 1169528.9 | O12: =('2-Production'!D44*'1-Inputs'!$C$81+'2-Production'!D45*'1-Inputs'!$C$82+'2-Production'!D46*'1-Inputs'!$C$83)*O5*(1+'1-Inputs'!$C$161)^12 -> 1192919.5 | P12: =('2-Production'!D44*'1-Inputs'!$C$81+'2-Production'!D45*'1-Inputs'!$C$82+'2-Production'!D46*'1-Inputs'!$C$83)*P5*(1+'1-Inputs'!$C$161)^13 -> 1216777.9 | Q12: =('2-Production'!D44*'1-Inputs'!$C$81+'2-Production'!D45*'1-Inputs'!$C$82+'2-Production'!D46*'1-Inputs'!$C$83)*Q5*(1+'1-Inputs'!$C$161)^14 -> 1241113.5
B13: Verre et recyclables du pre-tri | C13: =('2-Production'!D48*'1-Inputs'!$C$84+'2-Production'!D92*'1-Inputs'!$C$185+'2-Production'!D93*'1-Inputs'!$C$187)*C5*(1+'1-Inputs'!$C$161)^0 -> 36605.646 | D13: =('2-Production'!D48*'1-Inputs'!$C$84+'2-Production'!D92*'1-Inputs'!$C$185+'2-Production'!D93*'1-Inputs'!$C$187)*D5*(1+'1-Inputs'!$C$161)^1 -> 45338.707 | E13: =('2-Production'!D48*'1-Inputs'!$C$84+'2-Production'!D92*'1-Inputs'!$C$185+'2-Production'!D93*'1-Inputs'!$C$187)*E5*(1+'1-Inputs'!$C$161)^2 -> 54406.449 | F13: =('2-Production'!D48*'1-Inputs'!$C$84+'2-Production'!D92*'1-Inputs'!$C$185+'2-Production'!D93*'1-Inputs'!$C$187)*F5*(1+'1-Inputs'!$C$161)^3 -> 55494.578 | G13: =('2-Production'!D48*'1-Inputs'!$C$84+'2-Production'!D92*'1-Inputs'!$C$185+'2-Production'!D93*'1-Inputs'!$C$187)*G5*(1+'1-Inputs'!$C$161)^4 -> 56604.469 | H13: =('2-Production'!D48*'1-Inputs'!$C$84+'2-Production'!D92*'1-Inputs'!$C$185+'2-Production'!D93*'1-Inputs'!$C$187)*H5*(1+'1-Inputs'!$C$161)^5 -> 57736.559 | I13: =('2-Production'!D48*'1-Inputs'!$C$84+'2-Production'!D92*'1-Inputs'!$C$185+'2-Production'!D93*'1-Inputs'!$C$187)*I5*(1+'1-Inputs'!$C$161)^6 -> 58891.29 | J13: =('2-Production'!D48*'1-Inputs'!$C$84+'2-Production'!D92*'1-Inputs'!$C$185+'2-Production'!D93*'1-Inputs'!$C$187)*J5*(1+'1-Inputs'!$C$161)^7 -> 60069.116 | K13: =('2-Production'!D48*'1-Inputs'!$C$84+'2-Production'!D92*'1-Inputs'!$C$185+'2-Production'!D93*'1-Inputs'!$C$187)*K5*(1+'1-Inputs'!$C$161)^8 -> 61270.498 | L13: =('2-Production'!D48*'1-Inputs'!$C$84+'2-Production'!D92*'1-Inputs'!$C$185+'2-Production'!D93*'1-Inputs'!$C$187)*L5*(1+'1-Inputs'!$C$161)^9 -> 62495.908 | M13: =('2-Production'!D48*'1-Inputs'!$C$84+'2-Production'!D92*'1-Inputs'!$C$185+'2-Production'!D93*'1-Inputs'!$C$187)*M5*(1+'1-Inputs'!$C$161)^10 -> 63745.826 | N13: =('2-Production'!D48*'1-Inputs'!$C$84+'2-Production'!D92*'1-Inputs'!$C$185+'2-Production'!D93*'1-Inputs'!$C$187)*N5*(1+'1-Inputs'!$C$161)^11 -> 65020.743 | O13: =('2-Production'!D48*'1-Inputs'!$C$84+'2-Production'!D92*'1-Inputs'!$C$185+'2-Production'!D93*'1-Inputs'!$C$187)*O5*(1+'1-Inputs'!$C$161)^12 -> 66321.157 | P13: =('2-Production'!D48*'1-Inputs'!$C$84+'2-Production'!D92*'1-Inputs'!$C$185+'2-Production'!D93*'1-Inputs'!$C$187)*P5*(1+'1-Inputs'!$C$161)^13 -> 67647.581 | Q13: =('2-Production'!D48*'1-Inputs'!$C$84+'2-Production'!D92*'1-Inputs'!$C$185+'2-Production'!D93*'1-Inputs'!$C$187)*Q5*(1+'1-Inputs'!$C$161)^14 -> 69000.532
B14: Credits carbone | C14: ='2-Production'!D89*C5*'1-Inputs'!$C$92*'1-Inputs'!$C$90*(1+'1-Inputs'!$C$161)^0 -> 0 | D14: ='2-Production'!D89*D5*'1-Inputs'!$C$92*'1-Inputs'!$C$90*(1+'1-Inputs'!$C$161)^1 -> 0 | E14: ='2-Production'!D89*E5*'1-Inputs'!$C$92*'1-Inputs'!$C$90*(1+'1-Inputs'!$C$161)^2 -> 0 | F14: ='2-Production'!D89*F5*'1-Inputs'!$C$92*'1-Inputs'!$C$90*(1+'1-Inputs'!$C$161)^3 -> 0 | G14: ='2-Production'!D89*G5*'1-Inputs'!$C$92*'1-Inputs'!$C$90*(1+'1-Inputs'!$C$161)^4 -> 0 | H14: ='2-Production'!D89*H5*'1-Inputs'!$C$92*'1-Inputs'!$C$90*(1+'1-Inputs'!$C$161)^5 -> 0 | I14: ='2-Production'!D89*I5*'1-Inputs'!$C$92*'1-Inputs'!$C$90*(1+'1-Inputs'!$C$161)^6 -> 0 | J14: ='2-Production'!D89*J5*'1-Inputs'!$C$92*'1-Inputs'!$C$90*(1+'1-Inputs'!$C$161)^7 -> 0 | K14: ='2-Production'!D89*K5*'1-Inputs'!$C$92*'1-Inputs'!$C$90*(1+'1-Inputs'!$C$161)^8 -> 0 | L14: ='2-Production'!D89*L5*'1-Inputs'!$C$92*'1-Inputs'!$C$90*(1+'1-Inputs'!$C$161)^9 -> 0 | M14: ='2-Production'!D89*M5*'1-Inputs'!$C$92*'1-Inputs'!$C$90*(1+'1-Inputs'!$C$161)^10 -> 0 | N14: ='2-Production'!D89*N5*'1-Inputs'!$C$92*'1-Inputs'!$C$90*(1+'1-Inputs'!$C$161)^11 -> 0 | O14: ='2-Production'!D89*O5*'1-Inputs'!$C$92*'1-Inputs'!$C$90*(1+'1-Inputs'!$C$161)^12 -> 0 | P14: ='2-Production'!D89*P5*'1-Inputs'!$C$92*'1-Inputs'!$C$90*(1+'1-Inputs'!$C$161)^13 -> 0 | Q14: ='2-Production'!D89*Q5*'1-Inputs'!$C$92*'1-Inputs'!$C$90*(1+'1-Inputs'!$C$161)^14 -> 0
B15: TOTAL RECETTES | C15: =SUM(C9:C14) -> 9433988.6 | D15: =SUM(D9:D14) -> 11684669 | E15: =SUM(E9:E14) -> 14021603 | F15: =SUM(F9:F14) -> 14302035 | G15: =SUM(G9:G14) -> 14588075 | H15: =SUM(H9:H14) -> 14879837 | I15: =SUM(I9:I14) -> 15177434 | J15: =SUM(J9:J14) -> 15480982 | ... Q15: =SUM(Q9:Q14) -> 17782782
A17: CHARGES
B18: Personnel | C18: =('1-Inputs'!$C$104+'1-Inputs'!$C$105*('1-Inputs'!$C$8-1)+'1-Inputs'!$C$106*'1-Inputs'!$C$8)*'1-Inputs'!$C$107*C5*(1+'1-Inputs'!$C$161)^0 -> 862400 | D18: =('1-Inputs'!$C$104+'1-Inputs'!$C$105*('1-Inputs'!$C$8-1)+'1-Inputs'!$C$106*'1-Inputs'!$C$8)*'1-Inputs'!$C$107*D5*(1+'1-Inputs'!$C$161)^1 -> 1068144 | E18: =('1-Inputs'!$C$104+'1-Inputs'!$C$105*('1-Inputs'!$C$8-1)+'1-Inputs'!$C$106*'1-Inputs'!$C$8)*'1-Inputs'!$C$107*E5*(1+'1-Inputs'!$C$161)^2 -> 1281772.8 | F18: =('1-Inputs'!$C$104+'1-Inputs'!$C$105*('1-Inputs'!$C$8-1)+'1-Inputs'!$C$106*'1-Inputs'!$C$8)*'1-Inputs'!$C$107*F5*(1+'1-Inputs'!$C$161)^3 -> 1307408.3 | G18: =('1-Inputs'!$C$104+'1-Inputs'!$C$105*('1-Inputs'!$C$8-1)+'1-Inputs'!$C$106*'1-Inputs'!$C$8)*'1-Inputs'!$C$107*G5*(1+'1-Inputs'!$C$161)^4 -> 1333556.4 | H18: =('1-Inputs'!$C$104+'1-Inputs'!$C$105*('1-Inputs'!$C$8-1)+'1-Inputs'!$C$106*'1-Inputs'!$C$8)*'1-Inputs'!$C$107*H5*(1+'1-Inputs'!$C$161)^5 -> 1360227.5 | I18: =('1-Inputs'!$C$104+'1-Inputs'!$C$105*('1-Inputs'!$C$8-1)+'1-Inputs'!$C$106*'1-Inputs'!$C$8)*'1-Inputs'!$C$107*I5*(1+'1-Inputs'!$C$161)^6 -> 1387432.1 | J18: =('1-Inputs'!$C$104+'1-Inputs'!$C$105*('1-Inputs'!$C$8-1)+'1-Inputs'!$C$106*'1-Inputs'!$C$8)*'1-Inputs'!$C$107*J5*(1+'1-Inputs'!$C$161)^7 -> 1415180.7 | K18: =('1-Inputs'!$C$104+'1-Inputs'!$C$105*('1-Inputs'!$C$8-1)+'1-Inputs'!$C$106*'1-Inputs'!$C$8)*'1-Inputs'!$C$107*K5*(1+'1-Inputs'!$C$161)^8 -> 1443484.4 | L18: =('1-Inputs'!$C$104+'1-Inputs'!$C$105*('1-Inputs'!$C$8-1)+'1-Inputs'!$C$106*'1-Inputs'!$C$8)*'1-Inputs'!$C$107*L5*(1+'1-Inputs'!$C$161)^9 -> 1472354 | M18: =('1-Inputs'!$C$104+'1-Inputs'!$C$105*('1-Inputs'!$C$8-1)+'1-Inputs'!$C$106*'1-Inputs'!$C$8)*'1-Inputs'!$C$107*M5*(1+'1-Inputs'!$C$161)^10 -> 1501801.1 | N18: =('1-Inputs'!$C$104+'1-Inputs'!$C$105*('1-Inputs'!$C$8-1)+'1-Inputs'!$C$106*'1-Inputs'!$C$8)*'1-Inputs'!$C$107*N5*(1+'1-Inputs'!$C$161)^11 -> 1531837.1 | O18: =('1-Inputs'!$C$104+'1-Inputs'!$C$105*('1-Inputs'!$C$8-1)+'1-Inputs'!$C$106*'1-Inputs'!$C$8)*'1-Inputs'!$C$107*O5*(1+'1-Inputs'!$C$161)^12 -> 1562473.9 | P18: =('1-Inputs'!$C$104+'1-Inputs'!$C$105*('1-Inputs'!$C$8-1)+'1-Inputs'!$C$106*'1-Inputs'!$C$8)*'1-Inputs'!$C$107*P5*(1+'1-Inputs'!$C$161)^13 -> 1593723.4 | Q18: =('1-Inputs'!$C$104+'1-Inputs'!$C$105*('1-Inputs'!$C$8-1)+'1-Inputs'!$C$106*'1-Inputs'!$C$8)*'1-Inputs'!$C$107*Q5*(1+'1-Inputs'!$C$161)^14 -> 1625597.8
B19: Taux de maintenance applique | C19: =IF(1<='1-Inputs'!$C$110,'1-Inputs'!$C$108,IF(1>='1-Inputs'!$C$111,'1-Inputs'!$C$109,'1-Inputs'!$C$108+('1-Inputs'!$C$109-'1-Inputs'!$C$108)*(1-'1-Inputs'!$C$110)/('1-Inputs'!$C$111-'1-Inputs'!$C$110))) -> 0.01 | D19: =IF(2<='1-Inputs'!$C$110,'1-Inputs'!$C$108,IF(2>='1-Inputs'!$C$111,'1-Inputs'!$C$109,'1-Inputs'!$C$108+('1-Inputs'!$C$109-'1-Inputs'!$C$108)*(2-'1-Inputs'!$C$110)/('1-Inputs'!$C$111-'1-Inputs'!$C$110))) -> 0.01 | E19: =IF(3<='1-Inputs'!$C$110,'1-Inputs'!$C$108,IF(3>='1-Inputs'!$C$111,'1-Inputs'!$C$109,'1-Inputs'!$C$108+('1-Inputs'!$C$109-'1-Inputs'!$C$108)*(3-'1-Inputs'!$C$110)/('1-Inputs'!$C$111-'1-Inputs'!$C$110))) -> 0.01 | F19: =IF(4<='1-Inputs'!$C$110,'1-Inputs'!$C$108,IF(4>='1-Inputs'!$C$111,'1-Inputs'!$C$109,'1-Inputs'!$C$108+('1-Inputs'!$C$109-'1-Inputs'!$C$108)*(4-'1-Inputs'!$C$110)/('1-Inputs'!$C$111-'1-Inputs'!$C$110))) -> 0.01 | G19: =IF(5<='1-Inputs'!$C$110,'1-Inputs'!$C$108,IF(5>='1-Inputs'!$C$111,'1-Inputs'!$C$109,'1-Inputs'!$C$108+('1-Inputs'!$C$109-'1-Inputs'!$C$108)*(5-'1-Inputs'!$C$110)/('1-Inputs'!$C$111-'1-Inputs'!$C$110))) -> 0.015 | H19: =IF(6<='1-Inputs'!$C$110,'1-Inputs'!$C$108,IF(6>='1-Inputs'!$C$111,'1-Inputs'!$C$109,'1-Inputs'!$C$108+('1-Inputs'!$C$109-'1-Inputs'!$C$108)*(6-'1-Inputs'!$C$110)/('1-Inputs'!$C$111-'1-Inputs'!$C$110))) -> 0.02 | I19: =IF(7<='1-Inputs'!$C$110,'1-Inputs'!$C$108,IF(7>='1-Inputs'!$C$111,'1-Inputs'!$C$109,'1-Inputs'!$C$108+('1-Inputs'!$C$109-'1-Inputs'!$C$108)*(7-'1-Inputs'!$C$110)/('1-Inputs'!$C$111-'1-Inputs'!$C$110))) -> 0.025 | J19: =IF(8<='1-Inputs'!$C$110,'1-Inputs'!$C$108,IF(8>='1-Inputs'!$C$111,'1-Inputs'!$C$109,'1-Inputs'!$C$108+('1-Inputs'!$C$109-'1-Inputs'!$C$108)*(8-'1-Inputs'!$C$110)/('1-Inputs'!$C$111-'1-Inputs'!$C$110))) -> 0.03 | K19: =IF(9<='1-Inputs'!$C$110,'1-Inputs'!$C$108,IF(9>='1-Inputs'!$C$111,'1-Inputs'!$C$109,'1-Inputs'!$C$108+('1-Inputs'!$C$109-'1-Inputs'!$C$108)*(9-'1-Inputs'!$C$110)/('1-Inputs'!$C$111-'1-Inputs'!$C$110))) -> 0.035 | L19: =IF(10<='1-Inputs'!$C$110,'1-Inputs'!$C$108,IF(10>='1-Inputs'!$C$111,'1-Inputs'!$C$109,'1-Inputs'!$C$108+('1-Inputs'!$C$109-'1-Inputs'!$C$108)*(10-'1-Inputs'!$C$110)/('1-Inputs'!$C$111-'1-Inputs'!$C$110))) -> 0.04 | M19: =IF(11<='1-Inputs'!$C$110,'1-Inputs'!$C$108,IF(11>='1-Inputs'!$C$111,'1-Inputs'!$C$109,'1-Inputs'!$C$108+('1-Inputs'!$C$109-'1-Inputs'!$C$108)*(11-'1-Inputs'!$C$110)/('1-Inputs'!$C$111-'1-Inputs'!$C$110))) -> 0.04 | N19: =IF(12<='1-Inputs'!$C$110,'1-Inputs'!$C$108,IF(12>='1-Inputs'!$C$111,'1-Inputs'!$C$109,'1-Inputs'!$C$108+('1-Inputs'!$C$109-'1-Inputs'!$C$108)*(12-'1-Inputs'!$C$110)/('1-Inputs'!$C$111-'1-Inputs'!$C$110))) -> 0.04 | O19: =IF(13<='1-Inputs'!$C$110,'1-Inputs'!$C$108,IF(13>='1-Inputs'!$C$111,'1-Inputs'!$C$109,'1-Inputs'!$C$108+('1-Inputs'!$C$109-'1-Inputs'!$C$108)*(13-'1-Inputs'!$C$110)/('1-Inputs'!$C$111-'1-Inputs'!$C$110))) -> 0.04 | P19: =IF(14<='1-Inputs'!$C$110,'1-Inputs'!$C$108,IF(14>='1-Inputs'!$C$111,'1-Inputs'!$C$109,'1-Inputs'!$C$108+('1-Inputs'!$C$109-'1-Inputs'!$C$108)*(14-'1-Inputs'!$C$110)/('1-Inputs'!$C$111-'1-Inputs'!$C$110))) -> 0.04 | Q19: =IF(15<='1-Inputs'!$C$110,'1-Inputs'!$C$108,IF(15>='1-Inputs'!$C$111,'1-Inputs'!$C$109,'1-Inputs'!$C$108+('1-Inputs'!$C$109-'1-Inputs'!$C$108)*(15-'1-Inputs'!$C$110)/('1-Inputs'!$C$111-'1-Inputs'!$C$110))) -> 0.04
B20: Maintenance | C20: =C19*'3-CAPEX'!$C$15*C5*(1+'1-Inputs'!$C$161)^0 -> 387170 | D20: =D19*'3-CAPEX'!$C$15*D5*(1+'1-Inputs'!$C$161)^1 -> 479537.7 | E20: =E19*'3-CAPEX'!$C$15*E5*(1+'1-Inputs'!$C$161)^2 -> 575445.24 | F20: =F19*'3-CAPEX'!$C$15*F5*(1+'1-Inputs'!$C$161)^3 -> 586954.14 | G20: =G19*'3-CAPEX'!$C$15*G5*(1+'1-Inputs'!$C$161)^4 -> 898039.84 | H20: =H19*'3-CAPEX'!$C$15*H5*(1+'1-Inputs'!$C$161)^5 -> 1221334.2 | I20: =I19*'3-CAPEX'!$C$15*I5*(1+'1-Inputs'!$C$161)^6 -> 1557201.1 | J20: =J19*'3-CAPEX'!$C$15*J5*(1+'1-Inputs'!$C$161)^7 -> 1906014.1 | K20: =K19*'3-CAPEX'!$C$15*K5*(1+'1-Inputs'!$C$161)^8 -> 2268156.8 | L20: =L19*'3-CAPEX'!$C$15*L5*(1+'1-Inputs'!$C$161)^9 -> 2644022.8 | M20: =M19*'3-CAPEX'!$C$15*M5*(1+'1-Inputs'!$C$161)^10 -> 2696903.3 | N20: =N19*'3-CAPEX'!$C$15*N5*(1+'1-Inputs'!$C$161)^11 -> 2750841.3 | O20: =O19*'3-CAPEX'!$C$15*O5*(1+'1-Inputs'!$C$161)^12 -> 2805858.1 | P20: =P19*'3-CAPEX'!$C$15*P5*(1+'1-Inputs'!$C$161)^13 -> 2861975.3 | Q20: =Q19*'3-CAPEX'!$C$15*Q5*(1+'1-Inputs'!$C$161)^14 -> 2919214.8
B21: Electricite | C21: ='1-Inputs'!$C$113*'1-Inputs'!$C$8*'1-Inputs'!$C$9*'1-Inputs'!$C$87*C5*(1+'1-Inputs'!$C$161)^0 -> 103950 | D21: ='1-Inputs'!$C$113*'1-Inputs'!$C$8*'1-Inputs'!$C$9*'1-Inputs'!$C$87*D5*(1+'1-Inputs'!$C$161)^1 -> 128749.5 | E21: ='1-Inputs'!$C$113*'1-Inputs'!$C$8*'1-Inputs'!$C$9*'1-Inputs'!$C$87*E5*(1+'1-Inputs'!$C$161)^2 -> 154499.4 | F21: ='1-Inputs'!$C$113*'1-Inputs'!$C$8*'1-Inputs'!$C$9*'1-Inputs'!$C$87*F5*(1+'1-Inputs'!$C$161)^3 -> 157589.39 | G21: ='1-Inputs'!$C$113*'1-Inputs'!$C$8*'1-Inputs'!$C$9*'1-Inputs'!$C$87*G5*(1+'1-Inputs'!$C$161)^4 -> 160741.18 | H21: ='1-Inputs'!$C$113*'1-Inputs'!$C$8*'1-Inputs'!$C$9*'1-Inputs'!$C$87*H5*(1+'1-Inputs'!$C$161)^5 -> 163956 | I21: ='1-Inputs'!$C$113*'1-Inputs'!$C$8*'1-Inputs'!$C$9*'1-Inputs'!$C$87*I5*(1+'1-Inputs'!$C$161)^6 -> 167235.12 | J21: ='1-Inputs'!$C$113*'1-Inputs'!$C$8*'1-Inputs'!$C$9*'1-Inputs'!$C$87*J5*(1+'1-Inputs'!$C$161)^7 -> 170579.82 | K21: ='1-Inputs'!$C$113*'1-Inputs'!$C$8*'1-Inputs'!$C$9*'1-Inputs'!$C$87*K5*(1+'1-Inputs'!$C$161)^8 -> 173991.42 | L21: ='1-Inputs'!$C$113*'1-Inputs'!$C$8*'1-Inputs'!$C$9*'1-Inputs'!$C$87*L5*(1+'1-Inputs'!$C$161)^9 -> 177471.25 | M21: ='1-Inputs'!$C$113*'1-Inputs'!$C$8*'1-Inputs'!$C$9*'1-Inputs'!$C$87*M5*(1+'1-Inputs'!$C$161)^10 -> 181020.67 | N21: ='1-Inputs'!$C$113*'1-Inputs'!$C$8*'1-Inputs'!$C$9*'1-Inputs'!$C$87*N5*(1+'1-Inputs'!$C$161)^11 -> 184641.08 | O21: ='1-Inputs'!$C$113*'1-Inputs'!$C$8*'1-Inputs'!$C$9*'1-Inputs'!$C$87*O5*(1+'1-Inputs'!$C$161)^12 -> 188333.91 | P21: ='1-Inputs'!$C$113*'1-Inputs'!$C$8*'1-Inputs'!$C$9*'1-Inputs'!$C$87*P5*(1+'1-Inputs'!$C$161)^13 -> 192100.58 | Q21: ='1-Inputs'!$C$113*'1-Inputs'!$C$8*'1-Inputs'!$C$9*'1-Inputs'!$C$87*Q5*(1+'1-Inputs'!$C$161)^14 -> 195942.6
B22: Fioul de secours | C22: ='2-Production'!D37*'1-Inputs'!$C$9*'1-Inputs'!$C$86*C5*(1+'1-Inputs'!$C$161)^0 -> 129074.65 | D22: ='2-Production'!D37*'1-Inputs'!$C$9*'1-Inputs'!$C$86*D5*(1+'1-Inputs'!$C$161)^1 -> 159868.17 | E22: ='2-Production'!D37*'1-Inputs'!$C$9*'1-Inputs'!$C$86*E5*(1+'1-Inputs'!$C$161)^2 -> 191841.8 | F22: ='2-Production'!D37*'1-Inputs'!$C$9*'1-Inputs'!$C$86*F5*(1+'1-Inputs'!$C$161)^3 -> 195678.64 | G22: ='2-Production'!D37*'1-Inputs'!$C$9*'1-Inputs'!$C$86*G5*(1+'1-Inputs'!$C$161)^4 -> 199592.21 | H22: ='2-Production'!D37*'1-Inputs'!$C$9*'1-Inputs'!$C$86*H5*(1+'1-Inputs'!$C$161)^5 -> 203584.06 | I22: ='2-Production'!D37*'1-Inputs'!$C$9*'1-Inputs'!$C$86*I5*(1+'1-Inputs'!$C$161)^6 -> 207655.74 | J22: ='2-Production'!D37*'1-Inputs'!$C$9*'1-Inputs'!$C$86*J5*(1+'1-Inputs'!$C$161)^7 -> 211808.85 | K22: ='2-Production'!D37*'1-Inputs'!$C$9*'1-Inputs'!$C$86*K5*(1+'1-Inputs'!$C$161)^8 -> 216045.03 | L22: ='2-Production'!D37*'1-Inputs'!$C$9*'1-Inputs'!$C$86*L5*(1+'1-Inputs'!$C$161)^9 -> 220365.93 | M22: ='2-Production'!D37*'1-Inputs'!$C$9*'1-Inputs'!$C$86*M5*(1+'1-Inputs'!$C$161)^10 -> 224773.25 | N22: ='2-Production'!D37*'1-Inputs'!$C$9*'1-Inputs'!$C$86*N5*(1+'1-Inputs'!$C$161)^11 -> 229268.71 | O22: ='2-Production'!D37*'1-Inputs'!$C$9*'1-Inputs'!$C$86*O5*(1+'1-Inputs'!$C$161)^12 -> 233854.09 | P22: ='2-Production'!D37*'1-Inputs'!$C$9*'1-Inputs'!$C$86*P5*(1+'1-Inputs'!$C$161)^13 -> 238531.17 | Q22: ='2-Production'!D37*'1-Inputs'!$C$9*'1-Inputs'!$C$86*Q5*(1+'1-Inputs'!$C$161)^14 -> 243301.79
B23: Elimination des residus | C23: ='2-Production'!D56*'1-Inputs'!$C$85*C5*(1+'1-Inputs'!$C$161)^0 -> 494920.38 | D23: ='2-Production'!D56*'1-Inputs'!$C$85*D5*(1+'1-Inputs'!$C$161)^1 -> 612994.24 | E23: ='2-Production'!D56*'1-Inputs'!$C$85*E5*(1+'1-Inputs'!$C$161)^2 -> 735593.09 | F23: ='2-Production'!D56*'1-Inputs'!$C$85*F5*(1+'1-Inputs'!$C$161)^3 -> 750304.95 | G23: ='2-Production'!D56*'1-Inputs'!$C$85*G5*(1+'1-Inputs'!$C$161)^4 -> 765311.05 | H23: ='2-Production'!D56*'1-Inputs'!$C$85*H5*(1+'1-Inputs'!$C$161)^5 -> 780617.27 | I23: ='2-Production'!D56*'1-Inputs'!$C$85*I5*(1+'1-Inputs'!$C$161)^6 -> 796229.61 | J23: ='2-Production'!D56*'1-Inputs'!$C$85*J5*(1+'1-Inputs'!$C$161)^7 -> 812154.2 | K23: ='2-Production'!D56*'1-Inputs'!$C$85*K5*(1+'1-Inputs'!$C$161)^8 -> 828397.29 | L23: ='2-Production'!D56*'1-Inputs'!$C$85*L5*(1+'1-Inputs'!$C$161)^9 -> 844965.23 | M23: ='2-Production'!D56*'1-Inputs'!$C$85*M5*(1+'1-Inputs'!$C$161)^10 -> 861864.54 | N23: ='2-Production'!D56*'1-Inputs'!$C$85*N5*(1+'1-Inputs'!$C$161)^11 -> 879101.83 | O23: ='2-Production'!D56*'1-Inputs'!$C$85*O5*(1+'1-Inputs'!$C$161)^12 -> 896683.87 | P23: ='2-Production'!D56*'1-Inputs'!$C$85*P5*(1+'1-Inputs'!$C$161)^13 -> 914617.54 | Q23: ='2-Production'!D56*'1-Inputs'!$C$85*Q5*(1+'1-Inputs'!$C$161)^14 -> 932909.89
B24: Couche catalytique halogenes | C24: ='1-Inputs'!$C$115*'1-Inputs'!$C$8*C5*(1+'1-Inputs'!$C$161)^0 -> 105000 | D24: ='1-Inputs'!$C$115*'1-Inputs'!$C$8*D5*(1+'1-Inputs'!$C$161)^1 -> 130050 | E24: ='1-Inputs'!$C$115*'1-Inputs'!$C$8*E5*(1+'1-Inputs'!$C$161)^2 -> 156060 | F24: ='1-Inputs'!$C$115*'1-Inputs'!$C$8*F5*(1+'1-Inputs'!$C$161)^3 -> 159181.2 | G24: ='1-Inputs'!$C$115*'1-Inputs'!$C$8*G5*(1+'1-Inputs'!$C$161)^4 -> 162364.82 | H24: ='1-Inputs'!$C$115*'1-Inputs'!$C$8*H5*(1+'1-Inputs'!$C$161)^5 -> 165612.12 | I24: ='1-Inputs'!$C$115*'1-Inputs'!$C$8*I5*(1+'1-Inputs'!$C$161)^6 -> 168924.36 | J24: ='1-Inputs'!$C$115*'1-Inputs'!$C$8*J5*(1+'1-Inputs'!$C$161)^7 -> 172302.85 | K24: ='1-Inputs'!$C$115*'1-Inputs'!$C$8*K5*(1+'1-Inputs'!$C$161)^8 -> 175748.91 | L24: ='1-Inputs'!$C$115*'1-Inputs'!$C$8*L5*(1+'1-Inputs'!$C$161)^9 -> 179263.89 | M24: ='1-Inputs'!$C$115*'1-Inputs'!$C$8*M5*(1+'1-Inputs'!$C$161)^10 -> 182849.16 | N24: ='1-Inputs'!$C$115*'1-Inputs'!$C$8*N5*(1+'1-Inputs'!$C$161)^11 -> 186506.15 | O24: ='1-Inputs'!$C$115*'1-Inputs'!$C$8*O5*(1+'1-Inputs'!$C$161)^12 -> 190236.27 | P24: ='1-Inputs'!$C$115*'1-Inputs'!$C$8*P5*(1+'1-Inputs'!$C$161)^13 -> 194040.99 | Q24: ='1-Inputs'!$C$115*'1-Inputs'!$C$8*Q5*(1+'1-Inputs'!$C$161)^14 -> 197921.81
B25: Ceramique SEA CORAL | C25: ='1-Inputs'!$C$116*'1-Inputs'!$C$8*(1+'1-Inputs'!$C$161)^0 -> 15000 | D25: ='1-Inputs'!$C$116*'1-Inputs'!$C$8*(1+'1-Inputs'!$C$161)^1 -> 15300 | E25: ='1-Inputs'!$C$116*'1-Inputs'!$C$8*(1+'1-Inputs'!$C$161)^2 -> 15606 | F25: ='1-Inputs'!$C$116*'1-Inputs'!$C$8*(1+'1-Inputs'!$C$161)^3 -> 15918.12 | G25: ='1-Inputs'!$C$116*'1-Inputs'!$C$8*(1+'1-Inputs'!$C$161)^4 -> 16236.482 | H25: ='1-Inputs'!$C$116*'1-Inputs'!$C$8*(1+'1-Inputs'!$C$161)^5 -> 16561.212 | I25: ='1-Inputs'!$C$116*'1-Inputs'!$C$8*(1+'1-Inputs'!$C$161)^6 -> 16892.436 | J25: ='1-Inputs'!$C$116*'1-Inputs'!$C$8*(1+'1-Inputs'!$C$161)^7 -> 17230.285 | K25: ='1-Inputs'!$C$116*'1-Inputs'!$C$8*(1+'1-Inputs'!$C$161)^8 -> 17574.891 | L25: ='1-Inputs'!$C$116*'1-Inputs'!$C$8*(1+'1-Inputs'!$C$161)^9 -> 17926.389 | M25: ='1-Inputs'!$C$116*'1-Inputs'!$C$8*(1+'1-Inputs'!$C$161)^10 -> 18284.916 | N25: ='1-Inputs'!$C$116*'1-Inputs'!$C$8*(1+'1-Inputs'!$C$161)^11 -> 18650.615 | O25: ='1-Inputs'!$C$116*'1-Inputs'!$C$8*(1+'1-Inputs'!$C$161)^12 -> 19023.627 | P25: ='1-Inputs'!$C$116*'1-Inputs'!$C$8*(1+'1-Inputs'!$C$161)^13 -> 19404.099 | Q25: ='1-Inputs'!$C$116*'1-Inputs'!$C$8*(1+'1-Inputs'!$C$161)^14 -> 19792.181
B26: Carbonate de calcium (neutralisation) | C26: ='2-Production'!D50*'1-Inputs'!$C$120*C5*(1+'1-Inputs'!$C$161)^0 -> 20709.118 | D26: ='2-Production'!D50*'1-Inputs'!$C$120*D5*(1+'1-Inputs'!$C$161)^1 -> 25649.722 | E26: ='2-Production'!D50*'1-Inputs'!$C$120*E5*(1+'1-Inputs'!$C$161)^2 -> 30779.667 | F26: ='2-Production'!D50*'1-Inputs'!$C$120*F5*(1+'1-Inputs'!$C$161)^3 -> 31395.26 | G26: ='2-Production'!D50*'1-Inputs'!$C$120*G5*(1+'1-Inputs'!$C$161)^4 -> 32023.165 | H26: ='2-Production'!D50*'1-Inputs'!$C$120*H5*(1+'1-Inputs'!$C$161)^5 -> 32663.629 | I26: ='2-Production'!D50*'1-Inputs'!$C$120*I5*(1+'1-Inputs'!$C$161)^6 -> 33316.901 | J26: ='2-Production'!D50*'1-Inputs'!$C$120*J5*(1+'1-Inputs'!$C$161)^7 -> 33983.239 | K26: ='2-Production'!D50*'1-Inputs'!$C$120*K5*(1+'1-Inputs'!$C$161)^8 -> 34662.904 | L26: ='2-Production'!D50*'1-Inputs'!$C$120*L5*(1+'1-Inputs'!$C$161)^9 -> 35356.162 | M26: ='2-Production'!D50*'1-Inputs'!$C$120*M5*(1+'1-Inputs'!$C$161)^10 -> 36063.285 | N26: ='2-Production'!D50*'1-Inputs'!$C$120*N5*(1+'1-Inputs'!$C$161)^11 -> 36784.551 | O26: ='2-Production'!D50*'1-Inputs'!$C$120*O5*(1+'1-Inputs'!$C$161)^12 -> 37520.242 | P26: ='2-Production'!D50*'1-Inputs'!$C$120*P5*(1+'1-Inputs'!$C$161)^13 -> 38270.647 | Q26: ='2-Production'!D50*'1-Inputs'!$C$120*Q5*(1+'1-Inputs'!$C$161)^14 -> 39036.06
B27: Charbon actif (affinage eau) | C27: ='1-Inputs'!$C$121*'1-Inputs'!$C$8*C5*(1+'1-Inputs'!$C$161)^0 -> 28000 | D27: ='1-Inputs'!$C$121*'1-Inputs'!$C$8*D5*(1+'1-Inputs'!$C$161)^1 -> 34680 | E27: ='1-Inputs'!$C$121*'1-Inputs'!$C$8*E5*(1+'1-Inputs'!$C$161)^2 -> 41616 | F27: ='1-Inputs'!$C$121*'1-Inputs'!$C$8*F5*(1+'1-Inputs'!$C$161)^3 -> 42448.32 | G27: ='1-Inputs'!$C$121*'1-Inputs'!$C$8*G5*(1+'1-Inputs'!$C$161)^4 -> 43297.286 | H27: ='1-Inputs'!$C$121*'1-Inputs'!$C$8*H5*(1+'1-Inputs'!$C$161)^5 -> 44163.232 | I27: ='1-Inputs'!$C$121*'1-Inputs'!$C$8*I5*(1+'1-Inputs'!$C$161)^6 -> 45046.497 | J27: ='1-Inputs'!$C$121*'1-Inputs'!$C$8*J5*(1+'1-Inputs'!$C$161)^7 -> 45947.427 | K27: ='1-Inputs'!$C$121*'1-Inputs'!$C$8*K5*(1+'1-Inputs'!$C$161)^8 -> 46866.375 | L27: ='1-Inputs'!$C$121*'1-Inputs'!$C$8*L5*(1+'1-Inputs'!$C$161)^9 -> 47803.703 | M27: ='1-Inputs'!$C$121*'1-Inputs'!$C$8*M5*(1+'1-Inputs'!$C$161)^10 -> 48759.777 | N27: ='1-Inputs'!$C$121*'1-Inputs'!$C$8*N5*(1+'1-Inputs'!$C$161)^11 -> 49734.972 | O27: ='1-Inputs'!$C$121*'1-Inputs'!$C$8*O5*(1+'1-Inputs'!$C$161)^12 -> 50729.672 | P27: ='1-Inputs'!$C$121*'1-Inputs'!$C$8*P5*(1+'1-Inputs'!$C$161)^13 -> 51744.265 | Q27: ='1-Inputs'!$C$121*'1-Inputs'!$C$8*Q5*(1+'1-Inputs'!$C$161)^14 -> 52779.151
B28: Elimination du concentrat halogene | C28: ='2-Production'!D55*'1-Inputs'!$C$118*C5*(1+'1-Inputs'!$C$161)^0 -> 77880.959 | D28: ='2-Production'!D55*'1-Inputs'!$C$118*D5*(1+'1-Inputs'!$C$161)^1 -> 96461.131 | E28: ='2-Production'!D55*'1-Inputs'!$C$118*E5*(1+'1-Inputs'!$C$161)^2 -> 115753.36 | F28: ='2-Production'!D55*'1-Inputs'!$C$118*F5*(1+'1-Inputs'!$C$161)^3 -> 118068.42 | G28: ='2-Production'!D55*'1-Inputs'!$C$118*G5*(1+'1-Inputs'!$C$161)^4 -> 120429.79 | H28: ='2-Production'!D55*'1-Inputs'!$C$118*H5*(1+'1-Inputs'!$C$161)^5 -> 122838.39 | I28: ='2-Production'!D55*'1-Inputs'!$C$118*I5*(1+'1-Inputs'!$C$161)^6 -> 125295.16 | J28: ='2-Production'!D55*'1-Inputs'!$C$118*J5*(1+'1-Inputs'!$C$161)^7 -> 127801.06 | K28: ='2-Production'!D55*'1-Inputs'!$C$118*K5*(1+'1-Inputs'!$C$161)^8 -> 130357.08 | L28: ='2-Production'!D55*'1-Inputs'!$C$118*L5*(1+'1-Inputs'!$C$161)^9 -> 132964.22 | M28: ='2-Production'!D55*'1-Inputs'!$C$118*M5*(1+'1-Inputs'!$C$161)^10 -> 135623.51 | N28: ='2-Production'!D55*'1-Inputs'!$C$118*N5*(1+'1-Inputs'!$C$161)^11 -> 138335.98 | O28: ='2-Production'!D55*'1-Inputs'!$C$118*O5*(1+'1-Inputs'!$C$161)^12 -> 141102.7 | P28: ='2-Production'!D55*'1-Inputs'!$C$118*P5*(1+'1-Inputs'!$C$161)^13 -> 143924.75 | Q28: ='2-Production'!D55*'1-Inputs'!$C$118*Q5*(1+'1-Inputs'!$C$161)^14 -> 146803.25
B29: Assurance | C29: ='1-Inputs'!$C$114*'3-CAPEX'!$C$31*(1+'1-Inputs'!$C$161)^0 -> 320298.75 | D29: ='1-Inputs'!$C$114*'3-CAPEX'!$C$31*(1+'1-Inputs'!$C$161)^1 -> 326704.72 | E29: ='1-Inputs'!$C$114*'3-CAPEX'!$C$31*(1+'1-Inputs'!$C$161)^2 -> 333238.82 | F29: ='1-Inputs'!$C$114*'3-CAPEX'!$C$31*(1+'1-Inputs'!$C$161)^3 -> 339903.6 | G29: ='1-Inputs'!$C$114*'3-CAPEX'!$C$31*(1+'1-Inputs'!$C$161)^4 -> 346701.67 | H29: ='1-Inputs'!$C$114*'3-CAPEX'!$C$31*(1+'1-Inputs'!$C$161)^5 -> 353635.7 | I29: ='1-Inputs'!$C$114*'3-CAPEX'!$C$31*(1+'1-Inputs'!$C$161)^6 -> 360708.42 | J29: ='1-Inputs'!$C$114*'3-CAPEX'!$C$31*(1+'1-Inputs'!$C$161)^7 -> 367922.58 | K29: ='1-Inputs'!$C$114*'3-CAPEX'!$C$31*(1+'1-Inputs'!$C$161)^8 -> 375281.04 | L29: ='1-Inputs'!$C$114*'3-CAPEX'!$C$31*(1+'1-Inputs'!$C$161)^9 -> 382786.66 | M29: ='1-Inputs'!$C$114*'3-CAPEX'!$C$31*(1+'1-Inputs'!$C$161)^10 -> 390442.39 | N29: ='1-Inputs'!$C$114*'3-CAPEX'!$C$31*(1+'1-Inputs'!$C$161)^11 -> 398251.24 | O29: ='1-Inputs'!$C$114*'3-CAPEX'!$C$31*(1+'1-Inputs'!$C$161)^12 -> 406216.26 | P29: ='1-Inputs'!$C$114*'3-CAPEX'!$C$31*(1+'1-Inputs'!$C$161)^13 -> 414340.59 | Q29: ='1-Inputs'!$C$114*'3-CAPEX'!$C$31*(1+'1-Inputs'!$C$161)^14 -> 422627.4
B30: Provision et divers | C30: ='1-Inputs'!$C$112*'3-CAPEX'!$C$31*C5*(1+'1-Inputs'!$C$161)^0 -> 896836.5 | D30: ='1-Inputs'!$C$112*'3-CAPEX'!$C$31*D5*(1+'1-Inputs'!$C$161)^1 -> 1110796.1 | E30: ='1-Inputs'!$C$112*'3-CAPEX'!$C$31*E5*(1+'1-Inputs'!$C$161)^2 -> 1332955.3 | F30: ='1-Inputs'!$C$112*'3-CAPEX'!$C$31*F5*(1+'1-Inputs'!$C$161)^3 -> 1359614.4 | G30: ='1-Inputs'!$C$112*'3-CAPEX'!$C$31*G5*(1+'1-Inputs'!$C$161)^4 -> 1386806.7 | H30: ='1-Inputs'!$C$112*'3-CAPEX'!$C$31*H5*(1+'1-Inputs'!$C$161)^5 -> 1414542.8 | I30: ='1-Inputs'!$C$112*'3-CAPEX'!$C$31*I5*(1+'1-Inputs'!$C$161)^6 -> 1442833.7 | J30: ='1-Inputs'!$C$112*'3-CAPEX'!$C$31*J5*(1+'1-Inputs'!$C$161)^7 -> 1471690.3 | K30: ='1-Inputs'!$C$112*'3-CAPEX'!$C$31*K5*(1+'1-Inputs'!$C$161)^8 -> 1501124.1 | L30: ='1-Inputs'!$C$112*'3-CAPEX'!$C$31*L5*(1+'1-Inputs'!$C$161)^9 -> 1531146.6 | M30: ='1-Inputs'!$C$112*'3-CAPEX'!$C$31*M5*(1+'1-Inputs'!$C$161)^10 -> 1561769.6 | N30: ='1-Inputs'!$C$112*'3-CAPEX'!$C$31*N5*(1+'1-Inputs'!$C$161)^11 -> 1593004.9 | O30: ='1-Inputs'!$C$112*'3-CAPEX'!$C$31*O5*(1+'1-Inputs'!$C$161)^12 -> 1624865 | P30: ='1-Inputs'!$C$112*'3-CAPEX'!$C$31*P5*(1+'1-Inputs'!$C$161)^13 -> 1657362.3 | Q30: ='1-Inputs'!$C$112*'3-CAPEX'!$C$31*Q5*(1+'1-Inputs'!$C$161)^14 -> 1690509.6
B31: TOTAL CHARGES | C31: =C18+SUM(C20:C30) -> 3441240.4 | D31: =D18+SUM(D20:D30) -> 4188935.3 | E31: =E18+SUM(E20:E30) -> 4965161.5 | F31: =F18+SUM(F20:F30) -> 5064464.7 | G31: =G18+SUM(G20:G30) -> 5465100.6 | H31: =H18+SUM(H20:H30) -> 5879736.1 | I31: =I18+SUM(I20:I30) -> 6308771.1 | J31: =J18+SUM(J20:J30) -> 6752615.5 | ... Q31: =Q18+SUM(Q20:Q30) -> 8486436.4
A33: RESULTAT
B34: EBITDA | C34: =C15-C31 -> 5992748.3 | D34: =D15-D31 -> 7495733.5 | E34: =E15-E31 -> 9056441.1 | F34: =F15-F31 -> 9237569.9 | G34: =G15-G31 -> 9122974.7 | H34: =H15-H31 -> 9000100.6 | I34: =I15-I31 -> 8868662.4 | J34: =J15-J31 -> 8728366.7 | ... Q34: =Q15-Q31 -> 9296346
B35: Marge EBITDA | C35: =C34/C15 -> 0.63522954 | D35: =D34/D15 -> 0.64150158 | E35: =E34/E15 -> 0.64589201 | F35: =F34/F15 -> 0.64589201 | G35: =G34/G15 -> 0.62537206 | H35: =H34/H15 -> 0.60485211 | I35: =I34/I15 -> 0.58433216 | J35: =J34/J15 -> 0.5638122 | ... Q35: =Q34/Q15 -> 0.5227723
B36: EBITDA par tonne | C36: =C34/C6 -> 185.30452 | D36: =D34/D6 -> 190.87684 | E36: =E34/E6 -> 196.02686 | F36: =F34/F6 -> 199.9474 | G36: =G34/G6 -> 197.46698 | H36: =H34/H6 -> 194.80737 | I36: =I34/I6 -> 191.96239 | J36: =J34/J6 -> 188.92569 | ... Q36: =Q34/Q6 -> 201.21961
B37: Amortissement | C37: =-IF(1<='1-Inputs'!$C$160,'3-CAPEX'!$C$37,0) -> -4270650 | D37: =-IF(2<='1-Inputs'!$C$160,'3-CAPEX'!$C$37,0) -> -4270650 | E37: =-IF(3<='1-Inputs'!$C$160,'3-CAPEX'!$C$37,0) -> -4270650 | F37: =-IF(4<='1-Inputs'!$C$160,'3-CAPEX'!$C$37,0) -> -4270650 | G37: =-IF(5<='1-Inputs'!$C$160,'3-CAPEX'!$C$37,0) -> -4270650 | H37: =-IF(6<='1-Inputs'!$C$160,'3-CAPEX'!$C$37,0) -> -4270650 | I37: =-IF(7<='1-Inputs'!$C$160,'3-CAPEX'!$C$37,0) -> -4270650 | J37: =-IF(8<='1-Inputs'!$C$160,'3-CAPEX'!$C$37,0) -> -4270650 | K37: =-IF(9<='1-Inputs'!$C$160,'3-CAPEX'!$C$37,0) -> -4270650 | L37: =-IF(10<='1-Inputs'!$C$160,'3-CAPEX'!$C$37,0) -> -4270650 | M37: =-IF(11<='1-Inputs'!$C$160,'3-CAPEX'!$C$37,0) -> -4270650 | N37: =-IF(12<='1-Inputs'!$C$160,'3-CAPEX'!$C$37,0) -> -4270650 | O37: =-IF(13<='1-Inputs'!$C$160,'3-CAPEX'!$C$37,0) -> -4270650 | P37: =-IF(14<='1-Inputs'!$C$160,'3-CAPEX'!$C$37,0) -> -4270650 | Q37: =-IF(15<='1-Inputs'!$C$160,'3-CAPEX'!$C$37,0) -> -4270650
B38: EBIT | C38: =C34+C37 -> 1722098.3 | D38: =D34+D37 -> 3225083.5 | E38: =E34+E37 -> 4785791.1 | F38: =F34+F37 -> 4966919.9 | G38: =G34+G37 -> 4852324.7 | H38: =H34+H37 -> 4729450.6 | I38: =I34+I37 -> 4598012.4 | J38: =J34+J37 -> 4457716.7 | ... Q38: =Q34+Q37 -> 5025696
B39: Interets | C39: =IF(AND(1<='1-Inputs'!$C$158,'3-CAPEX'!$C$35>0),CUMIPMT('1-Inputs'!$C$157/12,'1-Inputs'!$C$158*12,'3-CAPEX'!$C$35,12*(1-1)+1,12*1,0),0) -> -5247977.6 | D39: =IF(AND(2<='1-Inputs'!$C$158,'3-CAPEX'!$C$35>0),CUMIPMT('1-Inputs'!$C$157/12,'1-Inputs'!$C$158*12,'3-CAPEX'!$C$35,12*(2-1)+1,12*2,0),0) -> -4934438 | E39: =IF(AND(3<='1-Inputs'!$C$158,'3-CAPEX'!$C$35>0),CUMIPMT('1-Inputs'!$C$157/12,'1-Inputs'!$C$158*12,'3-CAPEX'!$C$35,12*(3-1)+1,12*3,0),0) -> -4581133.8 | F39: =IF(AND(4<='1-Inputs'!$C$158,'3-CAPEX'!$C$35>0),CUMIPMT('1-Inputs'!$C$157/12,'1-Inputs'!$C$158*12,'3-CAPEX'!$C$35,12*(4-1)+1,12*4,0),0) -> -4183021.7 | G39: =IF(AND(5<='1-Inputs'!$C$158,'3-CAPEX'!$C$35>0),CUMIPMT('1-Inputs'!$C$157/12,'1-Inputs'!$C$158*12,'3-CAPEX'!$C$35,12*(5-1)+1,12*5,0),0) -> -3734419.1 | H39: =IF(AND(6<='1-Inputs'!$C$158,'3-CAPEX'!$C$35>0),CUMIPMT('1-Inputs'!$C$157/12,'1-Inputs'!$C$158*12,'3-CAPEX'!$C$35,12*(6-1)+1,12*6,0),0) -> -3228922.5 | I39: =IF(AND(7<='1-Inputs'!$C$158,'3-CAPEX'!$C$35>0),CUMIPMT('1-Inputs'!$C$157/12,'1-Inputs'!$C$158*12,'3-CAPEX'!$C$35,12*(7-1)+1,12*7,0),0) -> -2659316.2 | J39: =IF(AND(8<='1-Inputs'!$C$158,'3-CAPEX'!$C$35>0),CUMIPMT('1-Inputs'!$C$157/12,'1-Inputs'!$C$158*12,'3-CAPEX'!$C$35,12*(8-1)+1,12*8,0),0) -> -2017469.6 | K39: =IF(AND(9<='1-Inputs'!$C$158,'3-CAPEX'!$C$35>0),CUMIPMT('1-Inputs'!$C$157/12,'1-Inputs'!$C$158*12,'3-CAPEX'!$C$35,12*(9-1)+1,12*9,0),0) -> -1294220.7 | L39: =IF(AND(10<='1-Inputs'!$C$158,'3-CAPEX'!$C$35>0),CUMIPMT('1-Inputs'!$C$157/12,'1-Inputs'!$C$158*12,'3-CAPEX'!$C$35,12*(10-1)+1,12*10,0),0) -> -479245.84 | M39: =IF(AND(11<='1-Inputs'!$C$158,'3-CAPEX'!$C$35>0),CUMIPMT('1-Inputs'!$C$157/12,'1-Inputs'!$C$158*12,'3-CAPEX'!$C$35,12*(11-1)+1,12*11,0),0) -> 0 | N39: =IF(AND(12<='1-Inputs'!$C$158,'3-CAPEX'!$C$35>0),CUMIPMT('1-Inputs'!$C$157/12,'1-Inputs'!$C$158*12,'3-CAPEX'!$C$35,12*(12-1)+1,12*12,0),0) -> 0 | O39: =IF(AND(13<='1-Inputs'!$C$158,'3-CAPEX'!$C$35>0),CUMIPMT('1-Inputs'!$C$157/12,'1-Inputs'!$C$158*12,'3-CAPEX'!$C$35,12*(13-1)+1,12*13,0),0) -> 0 | P39: =IF(AND(14<='1-Inputs'!$C$158,'3-CAPEX'!$C$35>0),CUMIPMT('1-Inputs'!$C$157/12,'1-Inputs'!$C$158*12,'3-CAPEX'!$C$35,12*(14-1)+1,12*14,0),0) -> 0 | Q39: =IF(AND(15<='1-Inputs'!$C$158,'3-CAPEX'!$C$35>0),CUMIPMT('1-Inputs'!$C$157/12,'1-Inputs'!$C$158*12,'3-CAPEX'!$C$35,12*(15-1)+1,12*15,0),0) -> 0
B40: Resultat avant impot | C40: =C38+C39 -> -3525879.3 | D40: =D38+D39 -> -1709354.5 | E40: =E38+E39 -> 204657.33 | F40: =F38+F39 -> 783898.19 | G40: =G38+G39 -> 1117905.6 | H40: =H38+H39 -> 1500528.2 | I40: =I38+I39 -> 1938696.3 | J40: =J38+J39 -> 2440247.1 | ... Q40: =Q38+Q39 -> 5025696
B41: Impot | C41: =-MAX(0,C40)*'1-Inputs'!$C$159 -> 0 | D41: =-MAX(0,D40)*'1-Inputs'!$C$159 -> 0 | E41: =-MAX(0,E40)*'1-Inputs'!$C$159 -> -51164.331 | F41: =-MAX(0,F40)*'1-Inputs'!$C$159 -> -195974.55 | G41: =-MAX(0,G40)*'1-Inputs'!$C$159 -> -279476.4 | H41: =-MAX(0,H40)*'1-Inputs'!$C$159 -> -375132.05 | I41: =-MAX(0,I40)*'1-Inputs'!$C$159 -> -484674.07 | J41: =-MAX(0,J40)*'1-Inputs'!$C$159 -> -610061.78 | ... Q41: =-MAX(0,Q40)*'1-Inputs'!$C$159 -> -1256424
B42: Resultat net | C42: =C40+C41 -> -3525879.3 | D42: =D40+D41 -> -1709354.5 | E42: =E40+E41 -> 153492.99 | F42: =F40+F41 -> 587923.64 | G42: =G40+G41 -> 838429.19 | H42: =H40+H41 -> 1125396.1 | I42: =I40+I41 -> 1454022.2 | J42: =J40+J41 -> 1830185.3 | ... Q42: =Q40+Q41 -> 3769272
A44: TRESORERIE
