Workbook
Name _50: [1]percentiles!$C$1
Name filtre: OMR!$A$21

Sheet Sommaire
A2: Sommaire
B4: Cet annexe interactive présente les données brutes du référentiel national des coûts du service public de gestion des déchets portant sur l'année 2023. Pour chaque boite à moustache présente dans le rapport du référentiel, le tableau de données correspondant est présenté dans cette annexe. Un bilan des coûts en €/habitant et €/tonne par flux et par typologie d'habitat est également proposé en synthèse.
B10: Fiche du référentiel
B11: Synthèse €/hab.
B12: Synthèse €/tonne
B13: Tous flux
B14: OMR
B15: Emballages en verre
B16: Papiers et emballages hors verre
B17: Déchèteries
B18: Autres flux
B19: Tarification Incitative
B20: Évolution
B22: ADEME, Laura VILLARROEL et Alexandra GENTRIC, AWIPLAN, Magali GASS. 2025/09. Référentiel des coûts du service public de gestion des déchets en France métropolitaine données 2023.

Sheet Synthèse €hab.
D1: Retour sommaire annexe
C2: Ensemble | I2: Rural | O2: Mixte rural | U2: Mixte urbain | AA2: Urbain | AG2: Touristique
A4: OMR | D4: Coût Complet | E4: Coût technique | F4: Coût partagé | G4: Coût aidé HT | J4: Coût Complet | K4: Coût technique | L4: Coût partagé | M4: Coût aidé HT | P4: Coût Complet | Q4: Coût technique | R4: Coût partagé | S4: Coût aidé HT | V4: Coût Complet | W4: Coût technique | X4: Coût partagé | Y4: Coût aidé HT | AB4: Coût Complet | AC4: Coût technique | AD4: Coût partagé | AE4: Coût aidé HT | AH4: Coût Complet | AI4: Coût technique | AJ4: Coût partagé | AK4: Coût aidé HT
C5: p90 | D5: =OMR!E21 -> 99.837633 | E5: =OMR!F21 -> 95.8612 | F5: =OMR!G21 -> 95.6546 | G5: =OMR!H21 -> 93.604 | I5: p90 | J5: 77.958 | K5: 78.32 | L5: 77.96 | M5: 77.4526 | O5: p90 | P5: 86.7878 | Q5: 85.407 | R5: 85.0806 | S5: 83.6816 | U5: p90 | V5: 101.106 | W5: 97.999 | X5: 97.7898 | Y5: 97.7898 | AA5: p90 | AB5: 111.74549 | AC5: 83.3901 | AD5: 82.8354 | AE5: 82.3177 | AG5: p90 | AH5: 146.06966 | AI5: 152.7783 | AJ5: 152.7783 | AK5: 152.7783
C6: p75 | D6: =OMR!E22 -> 76.365 | E6: =OMR!F22 -> 72.621 | F6: =OMR!G22 -> 72.548 | G6: =OMR!H22 -> 71.8845 | I6: p75 | J6: 68.89839 | K6: 63.82 | L6: 63.713 | M6: 63.496 | O6: p75 | P6: 71.681 | Q6: 67.863 | R6: 67.391 | S6: 66.49 | U6: p75 | V6: 77.0203 | W6: 75.885 | X6: 75.633 | Y6: 75.633 | AA6: p75 | AB6: 78.169389 | AC6: 72.18175 | AD6: 71.91325 | AE6: 70.891 | AG6: p75 | AH6: 126.09025 | AI6: 119.20825 | AJ6: 119.07975 | AK6: 118.167
C7: Moyenne pondérée | D7: =OMR!E23 -> 69.60774 | E7: =OMR!F23 -> 67.042323 | F7: =OMR!G23 -> 66.663792 | G7: =OMR!H23 -> 66.307238 | I7: Médiane | J7: 56.253 | K7: 54.1 | L7: 53.174 | M7: 52.756 | O7: Médiane | P7: 60.222 | Q7: 55.994 | R7: 55.576 | S7: 55.304 | U7: Médiane | V7: 61.701 | W7: 59.778 | X7: 59.132 | Y7: 58.474 | AA7: Médiane | AB7: 68.236 | AC7: 63.5115 | AD7: 62.832 | AE7: 62.407 | AG7: Médiane | AH7: 92.658599 | AI7: 87.0995 | AJ7: 86.9215 | AK7: 86.903
C8: p25 | D8: =OMR!E24 -> 49.625 | E8: =OMR!F24 -> 46.5485 | F8: =OMR!G24 -> 46.1825 | G8: =OMR!H24 -> 45.7465 | I8: p25 | J8: 44.694 | K8: 43.565 | L8: 43.167 | M8: 43.167 | O8: p25 | P8: 48.117803 | Q8: 44.003 | R8: 43.888 | S8: 43.646 | U8: p25 | V8: 51.466 | W8: 47.673 | X8: 47.673 | Y8: 47.479 | AA8: p25 | AB8: 58.164157 | AC8: 49.17775 | AD8: 48.42325 | AE8: 48.382 | AG8: p25 | AH8: 76.75375 | AI8: 76.18375 | AJ8: 75.76925 | AK8: 75.749
C9: p10 | D9: =OMR!E25 -> 40.69052 | E9: =OMR!F25 -> 37.64 | F9: =OMR!G25 -> 37.1282 | G9: =OMR!H25 -> 36.8058 | I9: p10 | J9: 38.183942 | K9: 35.789 | L9: 35.5986 | M9: 34.5934 | O9: p10 | P9: 38.4651 | Q9: 35.7756 | R9: 35.6702 | S9: 35.4366 | U9: p10 | V9: 41.469586 | W9: 37.501 | X9: 37.484 | Y9: 36.8154 | AA9: p10 | AB9: 55.318869 | AC9: 42.4537 | AD9: 41.6516 | AE9: 41.1972 | AG9: p10 | AH9: 69.036868 | AI9: 65.2389 | AJ9: 64.989 | AK9: 63.4972
A11: Verre | D11: Coût Complet | E11: Coût technique | F11: Coût partagé | G11: Coût aidé HT | J11: Coût Complet | K11: Coût technique | L11: Coût partagé | M11: Coût aidé HT | P11: Coût Complet | Q11: Coût technique | R11: Coût partagé | S11: Coût aidé HT | V11: Coût Complet | W11: Coût technique | X11: Coût partagé | Y11: Coût aidé HT | AB11: Coût Complet | AC11: Coût technique | AD11: Coût partagé | AE11: Coût aidé HT | AH11: Coût Complet | AI11: Coût technique | AJ11: Coût partagé | AK11: Coût aidé HT
C12: p90 | D12: ='Emb. Verre'!E24 -> 6.6784 | E12: ='Emb. Verre'!F24 -> 5.4134 | F12: ='Emb. Verre'!G24 -> 4.992 | G12: ='Emb. Verre'!H24 -> 4.874 | I12: p90 | J12: 5.484 | K12: 4.3078 | L12: 3.7972 | M12: 3.631 | O12: p90 | P12: 6.1649 | Q12: 4.9 | R12: 4.4588 | S12: 4.2332 | U12: p90 | V12: 6.1244 | W12: 5.3474 | X12: 4.9828 | Y12: 4.968 | AA12: p90 | AB12: 5.8106 | AC12: 5.1314 | AD12: 4.682 | AE12: 4.6596 | AG12: p90 | AH12: 13.5365 | AI12: 10.6106 | AJ12: 9.2681 | AK12: 9.2361
C13: p75 | D13: ='Emb. Verre'!E25 -> 4.751 | E13: ='Emb. Verre'!F25 -> 3.6225 | F13: ='Emb. Verre'!G25 -> 3.126 | G13: ='Emb. Verre'!H25 -> 3.0455 | I13: p75 | J13: 4.263 | K13: 3.151 | L13: 2.665 | M13: 2.636 | O13: p75 | P13: 4.555 | Q13: 3.09 | R13: 2.622 | S13: 2.568 | U13: p75 | V13: 4.842 | W13: 3.815 | X13: 3.4 | Y13: 3.269 | AA13: p75 | AB13: 4.608 | AC13: 3.811 | AD13: 3.63375 | AE13: 3.43875 | AG13: p75 | AH13: 9.2905 | AI13: 6.88925 | AJ13: 6.32825 | AK13: 6.1735
C14: Moyenne pondérée | D14: ='Emb. Verre'!E26 -> 3.6161306 | E14: ='Emb. Verre'!F26 -> 2.7376356 | F14: ='Emb. Verre'!G26 -> 2.3492468 | G14: ='Emb. Verre'!H26 -> 2.3112805 | I14: Médiane | J14: 3.487 | K14: 2.26 | L14: 1.754 | M14: 1.628 | O14: Médiane | P14: 3.389 | Q14: 2.223 | R14: 1.787 | S14: 1.692 | U14: Médiane | V14: 3.322 | W14: 2.512 | X14: 2.05 | Y14: 2.049 | AA14: Médiane | AB14: 2.946 | AC14: 2.333 | AD14: 2.04 | AE14: 2.0195 | AG14: Médiane | AH14: 6.0635 | AI14: 4.454 | AJ14: 3.588 | AK14: 3.4865
C15: p25 | D15: ='Emb. Verre'!E27 -> 2.791 | E15: ='Emb. Verre'!F27 -> 1.7115 | F15: ='Emb. Verre'!G27 -> 1.258 | G15: ='Emb. Verre'!H27 -> 1.25 | I15: p25 | J15: 2.701 | K15: 1.582 | L15: 1.112 | M15: 1.099 | O15: p25 | P15: 2.791 | Q15: 1.595 | R15: 1.133 | S15: 1.092 | U15: p25 | V15: 2.732 | W15: 1.82 | X15: 1.523 | Y15: 1.414 | AA15: p25 | AB15: 2.5505 | AC15: 1.852 | AD15: 1.61425 | AE15: 1.56475 | AG15: p25 | AH15: 4.3775 | AI15: 2.783 | AJ15: 2.3215 | AK15: 2.24775
C16: p10 | D16: ='Emb. Verre'!E28 -> 2.3 | E16: ='Emb. Verre'!F28 -> 1.2692 | F16: ='Emb. Verre'!G28 -> 0.8094 | G16: ='Emb. Verre'!H28 -> 0.7758 | I16: p10 | J16: 2.278 | K16: 1.1554 | L16: 0.6906 | M16: 0.6462 | O16: p10 | P16: 2.3183 | Q16: 1.2274 | R16: 0.7658 | S16: 0.7428 | U16: p10 | V16: 2.1028 | W16: 1.3712 | X16: 1.095 | Y16: 1.0678 | AA16: p10 | AB16: 2.0656 | AC16: 1.5216 | AD16: 1.1498 | AE16: 1.1407 | AG16: p10 | AH16: 3.82 | AI16: 2.3453 | AJ16: 1.7846 | AK16: 1.7148
A18: Recyclables | D18: Coût Complet | E18: Coût technique | F18: Coût partagé | G18: Coût aidé HT | J18: Coût Complet | K18: Coût technique | L18: Coût partagé | M18: Coût aidé HT | P18: Coût Complet | Q18: Coût technique | R18: Coût partagé | S18: Coût aidé HT | V18: Coût Complet | W18: Coût technique | X18: Coût partagé | Y18: Coût aidé HT | AB18: Coût Complet | AC18: Coût technique | AD18: Coût partagé | AE18: Coût aidé HT | AH18: Coût Complet | AI18: Coût technique | AJ18: Coût partagé | AK18: Coût aidé HT
C19: p90 | D19: ='Papiers et Emb. HV'!E32 -> 46.36 | E19: ='Papiers et Emb. HV'!F32 -> 42.389 | F19: ='Papiers et Emb. HV'!G32 -> 28.1654 | G19: ='Papiers et Emb. HV'!H32 -> 28.0384 | I19: p90 | J19: 44.829 | K19: 41.9886 | L19: 27.9956 | M19: 27.3776 | O19: p90 | P19: 44.0558 | Q19: 39.8334 | R19: 27.6368 | S19: 27.1936 | U19: p90 | V19: 45.669 | W19: 41.4446 | X19: 28.052 | Y19: 27.8936 | AA19: p90 | AB19: 37.9472 | AC19: 34.3065 | AD19: 22.8794 | AE19: 22.8563 | AG19: p90 | AH19: 62.258 | AI19: 58.0726 | AJ19: 40.3471 | AK19: 40.3471
C20: p75 | D20: ='Papiers et Emb. HV'!E33 -> 39.257 | E20: ='Papiers et Emb. HV'!F33 -> 34.948 | F20: ='Papiers et Emb. HV'!G33 -> 20.9135 | G20: ='Papiers et Emb. HV'!H33 -> 20.822 | I20: p75 | J20: 39.691 | K20: 35.54 | L20: 22.43 | M20: 21.975 | O20: p75 | P20: 37.456 | Q20: 33.655 | R20: 18.744 | S20: 18.699 | U20: p75 | V20: 36.721 | W20: 33.999 | X20: 18.917 | Y20: 18.881 | AA20: p75 | AB20: 33.101 | AC20: 29.5295 | AD20: 19.39225 | AE20: 18.9215 | AG20: p75 | AH20: 56.7355 | AI20: 48.932 | AJ20: 29.07275 | AK20: 28.578
C21: Moyenne pondérée | D21: ='Papiers et Emb. HV'!E34 -> 32.401013 | E21: ='Papiers et Emb. HV'!F34 -> 28.203666 | F21: ='Papiers et Emb. HV'!G34 -> 16.6283 | G21: ='Papiers et Emb. HV'!H34 -> 16.475601 | I21: Médiane | J21: 33.682 | K21: 29.873 | L21: 14.758 | M21: 14.543 | O21: Médiane | P21: 32.5905 | Q21: 28.65 | R21: 14.715 | S21: 14.136 | U21: Médiane | V21: 32.461 | W21: 28.701 | X21: 14.117 | Y21: 13.984 | AA21: Médiane | AB21: 30.557 | AC21: 26.1285 | AD21: 15.8195 | AE21: 15.723 | AG21: Médiane | AH21: 42.129 | AI21: 38.6355 | AJ21: 20.7345 | AK21: 20.7055
C22: p25 | D22: ='Papiers et Emb. HV'!E35 -> 27.346 | E22: ='Papiers et Emb. HV'!F35 -> 23.4775 | F22: ='Papiers et Emb. HV'!G35 -> 10.29 | G22: ='Papiers et Emb. HV'!H35 -> 10.102 | I22: p25 | J22: 27.524 | K22: 24.414 | L22: 9.597 | M22: 9.584 | O22: p25 | P22: 26.7595 | Q22: 22.981 | R22: 9.375 | S22: 9.375 | U22: p25 | V22: 26.047 | W22: 22.363 | X22: 9.717 | Y22: 9.717 | AA22: p25 | AB22: 27.4725 | AC22: 22.659 | AD22: 13.00425 | AE22: 12.822 | AG22: p25 | AH22: 29.70675 | AI22: 27.137 | AJ22: 12.303 | AK22: 12.30175
C23: p10 | D23: ='Papiers et Emb. HV'!E36 -> 20.985 | E23: ='Papiers et Emb. HV'!F36 -> 17.7032 | F23: ='Papiers et Emb. HV'!G36 -> 6.7278 | G23: ='Papiers et Emb. HV'!H36 -> 6.6434 | I23: p10 | J23: 20.784 | K23: 17.4464 | L23: 6.3988 | M23: 6.3374 | O23: p10 | P23: 21.2691 | Q23: 17.0874 | R23: 5.5744 | S23: 5.5744 | U23: p10 | V23: 19.9284 | W23: 17.7888 | X23: 7.6322 | Y23: 7.6322 | AA23: p10 | AB23: 23.2742 | AC23: 19.8777 | AD23: 9.1626 | AE23: 8.9547 | AG23: p10 | AH23: 17.0595 | AI23: 15.2354 | AJ23: 6.8382 | AK23: 6.1787
A25: Déchèteries | D25: Coût Complet | E25: Coût technique | F25: Coût partagé | G25: Coût aidé HT | J25: Coût Complet | K25: Coût technique | L25: Coût partagé | M25: Coût aidé HT | P25: Coût Complet | Q25: Coût technique | R25: Coût partagé | S25: Coût aidé HT | V25: Coût Complet | W25: Coût technique | X25: Coût partagé | Y25: Coût aidé HT | AB25: Coût Complet | AC25: Coût technique | AD25: Coût partagé | AE25: Coût aidé HT | AH25: Coût Complet | AI25: Coût technique | AJ25: Coût partagé | AK25: Coût aidé HT
C26: p90 | D26: =Déchèteries!E21 -> 60.0364 | E26: =Déchèteries!F21 -> 57.2494 | F26: =Déchèteries!G21 -> 55.6556 | G26: =Déchèteries!H21 -> 54.5144 | I26: p90 | J26: 56.306 | K26: 56.512 | L26: 53.762 | M26: 52.9838 | O26: p90 | P26: 57.9985 | Q26: 54.1532 | R26: 52.358 | S26: 51.178 | U26: p90 | V26: 58.4224 | W26: 56.45 | X26: 55.1106 | Y26: 54.189 | AA26: p90 | AB26: 37.7508 | AC26: 35.6174 | AD26: 34.2228 | AE26: 34.1439 | AG26: p90 | AH26: 86.453 | AI26: 82.3862 | AJ26: 78.5884 | AK26: 77.7824
C27: p75 | D27: =Déchèteries!E22 -> 49.989 | E27: =Déchèteries!F22 -> 46.9705 | F27: =Déchèteries!G22 -> 44.6445 | G27: =Déchèteries!H22 -> 43.726 | I27: p75 | J27: 49.023 | K27: 46.974 | L27: 44.626 | M27: 43.553 | O27: p75 | P27: 48.46475 | Q27: 45.591 | R27: 43.485 | S27: 43.393 | U27: p75 | V27: 46.826 | W27: 42.251 | X27: 40.48 | Y27: 40.078 | AA27: p75 | AB27: 34.7285 | AC27: 32.17625 | AD27: 30.7265 | AE27: 30.72375 | AG27: p75 | AH27: 69.82825 | AI27: 66.26075 | AJ27: 63.36225 | AK27: 62.52225
C28: Moyenne pondérée | D28: =Déchèteries!E23 -> 33.697717 | E28: =Déchèteries!F23 -> 32.8194 | F28: =Déchèteries!G23 -> 31.39124 | G28: =Déchèteries!H23 -> 31.041737 | I28: Médiane | J28: 41.322 | K28: 39.392 | L28: 37.557 | M28: 37.069 | O28: Médiane | P28: 40.4355 | Q28: 37.639 | R28: 36.112 | S28: 35.478 | U28: Médiane | V28: 38.681 | W28: 35.903 | X28: 34.528 | Y28: 34.465 | AA28: Médiane | AB28: 26.775 | AC28: 26.546 | AD28: 26.05 | AE28: 25.955 | AG28: Médiane | AH28: 57.0875 | AI28: 54.7705 | AJ28: 51.2485 | AK28: 48.879
C29: p25 | D29: =Déchèteries!E24 -> 33.477 | E29: =Déchèteries!F24 -> 30.8235 | F29: =Déchèteries!G24 -> 29.233 | G29: =Déchèteries!H24 -> 28.81 | I29: p25 | J29: 36.207 | K29: 35.124 | L29: 32.622 | M29: 32.241 | O29: p25 | P29: 34.12675 | Q29: 31.766 | R29: 29.66 | S29: 29.304 | U29: p25 | V29: 29.437 | W29: 27.021 | X29: 26.137 | Y29: 25.975 | AA29: p25 | AB29: 19.0255 | AC29: 19.805 | AD29: 18.8435 | AE29: 18.615 | AG29: p25 | AH29: 46.91125 | AI29: 44.2755 | AJ29: 40.42575 | AK29: 39.17125
C30: p10 | D30: =Déchèteries!E25 -> 26.7252 | E30: =Déchèteries!F25 -> 25.4802 | F30: =Déchèteries!G25 -> 23.9276 | G30: =Déchèteries!H25 -> 23.4938 | I30: p10 | J30: 31.083 | K30: 29.3772 | L30: 27.5972 | M30: 27.1264 | O30: p10 | P30: 27.2688 | Q30: 26.3212 | R30: 24.7168 | S30: 24.573 | U30: p10 | V30: 25.6282 | W30: 25.0198 | X30: 23.8714 | Y30: 23.437 | AA30: p10 | AB30: 13.3738 | AC30: 12.7016 | AD30: 12.1008 | AE30: 12.0882 | AG30: p10 | AH30: 32.516 | AI30: 30.2319 | AJ30: 26.3161 | AK30: 26.208
A32: Tous flux | D32: Coût Complet | E32: Coût technique | F32: Coût partagé | G32: Coût aidé HT | J32: Coût Complet | K32: Coût technique | L32: Coût partagé | M32: Coût aidé HT | P32: Coût Complet | Q32: Coût technique | R32: Coût partagé | S32: Coût aidé HT | V32: Coût Complet | W32: Coût technique | X32: Coût partagé | Y32: Coût aidé HT | AB32: Coût Complet | AC32: Coût technique | AD32: Coût partagé | AE32: Coût aidé HT | AH32: Coût Complet | AI32: Coût technique | AJ32: Coût partagé | AK32: Coût aidé HT
C33: p90 | D33: ='Tous flux'!E18 -> 204.6404 | E33: ='Tous flux'!F18 -> 193.0818 | F33: ='Tous flux'!G18 -> 178.2472 | G33: ='Tous flux'!H18 -> 177.5704 | I33: p90 | J33: 178.915 | K33: 170.5364 | L33: 152.1054 | M33: 150.9358 | O33: p90 | P33: 191.8713 | Q33: 181.1776 | R33: 168.2726 | S33: 167.1282 | U33: p90 | V33: 190.978 | W33: 185.3988 | X33: 173.9862 | Y33: 173.2356 | AA33: p90 | AB33: 206.13794 | AC33: 168.6898 | AD33: 153.8595 | AE33: 152.1216 | AG33: p90 | AH33: 307.377 | AI33: 319.6035 | AJ33: 299.9243 | AK33: 297.0257
C34: p75 | D34: ='Tous flux'!E19 -> 168.85066 | E34: ='Tous flux'!F19 -> 157.129 | F34: ='Tous flux'!G19 -> 141.458 | G34: ='Tous flux'!H19 -> 139.373 | I34: p75 | J34: 157.682 | K34: 148.235 | L34: 134.008 | M34: 129.908 | O34: p75 | P34: 159.26225 | Q34: 146.19 | R34: 130.098 | S34: 128.299 | U34: p75 | V34: 171.582 | W34: 161.62 | X34: 145.118 | Y34: 144.863 | AA34: p75 | AB34: 155.00395 | AC34: 140.321 | AD34: 126.83175 | AE34: 126.47125 | AG34: p75 | AH34: 266.676 | AI34: 253.13575 | AJ34: 230.87625 | AK34: 223.1085
C35: Moyenne pondérée | D35: ='Tous flux'!E20 -> 152.7276 | E35: ='Tous flux'!F20 -> 141.76117 | F35: ='Tous flux'!G20 -> 127.84699 | G35: ='Tous flux'!H20 -> 126.86158 | I35: Médiane | J35: 139.738 | K35: 132.304 | L35: 114.606 | M35: 113.036 | O35: Médiane | P35: 141.85072 | Q35: 130.203 | R35: 112.718 | S35: 111.642 | U35: Médiane | V35: 144.66357 | W35: 132.167 | X35: 119.502 | Y35: 119.026 | AA35: Médiane | AB35: 141.55108 | AC35: 132.904 | AD35: 117.8145 | AE35: 116.8845 | AG35: Médiane | AH35: 205.1955 | AI35: 197.6295 | AJ35: 178.261 | AK35: 178.146
C36: p25 | D36: ='Tous flux'!E21 -> 127.771 | E36: ='Tous flux'!F21 -> 116.5265 | F36: ='Tous flux'!G21 -> 99.772 | G36: ='Tous flux'!H21 -> 99.032 | I36: p25 | J36: 123.586 | K36: 112.99 | L36: 94.4 | M36: 93.433 | O36: p25 | P36: 126.65024 | Q36: 115.18 | R36: 97.411 | S36: 95.531 | U36: p25 | V36: 134.546 | W36: 122.509 | X36: 107.176 | Y36: 106.204 | AA36: p25 | AB36: 125.6683 | AC36: 114.35825 | AD36: 101.89625 | AE36: 101.40975 | AG36: p25 | AH36: 177.53175 | AI36: 165.43075 | AJ36: 146.7075 | AK36: 144.00925
C37: p10 | D37: ='Tous flux'!E22 -> 117.19135 | E37: ='Tous flux'!F22 -> 102.8034 | F37: ='Tous flux'!G22 -> 87.4428 | G37: ='Tous flux'!H22 -> 86.4298 | I37: p10 | J37: 115.844 | K37: 102.3758 | L37: 84.9892 | M37: 82.9088 | O37: p10 | P37: 112.68039 | Q37: 100.3368 | R37: 83.0946 | S37: 82.4842 | U37: p10 | V37: 124.55498 | W37: 108.7522 | X37: 92.107 | Y37: 91.572 | AA37: p10 | AB37: 116.1738 | AC37: 100.9908 | AD37: 88.9727 | AE37: 88.5151 | AG37: p10 | AH37: 160.631 | AI37: 146.8417 | AJ37: 130.7231 | AK37: 130.4276

Sheet Synthèse €tonne
D1: Retour sommaire annexe
C2: Ensemble | I2: Rural | O2: Mixte rural | U2: Mixte urbain | AA2: Urbain | AG2: Touristique
A4: OMR | D4: Coût Complet | E4: Coût technique | F4: Coût partagé | G4: Coût aidé HT | J4: Coût Complet | K4: Coût technique | L4: Coût partagé | M4: Coût aidé HT | P4: Coût Complet | Q4: Coût technique | R4: Coût partagé | S4: Coût aidé HT | V4: Coût Complet | W4: Coût technique | X4: Coût partagé | Y4: Coût aidé HT | AB4: Coût Complet | AC4: Coût technique | AD4: Coût partagé | AE4: Coût aidé HT | AH4: Coût Complet | AI4: Coût technique | AJ4: Coût partagé | AK4: Coût aidé HT
C5: p90 | D5: =OMR!E28 -> 446.2752 | E5: =OMR!F28 -> 425.0448 | F5: =OMR!G28 -> 423.645 | G5: =OMR!H28 -> 418.8392 | I5: p90 | J5: 472.47676 | K5: 439.708 | L5: 439.6558 | M5: 422.7738 | O5: p90 | P5: 447.6854 | Q5: 431.1104 | R5: 430.533 | S5: 424.8262 | U5: p90 | V5: 427.0618 | W5: 397.1748 | X5: 396.5396 | Y5: 394.2508 | AA5: p90 | AB5: 392.0406 | AC5: 364.8063 | AD5: 364.7574 | AE5: 364.7574 | AG5: p90 | AH5: 471.663 | AI5: 480.2558 | AJ5: 479.8035 | AK5: 468.9075
C6: p75 | D6: =OMR!E29 -> 391.759 | E6: =OMR!F29 -> 377.074 | F6: =OMR!G29 -> 375.7575 | G6: =OMR!H29 -> 372.647 | I6: p75 | J6: 394.62019 | K6: 382.568 | L6: 382.034 | M6: 378.409 | O6: p75 | P6: 391.2393 | Q6: 378.749 | R6: 378.591 | S6: 376.144 | U6: p75 | V6: 387.888 | W6: 353.949 | X6: 352.377 | Y6: 352.059 | AA6: p75 | AB6: 355.9995 | AC6: 329.99275 | AD6: 327.2875 | AE6: 323.4385 | AG6: p75 | AH6: 404.81475 | AI6: 407.2255 | AJ6: 405.2885 | AK6: 402.40175
C7: Moyenne pondérée | D7: =OMR!E30 -> 332.6773 | E7: =OMR!F30 -> 311.35309 | F7: =OMR!G30 -> 309.57521 | G7: =OMR!H30 -> 307.90601 | I7: Médiane | J7: 346.491 | K7: 336.559 | L7: 336.173 | M7: 331.893 | O7: Médiane | P7: 344.45081 | Q7: 334.865 | R7: 332.759 | S7: 332.159 | U7: Médiane | V7: 336.822 | W7: 302.324 | X7: 302.107 | Y7: 297.264 | AA7: Médiane | AB7: 311.2068 | AC7: 269.885 | AD7: 267.4515 | AE7: 264.649 | AG7: Médiane | AH7: 375.6435 | AI7: 363.706 | AJ7: 362.3625 | AK7: 359.415
C8: p25 | D8: =OMR!E31 -> 307.288 | E8: =OMR!F31 -> 278.745 | F8: =OMR!G31 -> 276.4395 | G8: =OMR!H31 -> 275.0405 | I8: p25 | J8: 313.451 | K8: 288.936 | L8: 285.683 | M8: 284.324 | O8: p25 | P8: 306.3075 | Q8: 283.835 | R8: 281.492 | S8: 280.627 | U8: p25 | V8: 306.041 | W8: 270.762 | X8: 268.101 | Y8: 267.394 | AA8: p25 | AB8: 265.95654 | AC8: 227.185 | AD8: 222.74125 | AE8: 222.5065 | AG8: p25 | AH8: 337.05725 | AI8: 322.38025 | AJ8: 321.69525 | AK8: 316.9035
C9: p10 | D9: =OMR!E32 -> 268.04235 | E9: =OMR!F32 -> 237.2542 | F9: =OMR!G32 -> 234.75 | G9: =OMR!H32 -> 231.5072 | I9: p10 | J9: 267.05921 | K9: 255.3068 | L9: 255.1968 | M9: 250.6432 | O9: p10 | P9: 270.03572 | Q9: 240.6286 | R9: 237.748 | S9: 234.34 | U9: p10 | V9: 280.2622 | W9: 227.6646 | X9: 225.5496 | Y9: 224.8496 | AA9: p10 | AB9: 242.51964 | AC9: 189.9474 | AD9: 186.4736 | AE9: 184.2874 | AG9: p10 | AH9: 296.0845 | AI9: 259.3122 | AJ9: 256.4391 | AK9: 255.9883
A11: Verre | D11: Coût Complet | E11: Coût technique | F11: Coût partagé | G11: Coût aidé HT | J11: Coût Complet | K11: Coût technique | L11: Coût partagé | M11: Coût aidé HT | P11: Coût Complet | Q11: Coût technique | R11: Coût partagé | S11: Coût aidé HT | V11: Coût Complet | W11: Coût technique | X11: Coût partagé | Y11: Coût aidé HT | AB11: Coût Complet | AC11: Coût technique | AD11: Coût partagé | AE11: Coût aidé HT | AH11: Coût Complet | AI11: Coût technique | AJ11: Coût partagé | AK11: Coût aidé HT
C12: p90 | D12: ='Emb. Verre'!E31 -> 146.798 | E12: ='Emb. Verre'!F31 -> 126.063 | F12: ='Emb. Verre'!G31 -> 114.523 | G12: ='Emb. Verre'!H31 -> 113.405 | I12: p90 | J12: 127.946 | K12: 100.6374 | L12: 91.1324 | M12: 86.7882 | O12: p90 | P12: 147.4018 | Q12: 122.76 | R12: 109.613 | S12: 103.3114 | U12: p90 | V12: 168.538 | W12: 166.1166 | X12: 153.7244 | Y12: 153.7244 | AA12: p90 | AB12: 205.2032 | AC12: 201.5947 | AD12: 193.0849 | AE12: 191.3251 | AG12: p90 | AH12: 180.0355 | AI12: 145.7421 | AJ12: 135.6649 | AK12: 128.7187
C13: p75 | D13: ='Emb. Verre'!E32 -> 110.981 | E13: ='Emb. Verre'!F32 -> 85.316 | F13: ='Emb. Verre'!G32 -> 74.35 | G13: ='Emb. Verre'!H32 -> 73.0435 | I13: p75 | J13: 104.622 | K13: 75.81 | L13: 65.414 | M13: 64.842 | O13: p75 | P13: 107.6915 | Q13: 76.384 | R13: 66.974 | S13: 63.327 | U13: p75 | V13: 122.871 | W13: 94.997 | X13: 86.917 | Y13: 85.889 | AA13: p75 | AB13: 138.7115 | AC13: 120.42575 | AD13: 110.20375 | AE13: 110.20375 | AG13: p75 | AH13: 131.779 | AI13: 99.31525 | AJ13: 87.783 | AK13: 86.34775
C14: Moyenne pondérée | D14: ='Emb. Verre'!E33 -> 101.60516 | E14: ='Emb. Verre'!F33 -> 77.769097 | F14: ='Emb. Verre'!G33 -> 66.553213 | G14: ='Emb. Verre'!H33 -> 65.456187 | I14: Médiane | J14: 78.515 | K14: 52.513 | L14: 41.227 | M14: 39.247 | O14: Médiane | P14: 87.4235 | Q14: 58.938 | R14: 46.915 | S14: 45.704 | U14: Médiane | V14: 102.732 | W14: 72.846 | X14: 62.337 | Y14: 62.337 | AA14: Médiane | AB14: 108.231 | AC14: 86.905 | AD14: 74.8585 | AE14: 73.5735 | AG14: Médiane | AH14: 102.474 | AI14: 73.128 | AJ14: 63.8745 | AK14: 61.411
C15: p25 | D15: ='Emb. Verre'!E34 -> 69.608 | E15: ='Emb. Verre'!F34 -> 41.1335 | F15: ='Emb. Verre'!G34 -> 30.2065 | G15: ='Emb. Verre'!H34 -> 29.72 | I15: p25 | J15: 63.566 | K15: 37.726 | L15: 25.871 | M15: 25.487 | O15: p25 | P15: 66.48225 | Q15: 38.563 | R15: 27.444 | S15: 26.944 | U15: p25 | V15: 74.501 | W15: 51.561 | X15: 40.329 | Y15: 40.329 | AA15: p25 | AB15: 90.704 | AC15: 71.943 | AD15: 58.353 | AE15: 58.03575 | AG15: p25 | AH15: 82.64825 | AI15: 59.05125 | AJ15: 45.804 | AK15: 43.91225
C16: p10 | D16: ='Emb. Verre'!E35 -> 58.7442 | E16: ='Emb. Verre'!F35 -> 31.2182 | F16: ='Emb. Verre'!G35 -> 19.6022 | G16: ='Emb. Verre'!H35 -> 18.8342 | I16: p10 | J16: 56.71 | K16: 27.1126 | L16: 15.9652 | M16: 15.516 | O16: p10 | P16: 58.6337 | Q16: 30.242 | R16: 17.407 | S16: 17.407 | U16: p10 | V16: 67.5674 | W16: 42.55 | X16: 31.1438 | Y16: 29.5692 | AA16: p10 | AB16: 80.1788 | AC16: 53.4747 | AD16: 41.9371 | AE16: 41.3218 | AG16: p10 | AH16: 66.2225 | AI16: 37.5138 | AJ16: 27.5734 | AK16: 26.6855
A18: Recyclables | D18: Coût Complet | E18: Coût technique | F18: Coût partagé | G18: Coût aidé HT | J18: Coût Complet | K18: Coût technique | L18: Coût partagé | M18: Coût aidé HT | P18: Coût Complet | Q18: Coût technique | R18: Coût partagé | S18: Coût aidé HT | V18: Coût Complet | W18: Coût technique | X18: Coût partagé | Y18: Coût aidé HT | AB18: Coût Complet | AC18: Coût technique | AD18: Coût partagé | AE18: Coût aidé HT | AH18: Coût Complet | AI18: Coût technique | AJ18: Coût partagé | AK18: Coût aidé HT
C19: p90 | D19: ='Papiers et Emb. HV'!E39 -> 775.4784 | E19: ='Papiers et Emb. HV'!F39 -> 709.31 | F19: ='Papiers et Emb. HV'!G39 -> 494.6164 | G19: ='Papiers et Emb. HV'!H39 -> 481.7866 | I19: p90 | J19: 773.597 | K19: 691.873 | L19: 451.0022 | M19: 443.8062 | O19: p90 | P19: 743.6196 | Q19: 690.47 | R19: 494.9716 | S19: 484.0576 | U19: p90 | V19: 805.9536 | W19: 777.9652 | X19: 521.6314 | Y19: 517.166 | AA19: p90 | AB19: 809.076 | AC19: 704.5684 | AD19: 517.4662 | AE19: 511.6877 | AG19: p90 | AH19: 867.8 | AI19: 819.175 | AJ19: 604.8894 | AK19: 598.0543
C20: p75 | D20: ='Papiers et Emb. HV'!E40 -> 689.467 | E20: ='Papiers et Emb. HV'!F40 -> 619.1205 | F20: ='Papiers et Emb. HV'!G40 -> 387.4915 | G20: ='Papiers et Emb. HV'!H40 -> 383.7275 | I20: p75 | J20: 688.33 | K20: 611.51 | L20: 375.579 | M20: 372.134 | O20: p75 | P20: 680.7175 | Q20: 612.527 | R20: 370.416 | S20: 362.199 | U20: p75 | V20: 675.073 | W20: 627.425 | X20: 372.124 | Y20: 367.874 | AA20: p75 | AB20: 708.949 | AC20: 633.4525 | AD20: 413.37275 | AE20: 413.37275 | AG20: p75 | AH20: 740.828 | AI20: 702.711 | AJ20: 458.9515 | AK20: 458.434
C21: Moyenne pondérée | D21: ='Papiers et Emb. HV'!E41 -> 618.94227 | E21: ='Papiers et Emb. HV'!F41 -> 553.27338 | F21: ='Papiers et Emb. HV'!G41 -> 324.36263 | G21: ='Papiers et Emb. HV'!H41 -> 321.26627 | I21: Médiane | J21: 609.285 | K21: 537.573 | L21: 266.905 | M21: 263.444 | O21: Médiane | P21: 575.6215 | Q21: 516.313 | R21: 258.958 | S21: 256.257 | U21: Médiane | V21: 570.903 | W21: 492.123 | X21: 258.246 | Y21: 257.959 | AA21: Médiane | AB21: 633.498 | AC21: 553.958 | AD21: 332.6715 | AE21: 331.8195 | AG21: Médiane | AH21: 641.2645 | AI21: 556.6045 | AJ21: 304.7775 | AK21: 294.229
C22: p25 | D22: ='Papiers et Emb. HV'!E42 -> 512.922 | E22: ='Papiers et Emb. HV'!F42 -> 447.726 | F22: ='Papiers et Emb. HV'!G42 -> 195.17 | G22: ='Papiers et Emb. HV'!H42 -> 193.126 | I22: p25 | J22: 508.532 | K22: 444.123 | L22: 194 | M22: 191.399 | O22: p25 | P22: 490.788 | Q22: 426.404 | R22: 178.084 | S22: 177.21 | U22: p25 | V22: 501.597 | W22: 447.777 | X22: 181.567 | Y22: 180.891 | AA22: p25 | AB22: 540.2115 | AC22: 479.425 | AD22: 278.2285 | AE22: 273.37275 | AG22: p25 | AH22: 547.75775 | AI22: 488.52125 | AJ22: 236.87275 | AK22: 227.32925
C23: p10 | D23: ='Papiers et Emb. HV'!E43 -> 454.265 | E23: ='Papiers et Emb. HV'!F43 -> 392.2974 | F23: ='Papiers et Emb. HV'!G43 -> 129.226 | G23: ='Papiers et Emb. HV'!H43 -> 127.7246 | I23: p10 | J23: 437.32 | K23: 382.52 | L23: 128.5686 | M23: 124.9798 | O23: p10 | P23: 441.2537 | Q23: 383.4102 | R23: 110.9638 | S23: 110.9638 | U23: p10 | V23: 450.2384 | W23: 405.902 | X23: 136.332 | Y23: 134.1584 | AA23: p10 | AB23: 507.9092 | AC23: 439.8051 | AD23: 191.741 | AE23: 190.6698 | AG23: p10 | AH23: 503.2965 | AI23: 414.0081 | AJ23: 163.5699 | AK23: 160.7994
A25: Déchèteries | D25: Coût Complet | E25: Coût technique | F25: Coût partagé | G25: Coût aidé HT | J25: Coût Complet | K25: Coût technique | L25: Coût partagé | M25: Coût aidé HT | P25: Coût Complet | Q25: Coût technique | R25: Coût partagé | S25: Coût aidé HT | V25: Coût Complet | W25: Coût technique | X25: Coût partagé | Y25: Coût aidé HT | AB25: Coût Complet | AC25: Coût technique | AD25: Coût partagé | AE25: Coût aidé HT | AH25: Coût Complet | AI25: Coût technique | AJ25: Coût partagé | AK25: Coût aidé HT
C26: p90 | D26: =Déchèteries!E28 -> 242.5298 | E26: =Déchèteries!F28 -> 240.5508 | F26: =Déchèteries!G28 -> 228.1456 | G26: =Déchèteries!H28 -> 224.0458 | I26: p90 | J26: 232.353 | K26: 231.0166 | L26: 221.3564 | M26: 218.4192 | O26: p90 | P26: 240.4326 | Q26: 230.55 | R26: 222.7858 | S26: 222.0378 | U26: p90 | V26: 239.5006 | W26: 236.022 | X26: 225.9716 | Y26: 215.636 | AA26: p90 | AB26: 231.4786 | AC26: 248.5336 | AD26: 240.4214 | AE26: 238.1606 | AG26: p90 | AH26: 307.003 | AI26: 280.7392 | AJ26: 265.1359 | AK26: 256.2765
C27: p75 | D27: =Déchèteries!E29 -> 218.354 | E27: =Déchèteries!F29 -> 208.805 | F27: =Déchèteries!G29 -> 200.219 | G27: =Déchèteries!H29 -> 196.1515 | I27: p75 | J27: 207.16 | K27: 205.238 | L27: 195.3 | M27: 186.015 | O27: p75 | P27: 212.75925 | Q27: 203.307 | R27: 197.537 | S27: 192.403 | U27: p75 | V27: 220.741 | W27: 208.552 | X27: 202.723 | Y27: 200.966 | AA27: p75 | AB27: 220.767 | AC27: 217.194 | AD27: 213.022 | AE27: 212.36375 | AG27: p75 | AH27: 249.26425 | AI27: 237.98525 | AJ27: 219.499 | AK27: 210.48875
C28: Moyenne pondérée | D28: =Déchèteries!E30 -> 185.01117 | E28: =Déchèteries!F30 -> 180.80449 | F28: =Déchèteries!G30 -> 172.87101 | G28: =Déchèteries!H30 -> 170.89221 | I28: Médiane | J28: 180.878 | K28: 172.41 | L28: 162.802 | M28: 158.704 | O28: Médiane | P28: 187.923 | Q28: 176.529 | R28: 162.054 | S28: 160.176 | U28: Médiane | V28: 195.947 | W28: 176.983 | X28: 168.395 | Y28: 167.883 | AA28: Médiane | AB28: 190.872 | AC28: 189.415 | AD28: 177.9795 | AE28: 176.7175 | AG28: Médiane | AH28: 191.187 | AI28: 181.6425 | AJ28: 166.6825 | AK28: 163.4785
C29: p25 | D29: =Déchèteries!E31 -> 157.366 | E29: =Déchèteries!F31 -> 148.37 | F29: =Déchèteries!G31 -> 139.7425 | G29: =Déchèteries!H31 -> 137.619 | I29: p25 | J29: 155.524 | K29: 145.256 | L29: 138.276 | M29: 135.139 | O29: p25 | P29: 158.3295 | Q29: 147.685 | R29: 137.601 | S29: 136.127 | U29: p25 | V29: 158.147 | W29: 146.161 | X29: 140.413 | Y29: 139.738 | AA29: p25 | AB29: 168.561 | AC29: 164.10725 | AD29: 153.37075 | AE29: 152.665 | AG29: p25 | AH29: 157.473 | AI29: 143.539 | AJ29: 134.03875 | AK29: 133.2455
C30: p10 | D30: =Déchèteries!E32 -> 130.9986 | E30: =Déchèteries!F32 -> 124.06 | F30: =Déchèteries!G32 -> 114.6276 | G30: =Déchèteries!H32 -> 113.4274 | I30: p10 | J30: 128.141 | K30: 122.265 | L30: 114.4832 | M30: 111.8812 | O30: p10 | P30: 131.671 | Q30: 118.6254 | R30: 110.6122 | S30: 108.534 | U30: p10 | V30: 139.3806 | W30: 134.2112 | X30: 129.1484 | Y30: 127.4586 | AA30: p10 | AB30: 138.8902 | AC30: 138.6285 | AD30: 130.4537 | AE30: 129.9914 | AG30: p10 | AH30: 128.8015 | AI30: 124.9517 | AJ30: 113.4685 | AK30: 109.3115

Sheet Tous flux
C1: Sommaire
D2: Retour sommaire annexe
D5: Tous flux - Coûts de synthèse
D6: Tous flux - Évolution du coût aidé HT
D7: Tous flux - Coût aidé HT et typologie d'habitat
D8: Tous flux - Taux de couverture du coût aidé TTC par le financement
C10: =D5 -> Tous flux - Coûts de synthèse
C11: Retour sommaire fiche
E12: Coût Complet | F12: Coût technique | G12: Coût partagé | H12: Coût aidé HT
D13: Nombre de matrices | E13: 443 | F13: 597 | G13: =F13 -> 597 | H13: =F13 -> 597
D14: Population | E14: 23188175 | F14: 36422353 | G14: =F14 -> 36422353 | H14: =F14 -> 36422353
D15: Ratio (moyenne pondérée) | E15: 517.53975 | F15: 517.63772 | G15: =F15 -> 517.63772 | H15: =F15 -> 517.63772
E17: Coût Complet | F17: Coût technique | G17: Coût partagé | H17: Coût aidé HT
C18: Euro / habitant | D18: p90 | E18: 204.6404 | F18: 193.0818 | G18: 178.2472 | H18: 177.5704
D19: p75 | E19: 168.85066 | F19: 157.129 | G19: 141.458 | H19: 139.373
D20: Moyenne pondérée | E20: 152.7276 | F20: 141.76117 | G20: 127.84699 | H20: 126.86158
D21: p25 | E21: 127.771 | F21: 116.5265 | G21: 99.772 | H21: 99.032
D22: p10 | E22: 117.19135 | F22: 102.8034 | G22: 87.4428 | H22: 86.4298
E24: Coût Complet | F24: Coût technique | G24: Coût partagé | H24: Coût aidé HT
C25: Euro / tonne | D25: p90 | E25: 340.10104 | F25: 327.3028 | G25: 295.0832 | H25: 292.0276
D26: p75 | E26: 307.73948 | F26: 293.8985 | G26: 263.4745 | H26: 260.464
D27: Moyenne pondérée | E27: 282.66601 | F27: 268.16815 | G27: 241.4001 | H27: 239.53133
D28: p25 | E28: 244.79047 | F28: 222.6935 | G28: 189.8915 | H28: 187.5685
D29: p10 | E29: 201.97936 | F29: 185.1666 | G29: 155.5438 | H29: 154.9646
C32: =D6 -> Tous flux - Évolution du coût aidé HT
C33: Retour sommaire fiche
E34: 2010 | F34: 2012 | G34: 2014 | H34: 2016 | I34: 2018 | J34: 2019 | K34: 2020 | L34: 2022 | M34: 2023
D35: Nb de matrices | E35: 177 | F35: 358 | G35: 382 | H35: 351 | I35: 422 | J35: 597 | K35: 463 | L35: 648 | M35: 597
E37: 2010 | F37: 2012 | G37: 2014 | H37: 2016 | I37: 2018 | J37: 2019 | K37: 2020 | L37: 2022 | M37: 2023
C38: Euro / habitant | D38: p90 | E38: 107.40474 | F38: 110.20652 | G38: 115.7859 | H38: 122.3 | I38: 128.75656 | J38: 140.3875 | K38: 140.61432 | L38: 163.3945 | M38: 177.5704
D39: p75 | E39: 93.0869 | F39: 96.4497 | G39: 96.435625 | H39: 101.7 | I39: 105.48992 | J39: 114.1687 | K39: 114.0535 | L39: 129.84125 | M39: 139.373
D40: Moyenne pondérée | E40: 85.240492 | F40: 88.926495 | G40: 93.093204 | H40: 92.5 | I40: 98.011757 | J40: 105.281 | K40: 108.62809 | L40: 116.09271 | M40: 126.86158
D41: p25 | E41: 65.2952 | F41: 66.94605 | G41: 70.96925 | H41: 72.4 | I41: 75.088875 | J41: 80.1996 | K41: 82.6814 | L41: 90.3145 | M41: 99.032
D42: p10 | E42: 58.74942 | F42: 56.69959 | G42: 61.21245 | H42: 62.3 | I42: 63.10098 | J42: 68.8217 | K42: 71.01174 | L42: 78.2281 | M42: 86.4298
E44: 2010 | F44: 2012 | G44: 2014 | H44: 2016 | I44: 2018 | J44: 2019 | K44: 2020 | L44: 2022 | M44: 2022
C45: Euro / tonne | D45: p90 | E45: 192.51798 | F45: 206.44241 | G45: 206.71273 | H45: 213.8 | I45: 215.40364 | J45: 234.7738 | K45: 244.9693 | L45: 266.936 | M45: 292.0276
D46: p75 | E46: 173.0451 | F46: 178.70372 | G46: 181.05328 | H46: 186.3 | I46: 190.03355 | J46: 202.6291 | K46: 209.4247 | L46: 236.13075 | M46: 260.464
D47: Moyenne pondérée | E47: 161.57208 | F47: 165.98321 | G47: 174.00231 | H47: 173.6 | I47: 179.66621 | J47: 188.71864 | K47: 203.95111 | L47: 218.11482 | M47: 239.53133
D48: p25 | E48: 135.6186 | F48: 130.83367 | G48: 138.97787 | H48: 138.4 | I48: 146.53487 | J48: 153.9946 | K48: 160.7499 | L48: 170.741 | M48: 187.5685
D49: p10 | E49: 120.71972 | F49: 111.524 | G49: 120.80776 | H49: 122.2 | I49: 129.83854 | J49: 132.6749 | K49: 140.31406 | L49: 151.431 | M49: 154.9646
...

Sheet OMR
C1: Sommaire
D2: Retour sommaire annexe
D5: OMR - Coûts de synthèse
D6: OMR - Coûts de synthèse pour les collectivités ayant comme mode principal de traitement l’incinération
D7: OMR - Charges par étape technique
D8: OMR - Charges de traitement selon le mode de traitement
D9: OMR - Produits par nature
D10: OMR - Évolution du coût aidé HT
D11: OMR - Coût aidé HT et la typologie d'habitat
C13: =D5 -> OMR - Coûts de synthèse
C14: Retour sommaire fiche
E15: Coût Complet | F15: Coût technique | G15: Coût partagé | H15: Coût aidé HT
D16: Nombre de matrices | E16: 443 | F16: 597 | G16: =F16 -> 597 | H16: =F16 -> 597
D17: Population | E17: 23188175 | F17: 36422353 | G17: =F17 -> 36422353 | H17: =F17 -> 36422353
D18: Ratio (moyenne pondérée) | E18: 210.46347 | F18: 214.99161 | G18: =F18 -> 214.99161 | H18: =F18 -> 214.99161
E20: Coût Complet | F20: Coût technique | G20: Coût partagé | H20: Coût aidé HT
C21: Euro / habitant | D21: p90 | E21: 99.837633 | F21: 95.8612 | G21: 95.6546 | H21: 93.604
D22: p75 | E22: 76.365 | F22: 72.621 | G22: 72.548 | H22: 71.8845
D23: Moyenne pondérée | E23: 69.60774 | F23: 67.042323 | G23: 66.663792 | H23: 66.307238
D24: p25 | E24: 49.625 | F24: 46.5485 | G24: 46.1825 | H24: 45.7465
D25: p10 | E25: 40.69052 | F25: 37.64 | G25: 37.1282 | H25: 36.8058
E27: Coût Complet | F27: Coût technique | G27: Coût partagé | H27: Coût aidé HT
C28: Euro / tonne | D28: p90 | E28: 446.2752 | F28: 425.0448 | G28: 423.645 | H28: 418.8392
D29: p75 | E29: 391.759 | F29: 377.074 | G29: 375.7575 | H29: 372.647
D30: Moyenne pondérée | E30: 332.6773 | F30: 311.35309 | G30: 309.57521 | H30: 307.90601
D31: p25 | E31: 307.288 | F31: 278.745 | G31: 276.4395 | H31: 275.0405
D32: p10 | E32: 268.04235 | F32: 237.2542 | G32: 234.75 | H32: 231.5072
C35: =D6 -> OMR - Coûts de synthèse pour les collectivités ayant comme mode principal de traitement l’incinération
C36: Retour sommaire fiche
E37: Coût Complet | F37: Coût technique | G37: Coût partagé | H37: Coût aidé HT
D38: Nombre de matrices | E38: 204 | F38: 204 | G38: 204 | H38: 204
E40: Coût Complet | F40: Coût technique | G40: Coût partagé | H40: Coût aidé HT
C41: Euro / habitant | D41: p90 | E41: 90.6 | F41: 78.7 | G41: 78.1 | H41: 78
D42: p75 | E42: 71.2 | F42: 62.8 | G42: 62.5 | H42: 62.1
D43: Médiane | E43: 59 | F43: 51.1 | G43: 50.7 | H43: 50.6
D44: p25 | E44: 47.7 | F44: 40.2 | G44: 39.7 | H44: 39.2
D45: p10 | E45: 38.5 | F45: 34.2 | G45: 33.6 | H45: 33.2
E47: Coût Complet | F47: Coût technique | G47: Coût partagé | H47: Coût aidé HT
C48: Euro / tonne | D48: p90 | E48: 443 | F48: 400 | G48: 397 | H48: 395
D49: p75 | E49: 393 | F49: 352 | G49: 349 | H49: 349
...

Sheet Emb. Verre
C1: Sommaire
D2: Retour sommaire annexe
D5: Emballages verre - Coûts de synthèse
D6: Emballages verre - Charges par étape technique
D7: Emballages verre - Produits par nature
D8: Emballages verre - Évolution du coût aidé HT
D9: Emballages verre - Coût aidé HT et typologie d'habitat
D10: Emballages verre - Coût aidé HT et mode de collecte
D11: Emballages verre - Charges de pré-collecte et de collecte et mode de collecte
D12: Emballages verre - Charges de pré-collecte et mode de collecte
D13: Emballages verre - Charges de collecte et mode de collecte
C16: =D5 -> Emballages verre - Coûts de synthèse
C17: Retour sommaire fiche
E18: Coût Complet | F18: Coût technique | G18: Coût partagé | H18: Coût aidé HT
D19: Nombre de matrices | E19: 443 | F19: 597 | G19: =F19 -> 597 | H19: =F19 -> 597
D20: Population | E20: 23188175 | F20: 36422353 | G20: =F20 -> 36422353 | H20: =F20 -> 36422353
D21: Ratio (moyenne pondérée) | E21: 35.012972 | F21: 34.624674 | G21: =F21 -> 34.624674 | H21: =F21 -> 34.624674
E23: Coût Complet | F23: Coût technique | G23: Coût partagé | H23: Coût aidé HT
C24: Euro / habitant | D24: p90 | E24: 6.6784 | F24: 5.4134 | G24: 4.992 | H24: 4.874
D25: p75 | E25: 4.751 | F25: 3.6225 | G25: 3.126 | H25: 3.0455
D26: Moyenne pondérée | E26: 3.6161306 | F26: 2.7376356 | G26: 2.3492468 | H26: 2.3112805
D27: p25 | E27: 2.791 | F27: 1.7115 | G27: 1.258 | H27: 1.25
D28: p10 | E28: 2.3 | F28: 1.2692 | G28: 0.8094 | H28: 0.7758
E30: Coût Complet | F30: Coût technique | G30: Coût partagé | H30: Coût aidé HT
C31: Euro / tonne | D31: p90 | E31: 146.798 | F31: 126.063 | G31: 114.523 | H31: 113.405
D32: p75 | E32: 110.981 | F32: 85.316 | G32: 74.35 | H32: 73.0435
D33: Moyenne pondérée | E33: 101.60516 | F33: 77.769097 | G33: 66.553213 | H33: 65.456187
D34: p25 | E34: 69.608 | F34: 41.1335 | G34: 30.2065 | H34: 29.72
D35: p10 | E35: 58.7442 | F35: 31.2182 | G35: 19.6022 | H35: 18.8342
C38: =D6 -> Emballages verre - Charges par étape technique
C39: Retour sommaire fiche
E40: Pré-collecte | F40: Collecte
D41: Nombre de matrices | E41: 691 | F41: 683
E43: Pré-collecte | F43: Collecte
C44: Euro / habitant | D44: p90 | E44: 1.8944 | F44: 4.5384
D45: p75 | E45: 1.317 | F45: 3.215
D46: Médiane | E46: 0.621 | F46: 2.345
D47: p25 | E47: 0.291 | F47: 1.861
D48: p10 | E48: 0.158 | F48: 1.527
E50: Pré-collecte | F50: Collecte
...

Sheet Papiers et Emb. HV
C1: Sommaire
D2: Retour sommaire annexe
D5: Papiers et emballages hors verre - Coûts de synthèse
D6: Papiers et emballages hors verre - Charges par étape technique
D7: Papiers et emballages hors verre - Produits par nature
D8: Papiers et emballages hors verre - Évolution du coût aidé HT
D9: Papiers et emballages hors verre - Coût aidé HT et typologie d'habitat
D10: Papiers et emballages hors verre - Coût aidé HT et mode/schéma de collecte
D11: Papiers et emballages hors verre - Charges de pré-collecte et collecte et mode/schéma de collecte
D12: Papiers et emballages hors verre - Charges de pré-collecte et mode/schéma de collecte
D13: Papiers et emballages hors verre - Charges de collecte et mode/schéma de collecte
D14: Papiers et emballages hors verre - Charges de traitement et schéma de collecte
D15: Papiers et emballages hors verre - Quantités collectées par sous-flux et par mode de collecte
... D21: Papiers et emballages hors verre - Charges de tri par sous-flux
C24: =D5 -> Papiers et emballages hors verre - Coûts de synthèse
C25: Retour sommaire fiche
E26: Coût Complet | F26: Coût technique | G26: Coût partagé | H26: Coût aidé HT
D27: Nombre de matrices | E27: 443 | F27: 597 | G27: =F27 -> 597 | H27: =F27 -> 597
D28: Population | E28: 23188175 | F28: 36422353 | G28: =F28 -> 36422353 | H28: =F28 -> 36422353
D29: Ratio (moyenne pondérée) | E29: 51.795438 | F29: 50.687137 | G29: =F29 -> 50.687137 | H29: =F29 -> 50.687137
E31: Coût Complet | F31: Coût technique | G31: Coût partagé | H31: Coût aidé HT
C32: Euro / habitant | D32: p90 | E32: 46.36 | F32: 42.389 | G32: 28.1654 | H32: 28.0384
D33: p75 | E33: 39.257 | F33: 34.948 | G33: 20.9135 | H33: 20.822
D34: Moyenne pondérée | E34: 32.401013 | F34: 28.203666 | G34: 16.6283 | H34: 16.475601
D35: p25 | E35: 27.346 | F35: 23.4775 | G35: 10.29 | H35: 10.102
D36: p10 | E36: 20.985 | F36: 17.7032 | G36: 6.7278 | H36: 6.6434
E38: Coût Complet | F38: Coût technique | G38: Coût partagé | H38: Coût aidé HT
C39: Euro / tonne | D39: p90 | E39: 775.4784 | F39: 709.31 | G39: 494.6164 | H39: 481.7866
D40: p75 | E40: 689.467 | F40: 619.1205 | G40: 387.4915 | H40: 383.7275
D41: Moyenne pondérée | E41: 618.94227 | F41: 553.27338 | G41: 324.36263 | H41: 321.26627
D42: p25 | E42: 512.922 | F42: 447.726 | G42: 195.17 | H42: 193.126
D43: p10 | E43: 454.265 | F43: 392.2974 | G43: 129.226 | H43: 127.7246
C46: =D6 -> Papiers et emballages hors verre - Charges par étape technique
C47: Retour sommaire fiche
E48: Pré-collecte | F48: Collecte | G48: Transport | H48: Traitement
D49: Nombre de matrices | E49: 678 | F49: 668 | G49: 445 | H49: 640
E51: Pré-collecte | F51: Collecte | G51: Transport | H51: Traitement
C52: Euro / habitant | D52: p90 | E52: 4.8717 | F52: 21.2219 | G52: 4.6096 | H52: 18.064
D53: p75 | E53: 3.22875 | F53: 17.212 | G53: 3.249 | H53: 14.364
D54: Médiane | E54: 2.075 | F54: 13.2685 | G54: 2.333 | H54: 12.005
...

Sheet Déchèteries
C1: Sommaire
D2: Retour sommaire annexe
D5: Déchets en déchèterie - Coûts de synthèse
D6: Déchets en déchèterie - Charges par étape technique
D7: Déchets en déchèterie - Charges de traitement selon les flux
D8: Déchets en déchèterie - Produits par nature
D9: Déchets en déchèterie - Évolution du coût aidé HT
D10: Déchets en déchèterie - Coûts aidés HT et typologie d'habitat
C13: =D5 -> Déchets en déchèterie - Coûts de synthèse
C14: Retour sommaire fiche
E15: Coût Complet | F15: Coût technique | G15: Coût partagé | H15: Coût aidé HT
D16: Nombre de matrices | E16: 443 | F16: 597 | G16: =F16 -> 597 | H16: =F16 -> 597
D17: Population | E17: 23188175 | F17: 36422353 | G17: =F17 -> 36422353 | H17: =F17 -> 36422353
D18: Ratio (moyenne pondérée) | E18: 181.56422 | F18: 180.9513 | G18: =F18 -> 180.9513 | H18: =F18 -> 180.9513
E20: Coût Complet | F20: Coût technique | G20: Coût partagé | H20: Coût aidé HT
C21: Euro / habitant | D21: p90 | E21: 60.0364 | F21: 57.2494 | G21: 55.6556 | H21: 54.5144
D22: p75 | E22: 49.989 | F22: 46.9705 | G22: 44.6445 | H22: 43.726
D23: Moyenne pondérée | E23: 33.697717 | F23: 32.8194 | G23: 31.39124 | H23: 31.041737
D24: p25 | E24: 33.477 | F24: 30.8235 | G24: 29.233 | H24: 28.81
D25: p10 | E25: 26.7252 | F25: 25.4802 | G25: 23.9276 | H25: 23.4938
E27: Coût Complet | F27: Coût technique | G27: Coût partagé | H27: Coût aidé HT
C28: Euro / tonne | D28: p90 | E28: 242.5298 | F28: 240.5508 | G28: 228.1456 | H28: 224.0458
D29: p75 | E29: 218.354 | F29: 208.805 | G29: 200.219 | H29: 196.1515
D30: Moyenne pondérée | E30: 185.01117 | F30: 180.80449 | G30: 172.87101 | H30: 170.89221
D31: p25 | E31: 157.366 | F31: 148.37 | G31: 139.7425 | H31: 137.619
D32: p10 | E32: 130.9986 | F32: 124.06 | G32: 114.6276 | H32: 113.4274
C35: =D6 -> Déchets en déchèterie - Charges par étape technique
C36: Retour sommaire fiche
E37: Collecte | F37: Transport | G37: Traitement | H37: Gestion DD
D38: Nombre de matrices | E38: 672 | F38: 513 | G38: 510 | H38: 666
E40: Collecte | F40: Transport | G40: Traitement | H40: Gestion DD
C41: Euro / habitant | D41: p90 | E41: 21.5168 | F41: 13.6696 | G41: 22.8556 | H41: 2.9524
D42: p75 | E42: 15.83 | F42: 10.283 | G42: 17.5535 | H42: 1.895
D43: Médiane | E43: 12.043 | F43: 8.111 | G43: 13.6665 | H43: 1.184
D44: p25 | E44: 8.87125 | F44: 5.671 | G44: 10.4095 | H44: 0.676
D45: p10 | E45: 6.587 | F45: 3.8846 | G45: 7.6954 | H45: 0.3602
E47: Collecte | F47: Transport | G47: Traitement | H47: Gestion DD
C48: Euro / tonne | D48: p90 | E48: 101.6633 | F48: 56.871 | G48: 106.2936 | H48: 12.6877
D49: p75 | E49: 73.86825 | F49: 48.653 | G49: 86.14475 | H49: 8.43575
D50: Médiane | E50: 55.229 | F50: 38.087 | G50: 72.103 | H50: 5.7115
...

Sheet Autres flux
C1: Sommaire
D2: Retour sommaire annexe
D5: Autres flux - Coûts complet et aidé HT de gestion des déchets verts
D6: Autres flux - Coûts complet et aidé HT de gestion des biodéchets
D7: Autres flux - Coûts complet et aidé HT de gestion des encombrants
D8: Autres flux - Coûts complet et aidé HT de gestion des déchets des professionnels
C11: =D5 -> Autres flux - Coûts complet et aidé HT de gestion des déchets verts
C12: Retour sommaire fiche
E13: Coût complet | G13: Coût aidé HT
E14: AV | F14: PAP | G14: AV | H14: PAP
D15: Nombre de matrices | E15: 54 | F15: 75 | G15: 54 | H15: 75
D16: Ratio (médiane) | E16: 32 | F16: 43 | G16: 32 | H16: 43
E18: Coût complet | G18: Coût aidé HT
E19: AV | F19: PAP | G19: AV | H19: PAP
C20: Euro / habitant | D20: p90 | E20: 7.61295 | F20: 19.83394 | G20: 7.437 | H20: 19.8086
D21: p75 | E21: 5.768025 | F21: 14.002 | G21: 5.7665 | H21: 13.964
D22: Médiane | E22: 3.27205 | F22: 9.1606 | G22: 3.0225 | H22: 9.161
D23: p25 | E23: 1.244425 | F23: 4.3707 | G23: 0.90425 | H23: 4.29
D24: p10 | E24: 0.5206 | F24: 1.79332 | G24: 0.345 | H24: 1.792
E26: Coût complet | G26: Coût aidé HT
E27: AV | F27: PAP | G27: AV | H27: PAP
C28: Euro / tonne | D28: p90 | E28: 226.6945 | F28: 490.3992 | G28: 222.146 | H28: 490.3992
D29: p75 | E29: 120.2535 | F29: 300.379 | G29: 116.73 | H29: 300.105
D30: Médiane | E30: 76.8105 | F30: 208.386 | G30: 72.4775 | H30: 206.629
D31: p25 | E31: 51.8095 | F31: 161.023 | G31: 47.56125 | H31: 157.726
D32: p10 | E32: 38.3755 | F32: 120.6408 | G32: 32.443 | H32: 119.7368
C35: =D6 -> Autres flux - Coûts complet et aidé HT de gestion des biodéchets
C36: Retour sommaire fiche
E37: Coût complet | I37: Coût aidé HT
E38: AV | F38: PAP - DCT exclusivement | G38: PAP - DV à la marge | H38: PAP - DCT + DV | I38: AV | J38: PAP - DCT exclusivement | K38: PAP - DV à la marge | L38: PAP - DCT + DV
D39: Nombre de matrices | E39: 11 | F39: 10 | G39: 9 | H39: 8 | I39: 11 | J39: 10 | K39: 9 | L39: 8
D40: Ratio (médiane) | E40: 22 | F40: 37.5 | G40: 47 | H40: 65 | I40: 22 | J40: 37.5 | K40: 47 | L40: 65
E42: Coût complet | I42: Coût aidé HT
E43: AV | F43: PAP - DCT exclusivement | G43: PAP - DV à la marge | H43: PAP - DCT + DV | I43: AV | J43: PAP - DCT exclusivement | K43: PAP - DV à la marge | L43: PAP - DCT + DV
C44: Euro / habitant | D44: p90 | E44: 16.5332 | F44: 44.8113 | G44: 43.425 | I44: 16.2048 | J44: 44.7591 | K44: 43.425
D45: p75 | E45: 13.604 | F45: 29.775 | G45: 28.2795 | H45: 27.77625 | I45: 13.407 | J45: 29.36175 | K45: 27.5925 | L45: 27.747
D46: Médiane | E46: 9.309 | F46: 23.9555 | G46: 23.166 | H46: 23.9045 | I46: 8.865 | J46: 23.831 | K46: 22.726 | L46: 23.7945
D47: p25 | E47: 7.182 | F47: 17.52525 | G47: 18.7765 | H47: 17.4845 | I47: 6.605 | J47: 17.2745 | K47: 18.5875 | L47: 17.47875
D48: p10 | E48: 4.557 | F48: 16.5633 | G48: 7.415 | I48: 2.8454 | J48: 16.5353 | K48: 7.359
E50: Coût complet | I50: Coût aidé HT
...

Sheet Tarif. Incitative
C1: Sommaire
D2: Retour sommaire annexe
D5: Tarification incitative - Dispersion des quantités de déchets totaux collectés avec ou sans TI
D6: Tarification incitative - Dispersion des quantités de déchets collectés pour les quatre principaux flux avec ou sans TI
D7: Tarification incitative - Dispersion des quantités de déchets totaux collectés par typologie d'habitat avec ou sans TI
D8: Tarification incitative - Dispersion des quantités d'OMR collectées par typologie d'habitat avec ou sans TI
D9: Tarification incitative - Dispersion des quantités de verre collectées par typologie d'habitat avec ou sans TI
D10: Tarification incitative - Dispersion des quantités de PEHV collectées par typologie d'habitat avec ou sans TI
D11: Tarification incitative - Dispersion des quantités de déchets en déchèterie collectées par typologie d'habitat avec ou sans TI
D12: Tarification incitative - Dispersion des quantités d'OMR collectées par fréquence de collecte avec ou sans TI
D13: Tarification incitative - Dispersion des quantités d'OMR collectées par typologie d'habitat selon le type de facturation
D14: Tarification incitative - Coûts complets et aidés tous flux avec ou sans TI (en euros par habitant)
D15: Tarification incitative - Coûts aidés par flux avec ou sans TI (en euros par habitant)
... D23: Tarification incitative - Coûts aidés des OMR par typologie d'habitat selon le type de facturation(en euros par habitant)
C26: =D5 -> Tarification incitative - Dispersion des quantités de déchets totaux collectés avec ou sans TI
C27: Retour sommaire fiche
E28: Sans TI | F28: Avec TI
D29: Nombre de matrices | E29: 329 | F29: 129
E31: Sans TI | F31: Avec TI
C32: Ratio en kg/hab. | D32: p90 | E32: 663 | F32: 582
D33: p75 | E33: 589 | F33: 503
D34: Médiane | E34: 533 | F34: 461
D35: p25 | E35: 489 | F35: 425
D36: p10 | E36: 455 | F36: 396
C39: =D6 -> Tarification incitative - Dispersion des quantités de déchets collectés pour les quatre principaux flux avec ou sans TI
C40: Retour sommaire fiche
E41: OMR | G41: Emballages en verre | I41: Papiers et emballages hors verre | K41: Déchèteries
E42: Sans TI | F42: Avec TI | G42: Sans TI | H42: Avec TI | I42: Sans TI | J42: Avec TI | K42: Sans TI | L42: Avec TI
D43: Nombre de matrices | E43: 329 | F43: 129 | G43: 329 | H43: 129 | I43: 329 | J43: 129 | K43: 329 | L43: 129
E45: OMR | G45: Emballages en verre | I45: Papiers et emballages hors verre | K45: Déchèteries
E46: Sans TI | F46: Avec TI | G46: Sans TI | H46: Avec TI | I46: Sans TI | J46: Avec TI | K46: Sans TI | L46: Avec TI
C47: Ratio en kg/hab. | D47: p90 | E47: 252 | F47: 159 | G47: 52 | H47: 55 | I47: 70 | J47: 73 | K47: 315 | L47: 296
D48: p75 | E48: 225.5 | F48: 138 | G48: 45 | H48: 49 | I48: 62 | J48: 67 | K48: 274.5 | L48: 255.5
D49: Médiane | E49: 196 | F49: 113 | G49: 38 | H49: 45 | I49: 53 | J49: 62 | K49: 226 | L49: 224
D50: p25 | E50: 173 | F50: 98.5 | G50: 34 | H50: 40.5 | I50: 45 | J50: 54 | K50: 184.5 | L50: 188.5
D51: p10 | E51: 147 | F51: 88 | G51: 30 | H51: 36 | I51: 36 | J51: 49 | K51: 158 | L51: 155
C54: =D7 -> Tarification incitative - Dispersion des quantités de déchets totaux collectés par typologie d'habitat avec ou sans TI
C55: Retour sommaire fiche
E56: Rural | G56: Mixte rural | I56: Mixte urbain
E57: Sans TI | F57: Avec TI | G57: Sans TI | H57: Avec TI | I57: Sans TI | J57: Avec TI
...

Sheet Évolution
C1: Sommaire
D2: Retour sommaire annexe
D5: Évolution - Évolution du coût aidé HT tous flux entre 2010 et 2023
D6: Évolution - Évolution du coût aidé HT des OMR entre 2010 et 2023
D7: Évolution - Évolution du coût aidé HT des emballages en verre entre 2010 et 2023
D8: Évolution - Évolution du coût aidé HT des papiers et emballages hors verre entre 2010 et 2023
D9: Évolution - Évolution du coût aidé HT des déchèteries entre 2010 et 2023
C13: =D5 -> Évolution - Évolution du coût aidé HT tous flux entre 2010 et 2023
C14: Retour sommaire fiche
E15: 2010 | F15: 2012 | G15: 2014 | H15: 2016 | I15: 2018 | J15: 2019 | K15: 2020 | L15: 2022 | M15: 2023
D16: Nombre de matrices | E16: 177 | F16: 358 | G16: 382 | H16: 351 | I16: 422 | J16: 619 | K16: 463 | L16: 648 | M16: 597
E18: 2010 | F18: 2012 | G18: 2014 | H18: 2016 | I18: 2018 | J18: 2019 | K18: 2020 | L18: 2022 | M18: 2023
C19: Euro / habitant | D19: p90 | E19: 107.40474 | F19: 110.20652 | G19: 115.7859 | H19: 122.3 | I19: 128.75656 | J19: 140.3875 | K19: 140.61432 | L19: 163.3945 | M19: 177.5704
D20: p75 | E20: 93.0869 | F20: 96.4497 | G20: 96.435625 | H20: 101.7 | I20: 105.48992 | J20: 114.1687 | K20: 114.0535 | L20: 129.84125 | M20: 139.373
D21: Moyenne pondérée | E21: 85.240492 | F21: 88.926495 | G21: 93.093204 | H21: 92.5 | I21: 98.011757 | J21: 105.281 | K21: 108.62809 | L21: 116.09271 | M21: 126.86158
D22: Médiane | E22: 80.4128 | F22: 79.8754 | G22: 83.24325 | H22: 85.2996 | I22: 88.6 | J22: 93.8 | K22: 96.2401 | L22: 107.267 | M22: 117.375
D23: p25 | E23: 65.2952 | F23: 66.94605 | G23: 70.96925 | H23: 72.4 | I23: 75.088875 | J23: 80.1996 | K23: 82.6814 | L23: 90.3145 | M23: 99.032
D24: p10 | E24: 58.74942 | F24: 56.69959 | G24: 61.21245 | H24: 62.3 | I24: 63.10098 | J24: 68.8217 | K24: 71.01174 | L24: 78.2281 | M24: 86.4298
C27: =D6 -> Évolution - Évolution du coût aidé HT des OMR entre 2010 et 2023
C28: Retour sommaire fiche
E29: 2010 | F29: 2012 | G29: 2014 | H29: 2016 | I29: 2018 | J29: 2019 | K29: 2020 | L29: 2022 | M29: 2023
D30: Nombre de matrices | E30: 177 | F30: 358 | G30: 382 | H30: 351 | I30: 422 | J30: 619 | K30: 463 | L30: 648 | M30: 597
E32: 2010 | F32: 2012 | G32: 2014 | H32: 2016 | I32: 2018 | J32: 2019 | K32: 2020 | L32: 2022 | M32: 2023
C33: Euro / habitant | D33: p90 | E33: 64.8209 | F33: 65.93659 | G33: 70.51345 | H33: 73.2 | I33: 75.93979 | J33: 80.16982 | K33: 76.53728 | L33: 92.8881 | M33: 93.604
D34: p75 | E34: 56.877 | F34: 57.186575 | G34: 58.9627 | H34: 57.9 | I34: 59.581975 | J34: 61.6632 | K34: 61.3918 | L34: 71.927 | M34: 71.8845
D35: Moyenne pondérée | E35: 50.843892 | F35: 53.070704 | G35: 55.947086 | H35: 53.1 | I35: 55.155777 | J35: 57.214325 | K35: 59.826705 | L35: 64.926662 | M35: 66.307238
D36: Médiane | E36: 47.7674 | F36: 47.0025 | G36: 49.55405 | H36: 48.0639 | I36: 48.9 | J36: 49.9 | K36: 49.8782 | L36: 57.4355 | M36: 57.82
D37: p25 | E37: 40.1408 | F37: 38.376075 | G37: 39.3991 | H37: 38 | I37: 41.0759 | J37: 41.12295 | K37: 41.1956 | L37: 44.93775 | M37: 45.7465
D38: p10 | E38: 34.02056 | F38: 33.257 | G38: 32.61081 | H38: 33.1 | I38: 33.99946 | J38: 34.09874 | K38: 33.71896 | L38: 37.0288 | M38: 36.8058
C41: =D7 -> Évolution - Évolution du coût aidé HT des emballages en verre entre 2010 et 2023
C42: Retour sommaire fiche
E43: 2010 | F43: 2012 | G43: 2014 | H43: 2016 | I43: 2018 | J43: 2019 | K43: 2020 | L43: 2022 | M43: 2023
D44: Nombre de matrices | E44: 177 | F44: 358 | G44: 382 | H44: 351 | I44: 422 | J44: 619 | K44: 463 | L44: 648 | M44: 597
E46: 2010 | F46: 2012 | G46: 2014 | H46: 2016 | I46: 2018 | J46: 2019 | K46: 2020 | L46: 2022 | M46: 2023
C47: Euro / habitant | D47: p90 | E47: 2.53706 | F47: 2.82115 | G47: 3.06327 | H47: 3.5 | I47: 3.22585 | J47: 3.51208 | K47: 3.52832 | L47: 4.5197 | M47: 4.874
D48: p75 | E48: 1.5633 | F48: 1.666125 | G48: 1.829025 | H48: 2 | I48: 2.0552 | J48: 2.0456 | K48: 2.3371 | L48: 2.78225 | M48: 3.0455
D49: Moyenne pondérée | E49: 1.3327413 | F49: 1.6112969 | G49: 1.678713 | H49: 1.8 | I49: 1.7702933 | J49: 1.8053691 | K49: 1.9314983 | L49: 2.0672512 | M49: 2.3112805
D50: Médiane | E50: 0.9442 | F50: 1.08235 | G50: 1.14735 | H50: 1.1719 | I50: 1.1 | J50: 1.2 | K50: 1.3826 | L50: 1.756 | M50: 1.888
D51: p25 | E51: 0.5156 | F51: 0.6629 | G51: 0.668525 | H51: 0.7 | I51: 0.675875 | J51: 0.67425 | K51: 0.8783 | L51: 1.09725 | M51: 1.25
D52: p10 | E52: 0.26402 | F52: 0.29837 | G52: 0.28368 | H52: 0.3 | I52: 0.24953 | J52: 0.29672 | K52: 0.47114 | L52: 0.6114 | M52: 0.7758
...
